Workbook

Sheet 使い方
B2: SQLフォルダパス
B3: T:\運用作業\0230.年次\年度繁忙進捗集計クエリv2.1
B5: クエリ実行後、「SQLデータ」シートのA1セルに貼り付け

Sheet SQLデータ
A1: 申請番号 | B1: 申請職員番号 | C1: 申請日 | D1: 申請種別 | E1: ステータス | F1: 案件状況 | G1: 届出事由 | H1: 届出事由区分 | I1: 扶養手当 | J1: 共済 | K1: 税控除 | L1: 共済ありフラグ | M1: 扶養ありフラグ | N1: 税のみフラグ | O1: 本人税のみフラグ | P1: 集計対象フラグ | Q1: 責任職対象外 | R1: 一般職対象外
A2: 202510000793 | B2: 1111083 | C2: 45866 | D2: 給与口座 | E2: ＯＰ確認中 | F2: 添付待ち | G2: NULL | L2: =IF(ISBLANK(J2),0,1) -> 0 | M2: =IF(AND(L2=0,I2<>""),1,0) -> 0 | N2: =IF(AND(L2=0,M2=0,K2<>""),1,0) -> 0 | O2: =IF(COUNTIF(L2:N2,0)=3,1,0) -> 1 | P2: =IF(D2<>"扶養","",IF(E2<>"確認待ち",1,IF(OR(AND(G2="本人の結婚",O2=1),AND(H2="減",OR(N2=1,O2=1))),1,0))) | Q2: =COUNTIF('責任職 企業局→市長部局'!A:A,SQLデータ!B2) -> 0 | R2: =COUNTIF('一般職員 企業局→市長部局'!A:F,SQLデータ!B2) -> 0
A3: 202510001619 | B3: 1122110 | C3: 46016 | D3: 給与口座 | E3: ＳＶ確認中 | F3: オペレータ保留 | G3: NULL | L3: =IF(ISBLANK(J3),0,1) -> 0 | M3: =IF(AND(L3=0,I3<>""),1,0) -> 0 | N3: =IF(AND(L3=0,M3=0,K3<>""),1,0) -> 0 | O3: =IF(COUNTIF(L3:N3,0)=3,1,0) -> 1 | P3: =IF(D3<>"扶養","",IF(E3<>"確認待ち",1,IF(OR(AND(G3="本人の結婚",O3=1),AND(H3="減",OR(N3=1,O3=1))),1,0))) | Q3: =COUNTIF('責任職 企業局→市長部局'!A:A,SQLデータ!B3) -> 0 | R3: =COUNTIF('一般職員 企業局→市長部局'!A:F,SQLデータ!B3) -> 0
A4: 202510001748 | B4: 1256125 | C4: 46057 | D4: 給与口座 | E4: ＯＰ確認中 | F4: 添付待ち | G4: NULL | L4: =IF(ISBLANK(J4),0,1) -> 0 | M4: =IF(AND(L4=0,I4<>""),1,0) -> 0 | N4: =IF(AND(L4=0,M4=0,K4<>""),1,0) -> 0 | O4: =IF(COUNTIF(L4:N4,0)=3,1,0) -> 1 | P4: =IF(D4<>"扶養","",IF(E4<>"確認待ち",1,IF(OR(AND(G4="本人の結婚",O4=1),AND(H4="減",OR(N4=1,O4=1))),1,0))) | Q4: =COUNTIF('責任職 企業局→市長部局'!A:A,SQLデータ!B4) -> 0 | R4: =COUNTIF('一般職員 企業局→市長部局'!A:F,SQLデータ!B4) -> 0
A5: 202510001923 | B5: 1211445 | C5: 46069 | D5: 給与口座 | E5: ＯＰ確認中 | F5: 添付待ち | G5: NULL | L5: =IF(ISBLANK(J5),0,1) -> 0 | M5: =IF(AND(L5=0,I5<>""),1,0) -> 0 | N5: =IF(AND(L5=0,M5=0,K5<>""),1,0) -> 0 | O5: =IF(COUNTIF(L5:N5,0)=3,1,0) -> 1 | P5: =IF(D5<>"扶養","",IF(E5<>"確認待ち",1,IF(OR(AND(G5="本人の結婚",O5=1),AND(H5="減",OR(N5=1,O5=1))),1,0))) | Q5: =COUNTIF('責任職 企業局→市長部局'!A:A,SQLデータ!B5) -> 0 | R5: =COUNTIF('一般職員 企業局→市長部局'!A:F,SQLデータ!B5) -> 0
A6: 202510002028 | B6: 1256115 | C6: 46084 | D6: 給与口座 | E6: ＯＰ確認中 | F6: 添付待ち | G6: NULL | L6: =IF(ISBLANK(J6),0,1) -> 0 | M6: =IF(AND(L6=0,I6<>""),1,0) -> 0 | N6: =IF(AND(L6=0,M6=0,K6<>""),1,0) -> 0 | O6: =IF(COUNTIF(L6:N6,0)=3,1,0) -> 1 | P6: =IF(D6<>"扶養","",IF(E6<>"確認待ち",1,IF(OR(AND(G6="本人の結婚",O6=1),AND(H6="減",OR(N6=1,O6=1))),1,0))) | Q6: =COUNTIF('責任職 企業局→市長部局'!A:A,SQLデータ!B6) -> 0 | R6: =COUNTIF('一般職員 企業局→市長部局'!A:F,SQLデータ!B6) -> 0
A7: 202510002029 | B7: 1256115 | C7: 46084 | D7: 給与口座 | E7: ＯＰ確認中 | F7: 添付待ち | G7: NULL | L7: =IF(ISBLANK(J7),0,1) -> 0 | M7: =IF(AND(L7=0,I7<>""),1,0) -> 0 | N7: =IF(AND(L7=0,M7=0,K7<>""),1,0) -> 0 | O7: =IF(COUNTIF(L7:N7,0)=3,1,0) -> 1 | P7: =IF(D7<>"扶養","",IF(E7<>"確認待ち",1,IF(OR(AND(G7="本人の結婚",O7=1),AND(H7="減",OR(N7=1,O7=1))),1,0))) | Q7: =COUNTIF('責任職 企業局→市長部局'!A:A,SQLデータ!B7) -> 0 | R7: =COUNTIF('一般職員 企業局→市長部局'!A:F,SQLデータ!B7) -> 0
A8: 202510002056 | B8: 1176101 | C8: 46128 | D8: 給与口座 | E8: 確認待ち | G8: NULL | L8: =IF(ISBLANK(J8),0,1) -> 0 | M8: =IF(AND(L8=0,I8<>""),1,0) -> 0 | N8: =IF(AND(L8=0,M8=0,K8<>""),1,0) -> 0 | O8: =IF(COUNTIF(L8:N8,0)=3,1,0) -> 1 | P8: =IF(D8<>"扶養","",IF(E8<>"確認待ち",1,IF(OR(AND(G8="本人の結婚",O8=1),AND(H8="減",OR(N8=1,O8=1))),1,0))) | Q8: =COUNTIF('責任職 企業局→市長部局'!A:A,SQLデータ!B8) -> 0 | R8: =COUNTIF('一般職員 企業局→市長部局'!A:F,SQLデータ!B8) -> 0
A9: 202510002069 | B9: 1182055 | C9: 46090 | D9: 給与口座 | E9: ＯＰ確認中 | F9: 添付待ち | G9: NULL | L9: =IF(ISBLANK(J9),0,1) -> 0 | M9: =IF(AND(L9=0,I9<>""),1,0) -> 0 | N9: =IF(AND(L9=0,M9=0,K9<>""),1,0) -> 0 | O9: =IF(COUNTIF(L9:N9,0)=3,1,0) -> 1 | P9: =IF(D9<>"扶養","",IF(E9<>"確認待ち",1,IF(OR(AND(G9="本人の結婚",O9=1),AND(H9="減",OR(N9=1,O9=1))),1,0))) | Q9: =COUNTIF('責任職 企業局→市長部局'!A:A,SQLデータ!B9) -> 0 | R9: =COUNTIF('一般職員 企業局→市長部局'!A:F,SQLデータ!B9) -> 0
A10: 202510002115 | B10: 1201456 | C10: 46097 | D10: 給与口座 | E10: ＯＰ確認中 | F10: 添付待ち | G10: NULL | L10: =IF(ISBLANK(J10),0,1) -> 0 | M10: =IF(AND(L10=0,I10<>""),1,0) -> 0 | N10: =IF(AND(L10=0,M10=0,K10<>""),1,0) -> 0 | O10: =IF(COUNTIF(L10:N10,0)=3,1,0) -> 1 | P10: =IF(D10<>"扶養","",IF(E10<>"確認待ち",1,IF(OR(AND(G10="本人の結婚",O10=1),AND(H10="減",OR(N10=1,O10=1))),1,0))) | Q10: =COUNTIF('責任職 企業局→市長部局'!A:A,SQLデータ!B10) -> 0 | R10: =COUNTIF('一般職員 企業局→市長部局'!A:F,SQLデータ!B10) -> 0
A11: 202510002128 | B11: 1111168 | C11: 46099 | D11: 給与口座 | E11: ＯＰ確認中 | F11: 添付待ち | G11: NULL | L11: =IF(ISBLANK(J11),0,1) -> 0 | M11: =IF(AND(L11=0,I11<>""),1,0) -> 0 | N11: =IF(AND(L11=0,M11=0,K11<>""),1,0) -> 0 | O11: =IF(COUNTIF(L11:N11,0)=3,1,0) -> 1 | P11: =IF(D11<>"扶養","",IF(E11<>"確認待ち",1,IF(OR(AND(G11="本人の結婚",O11=1),AND(H11="減",OR(N11=1,O11=1))),1,0))) | Q11: =COUNTIF('責任職 企業局→市長部局'!A:A,SQLデータ!B11) -> 0 | R11: =COUNTIF('一般職員 企業局→市長部局'!A:F,SQLデータ!B11) -> 0
A12: 202510002155 | B12: 1126064 | C12: 46104 | D12: 給与口座 | E12: 確認済 | G12: NULL | L12: =IF(ISBLANK(J12),0,1) -> 0 | M12: =IF(AND(L12=0,I12<>""),1,0) -> 0 | N12: =IF(AND(L12=0,M12=0,K12<>""),1,0) -> 0 | O12: =IF(COUNTIF(L12:N12,0)=3,1,0) -> 1 | P12: =IF(D12<>"扶養","",IF(E12<>"確認待ち",1,IF(OR(AND(G12="本人の結婚",O12=1),AND(H12="減",OR(N12=1,O12=1))),1,0))) | Q12: =COUNTIF('責任職 企業局→市長部局'!A:A,SQLデータ!B12) -> 0 | R12: =COUNTIF('一般職員 企業局→市長部局'!A:F,SQLデータ!B12) -> 0
A13: 202510002164 | B13: 1081458 | C13: 46105 | D13: 給与口座 | E13: ＯＰ確認中 | F13: 添付待ち | G13: NULL | L13: =IF(ISBLANK(J13),0,1) -> 0 | M13: =IF(AND(L13=0,I13<>""),1,0) -> 0 | N13: =IF(AND(L13=0,M13=0,K13<>""),1,0) -> 0 | O13: =IF(COUNTIF(L13:N13,0)=3,1,0) -> 1 | P13: =IF(D13<>"扶養","",IF(E13<>"確認待ち",1,IF(OR(AND(G13="本人の結婚",O13=1),AND(H13="減",OR(N13=1,O13=1))),1,0))) | Q13: =COUNTIF('責任職 企業局→市長部局'!A:A,SQLデータ!B13) -> 0 | R13: =COUNTIF('一般職員 企業局→市長部局'!A:F,SQLデータ!B13) -> 0
A14: 202510002216 | B14: 1122110 | C14: 46111 | D14: 給与口座 | E14: ＳＶ確認中 | F14: 保留中 | G14: NULL | L14: =IF(ISBLANK(J14),0,1) -> 0 | M14: =IF(AND(L14=0,I14<>""),1,0) -> 0 | N14: =IF(AND(L14=0,M14=0,K14<>""),1,0) -> 0 | O14: =IF(COUNTIF(L14:N14,0)=3,1,0) -> 1 | P14: =IF(D14<>"扶養","",IF(E14<>"確認待ち",1,IF(OR(AND(G14="本人の結婚",O14=1),AND(H14="減",OR(N14=1,O14=1))),1,0))) | Q14: =COUNTIF('責任職 企業局→市長部局'!A:A,SQLデータ!B14) -> 0 | R14: =COUNTIF('一般職員 企業局→市長部局'!A:F,SQLデータ!B14) -> 0
A15: 202520000560 | B15: 1186140 | C15: 46053 | D15: 児童（認定） | E15: ＯＰ確認中 | F15: オペレータ保留 | G15: NULL | L15: =IF(ISBLANK(J15),0,1) -> 0 | M15: =IF(AND(L15=0,I15<>""),1,0) -> 0 | N15: =IF(AND(L15=0,M15=0,K15<>""),1,0) -> 0 | O15: =IF(COUNTIF(L15:N15,0)=3,1,0) -> 1 | P15: =IF(D15<>"扶養","",IF(E15<>"確認待ち",1,IF(OR(AND(G15="本人の結婚",O15=1),AND(H15="減",OR(N15=1,O15=1))),1,0))) | Q15: =COUNTIF('責任職 企業局→市長部局'!A:A,SQLデータ!B15) -> 0 | R15: =COUNTIF('一般職員 企業局→市長部局'!A:F,SQLデータ!B15) -> 0
A16: 202520000561 | B16: 1156002 | C16: 46059 | D16: 児童（認定） | E16: 確認済 | G16: NULL | L16: =IF(ISBLANK(J16),0,1) -> 0 | M16: =IF(AND(L16=0,I16<>""),1,0) -> 0 | N16: =IF(AND(L16=0,M16=0,K16<>""),1,0) -> 0 | O16: =IF(COUNTIF(L16:N16,0)=3,1,0) -> 1 | P16: =IF(D16<>"扶養","",IF(E16<>"確認待ち",1,IF(OR(AND(G16="本人の結婚",O16=1),AND(H16="減",OR(N16=1,O16=1))),1,0))) | Q16: =COUNTIF('責任職 企業局→市長部局'!A:A,SQLデータ!B16) -> 0 | R16: =COUNTIF('一般職員 企業局→市長部局'!A:F,SQLデータ!B16) -> 0
A17: 202520000585 | B17: 1251245 | C17: 46079 | D17: 児童（認定） | E17: 確認待ち | F17: 添付待ち | G17: NULL | L17: =IF(ISBLANK(J17),0,1) -> 0 | M17: =IF(AND(L17=0,I17<>""),1,0) -> 0 | N17: =IF(AND(L17=0,M17=0,K17<>""),1,0) -> 0 | O17: =IF(COUNTIF(L17:N17,0)=3,1,0) -> 1 | P17: =IF(D17<>"扶養","",IF(E17<>"確認待ち",1,IF(OR(AND(G17="本人の結婚",O17=1),AND(H17="減",OR(N17=1,O17=1))),1,0))) | Q17: =COUNTIF('責任職 企業局→市長部局'!A:A,SQLデータ!B17) -> 0 | R17: =COUNTIF('一般職員 企業局→市長部局'!A:F,SQLデータ!B17) -> 0
A18: 202520000591 | B18: 1192017 | C18: 46084 | D18: 児童（認定） | E18: 確認済 | F18: オペレータ保留 | G18: NULL | L18: =IF(ISBLANK(J18),0,1) -> 0 | M18: =IF(AND(L18=0,I18<>""),1,0) -> 0 | N18: =IF(AND(L18=0,M18=0,K18<>""),1,0) -> 0 | O18: =IF(COUNTIF(L18:N18,0)=3,1,0) -> 1 | P18: =IF(D18<>"扶養","",IF(E18<>"確認待ち",1,IF(OR(AND(G18="本人の結婚",O18=1),AND(H18="減",OR(N18=1,O18=1))),1,0))) | Q18: =COUNTIF('責任職 企業局→市長部局'!A:A,SQLデータ!B18) -> 0 | R18: =COUNTIF('一般職員 企業局→市長部局'!A:F,SQLデータ!B18) -> 0
A19: 202520000600 | B19: 1211166 | C19: 46091 | D19: 児童（認定） | E19: ＯＰ確認中 | F19: オペレータ保留 | G19: NULL | L19: =IF(ISBLANK(J19),0,1) -> 0 | M19: =IF(AND(L19=0,I19<>""),1,0) -> 0 | N19: =IF(AND(L19=0,M19=0,K19<>""),1,0) -> 0 | O19: =IF(COUNTIF(L19:N19,0)=3,1,0) -> 1 | P19: =IF(D19<>"扶養","",IF(E19<>"確認待ち",1,IF(OR(AND(G19="本人の結婚",O19=1),AND(H19="減",OR(N19=1,O19=1))),1,0))) | Q19: =COUNTIF('責任職 企業局→市長部局'!A:A,SQLデータ!B19) -> 0 | R19: =COUNTIF('一般職員 企業局→市長部局'!A:F,SQLデータ!B19) -> 0
A20: 202520000603 | B20: 920331 | C20: 46091 | D20: 児童（認定） | E20: 確認済 | G20: NULL | L20: =IF(ISBLANK(J20),0,1) -> 0 | M20: =IF(AND(L20=0,I20<>""),1,0) -> 0 | N20: =IF(AND(L20=0,M20=0,K20<>""),1,0) -> 0 | O20: =IF(COUNTIF(L20:N20,0)=3,1,0) -> 1 | P20: =IF(D20<>"扶養","",IF(E20<>"確認待ち",1,IF(OR(AND(G20="本人の結婚",O20=1),AND(H20="減",OR(N20=1,O20=1))),1,0))) | Q20: =COUNTIF('責任職 企業局→市長部局'!A:A,SQLデータ!B20) -> 0 | R20: =COUNTIF('一般職員 企業局→市長部局'!A:F,SQLデータ!B20) -> 0
A21: 202520000605 | B21: 1161250 | C21: 46092 | D21: 児童（認定） | E21: 確認済 | F21: オペレータ保留 | G21: NULL | L21: =IF(ISBLANK(J21),0,1) -> 0 | M21: =IF(AND(L21=0,I21<>""),1,0) -> 0 | N21: =IF(AND(L21=0,M21=0,K21<>""),1,0) -> 0 | O21: =IF(COUNTIF(L21:N21,0)=3,1,0) -> 1 | P21: =IF(D21<>"扶養","",IF(E21<>"確認待ち",1,IF(OR(AND(G21="本人の結婚",O21=1),AND(H21="減",OR(N21=1,O21=1))),1,0))) | Q21: =COUNTIF('責任職 企業局→市長部局'!A:A,SQLデータ!B21) -> 0 | R21: =COUNTIF('一般職員 企業局→市長部局'!A:F,SQLデータ!B21) -> 0
A22: 202520000616 | B22: 1111437 | C22: 46104 | D22: 児童（認定） | E22: ＳＶ確認中 | F22: 1,7 | G22: NULL | L22: =IF(ISBLANK(J22),0,1) -> 0 | M22: =IF(AND(L22=0,I22<>""),1,0) -> 0 | N22: =IF(AND(L22=0,M22=0,K22<>""),1,0) -> 0 | O22: =IF(COUNTIF(L22:N22,0)=3,1,0) -> 1 | P22: =IF(D22<>"扶養","",IF(E22<>"確認待ち",1,IF(OR(AND(G22="本人の結婚",O22=1),AND(H22="減",OR(N22=1,O22=1))),1,0))) | Q22: =COUNTIF('責任職 企業局→市長部局'!A:A,SQLデータ!B22) -> 0 | R22: =COUNTIF('一般職員 企業局→市長部局'!A:F,SQLデータ!B22) -> 0
A23: 202520000617 | B23: 1156093 | C23: 46106 | D23: 児童（認定） | E23: 確認待ち | F23: 添付待ち | G23: NULL | L23: =IF(ISBLANK(J23),0,1) -> 0 | M23: =IF(AND(L23=0,I23<>""),1,0) -> 0 | N23: =IF(AND(L23=0,M23=0,K23<>""),1,0) -> 0 | O23: =IF(COUNTIF(L23:N23,0)=3,1,0) -> 1 | P23: =IF(D23<>"扶養","",IF(E23<>"確認待ち",1,IF(OR(AND(G23="本人の結婚",O23=1),AND(H23="減",OR(N23=1,O23=1))),1,0))) | Q23: =COUNTIF('責任職 企業局→市長部局'!A:A,SQLデータ!B23) -> 0 | R23: =COUNTIF('一般職員 企業局→市長部局'!A:F,SQLデータ!B23) -> 0
A24: 202520000618 | B24: 1206045 | C24: 46107 | D24: 児童（認定） | E24: 確認待ち | F24: 添付待ち | G24: NULL | L24: =IF(ISBLANK(J24),0,1) -> 0 | M24: =IF(AND(L24=0,I24<>""),1,0) -> 0 | N24: =IF(AND(L24=0,M24=0,K24<>""),1,0) -> 0 | O24: =IF(COUNTIF(L24:N24,0)=3,1,0) -> 1 | P24: =IF(D24<>"扶養","",IF(E24<>"確認待ち",1,IF(OR(AND(G24="本人の結婚",O24=1),AND(H24="減",OR(N24=1,O24=1))),1,0))) | Q24: =COUNTIF('責任職 企業局→市長部局'!A:A,SQLデータ!B24) -> 0 | R24: =COUNTIF('一般職員 企業局→市長部局'!A:F,SQLデータ!B24) -> 0
A25: 202520000621 | B25: 1151461 | C25: 46127 | D25: 児童（認定） | E25: 確認待ち | G25: NULL | L25: =IF(ISBLANK(J25),0,1) -> 0 | M25: =IF(AND(L25=0,I25<>""),1,0) -> 0 | N25: =IF(AND(L25=0,M25=0,K25<>""),1,0) -> 0 | O25: =IF(COUNTIF(L25:N25,0)=3,1,0) -> 1 | P25: =IF(D25<>"扶養","",IF(E25<>"確認待ち",1,IF(OR(AND(G25="本人の結婚",O25=1),AND(H25="減",OR(N25=1,O25=1))),1,0))) | Q25: =COUNTIF('責任職 企業局→市長部局'!A:A,SQLデータ!B25) -> 0 | R25: =COUNTIF('一般職員 企業局→市長部局'!A:F,SQLデータ!B25) -> 0
A26: 202520000622 | B26: 1194097 | C26: 46118 | D26: 児童（認定） | E26: 確認済 | F26: オペレータ保留 | G26: NULL | L26: =IF(ISBLANK(J26),0,1) -> 0 | M26: =IF(AND(L26=0,I26<>""),1,0) -> 0 | N26: =IF(AND(L26=0,M26=0,K26<>""),1,0) -> 0 | O26: =IF(COUNTIF(L26:N26,0)=3,1,0) -> 1 | P26: =IF(D26<>"扶養","",IF(E26<>"確認待ち",1,IF(OR(AND(G26="本人の結婚",O26=1),AND(H26="減",OR(N26=1,O26=1))),1,0))) | Q26: =COUNTIF('責任職 企業局→市長部局'!A:A,SQLデータ!B26) -> 0 | R26: =COUNTIF('一般職員 企業局→市長部局'!A:F,SQLデータ!B26) -> 0
A27: 202520000623 | B27: 1131048 | C27: 46111 | D27: 児童（認定） | E27: 確認済 | F27: オペレータ保留 | G27: NULL | L27: =IF(ISBLANK(J27),0,1) -> 0 | M27: =IF(AND(L27=0,I27<>""),1,0) -> 0 | N27: =IF(AND(L27=0,M27=0,K27<>""),1,0) -> 0 | O27: =IF(COUNTIF(L27:N27,0)=3,1,0) -> 1 | P27: =IF(D27<>"扶養","",IF(E27<>"確認待ち",1,IF(OR(AND(G27="本人の結婚",O27=1),AND(H27="減",OR(N27=1,O27=1))),1,0))) | Q27: =COUNTIF('責任職 企業局→市長部局'!A:A,SQLデータ!B27) -> 0 | R27: =COUNTIF('一般職員 企業局→市長部局'!A:F,SQLデータ!B27) -> 0
A28: 202530000153 | B28: 1071006 | C28: 45804 | D28: 児童（改定） | E28: 確認済 | G28: NULL | L28: =IF(ISBLANK(J28),0,1) -> 0 | M28: =IF(AND(L28=0,I28<>""),1,0) -> 0 | N28: =IF(AND(L28=0,M28=0,K28<>""),1,0) -> 0 | O28: =IF(COUNTIF(L28:N28,0)=3,1,0) -> 1 | P28: =IF(D28<>"扶養","",IF(E28<>"確認待ち",1,IF(OR(AND(G28="本人の結婚",O28=1),AND(H28="減",OR(N28=1,O28=1))),1,0))) | Q28: =COUNTIF('責任職 企業局→市長部局'!A:A,SQLデータ!B28) -> 0 | R28: =COUNTIF('一般職員 企業局→市長部局'!A:F,SQLデータ!B28) -> 0
A29: 202530000259 | B29: 1034029 | C29: 45863 | D29: 児童（改定） | E29: 申請受付 | F29: 保留中 | G29: NULL | L29: =IF(ISBLANK(J29),0,1) -> 0 | M29: =IF(AND(L29=0,I29<>""),1,0) -> 0 | N29: =IF(AND(L29=0,M29=0,K29<>""),1,0) -> 0 | O29: =IF(COUNTIF(L29:N29,0)=3,1,0) -> 1 | P29: =IF(D29<>"扶養","",IF(E29<>"確認待ち",1,IF(OR(AND(G29="本人の結婚",O29=1),AND(H29="減",OR(N29=1,O29=1))),1,0))) | Q29: =COUNTIF('責任職 企業局→市長部局'!A:A,SQLデータ!B29) -> 0 | R29: =COUNTIF('一般職員 企業局→市長部局'!A:F,SQLデータ!B29) -> 0
A30: 202530000456 | B30: 1146122 | C30: 46099 | D30: 児童（改定） | E30: 確認済 | F30: オペレータ保留 | G30: NULL | L30: =IF(ISBLANK(J30),0,1) -> 0 | M30: =IF(AND(L30=0,I30<>""),1,0) -> 0 | N30: =IF(AND(L30=0,M30=0,K30<>""),1,0) -> 0 | O30: =IF(COUNTIF(L30:N30,0)=3,1,0) -> 1 | P30: =IF(D30<>"扶養","",IF(E30<>"確認待ち",1,IF(OR(AND(G30="本人の結婚",O30=1),AND(H30="減",OR(N30=1,O30=1))),1,0))) | Q30: =COUNTIF('責任職 企業局→市長部局'!A:A,SQLデータ!B30) -> 0 | R30: =COUNTIF('一般職員 企業局→市長部局'!A:F,SQLデータ!B30) -> 0
A31: 202530000458 | B31: 1186125 | C31: 46090 | D31: 児童（改定） | E31: 確認済 | F31: オペレータ保留 | G31: NULL | L31: =IF(ISBLANK(J31),0,1) -> 0 | M31: =IF(AND(L31=0,I31<>""),1,0) -> 0 | N31: =IF(AND(L31=0,M31=0,K31<>""),1,0) -> 0 | O31: =IF(COUNTIF(L31:N31,0)=3,1,0) -> 1 | P31: =IF(D31<>"扶養","",IF(E31<>"確認待ち",1,IF(OR(AND(G31="本人の結婚",O31=1),AND(H31="減",OR(N31=1,O31=1))),1,0))) | Q31: =COUNTIF('責任職 企業局→市長部局'!A:A,SQLデータ!B31) -> 0 | R31: =COUNTIF('一般職員 企業局→市長部局'!A:F,SQLデータ!B31) -> 0
A32: 202530000459 | B32: 1082041 | C32: 46080 | D32: 児童（改定） | E32: 確認済 | G32: NULL | L32: =IF(ISBLANK(J32),0,1) -> 0 | M32: =IF(AND(L32=0,I32<>""),1,0) -> 0 | N32: =IF(AND(L32=0,M32=0,K32<>""),1,0) -> 0 | O32: =IF(COUNTIF(L32:N32,0)=3,1,0) -> 1 | P32: =IF(D32<>"扶養","",IF(E32<>"確認待ち",1,IF(OR(AND(G32="本人の結婚",O32=1),AND(H32="減",OR(N32=1,O32=1))),1,0))) | Q32: =COUNTIF('責任職 企業局→市長部局'!A:A,SQLデータ!B32) -> 0 | R32: =COUNTIF('一般職員 企業局→市長部局'!A:F,SQLデータ!B32) -> 0
A33: 202530000462 | B33: 1126005 | C33: 46092 | D33: 児童（改定） | E33: 確認済 | G33: NULL | L33: =IF(ISBLANK(J33),0,1) -> 0 | M33: =IF(AND(L33=0,I33<>""),1,0) -> 0 | N33: =IF(AND(L33=0,M33=0,K33<>""),1,0) -> 0 | O33: =IF(COUNTIF(L33:N33,0)=3,1,0) -> 1 | P33: =IF(D33<>"扶養","",IF(E33<>"確認待ち",1,IF(OR(AND(G33="本人の結婚",O33=1),AND(H33="減",OR(N33=1,O33=1))),1,0))) | Q33: =COUNTIF('責任職 企業局→市長部局'!A:A,SQLデータ!B33) -> 0 | R33: =COUNTIF('一般職員 企業局→市長部局'!A:F,SQLデータ!B33) -> 0
A34: 202530000464 | B34: 1126011 | C34: 46097 | D34: 児童（改定） | E34: 確認済 | F34: オペレータ保留 | G34: NULL | L34: =IF(ISBLANK(J34),0,1) -> 0 | M34: =IF(AND(L34=0,I34<>""),1,0) -> 0 | N34: =IF(AND(L34=0,M34=0,K34<>""),1,0) -> 0 | O34: =IF(COUNTIF(L34:N34,0)=3,1,0) -> 1 | P34: =IF(D34<>"扶養","",IF(E34<>"確認待ち",1,IF(OR(AND(G34="本人の結婚",O34=1),AND(H34="減",OR(N34=1,O34=1))),1,0))) | Q34: =COUNTIF('責任職 企業局→市長部局'!A:A,SQLデータ!B34) -> 0 | R34: =COUNTIF('一般職員 企業局→市長部局'!A:F,SQLデータ!B34) -> 0
A35: 202530000465 | B35: 1191466 | C35: 46099 | D35: 児童（改定） | E35: ＳＶ確認中 | G35: NULL | L35: =IF(ISBLANK(J35),0,1) -> 0 | M35: =IF(AND(L35=0,I35<>""),1,0) -> 0 | N35: =IF(AND(L35=0,M35=0,K35<>""),1,0) -> 0 | O35: =IF(COUNTIF(L35:N35,0)=3,1,0) -> 1 | P35: =IF(D35<>"扶養","",IF(E35<>"確認待ち",1,IF(OR(AND(G35="本人の結婚",O35=1),AND(H35="減",OR(N35=1,O35=1))),1,0))) | Q35: =COUNTIF('責任職 企業局→市長部局'!A:A,SQLデータ!B35) -> 0 | R35: =COUNTIF('一般職員 企業局→市長部局'!A:F,SQLデータ!B35) -> 0
A36: 202530000468 | B36: 1193025 | C36: 46099 | D36: 児童（改定） | E36: 確認済 | F36: オペレータ保留 | G36: NULL | L36: =IF(ISBLANK(J36),0,1) -> 0 | M36: =IF(AND(L36=0,I36<>""),1,0) -> 0 | N36: =IF(AND(L36=0,M36=0,K36<>""),1,0) -> 0 | O36: =IF(COUNTIF(L36:N36,0)=3,1,0) -> 1 | P36: =IF(D36<>"扶養","",IF(E36<>"確認待ち",1,IF(OR(AND(G36="本人の結婚",O36=1),AND(H36="減",OR(N36=1,O36=1))),1,0))) | Q36: =COUNTIF('責任職 企業局→市長部局'!A:A,SQLデータ!B36) -> 0 | R36: =COUNTIF('一般職員 企業局→市長部局'!A:F,SQLデータ!B36) -> 0
A37: 202530000469 | B37: 974169 | C37: 46115 | D37: 児童（改定） | E37: 確認待ち | G37: NULL | L37: =IF(ISBLANK(J37),0,1) -> 0 | M37: =IF(AND(L37=0,I37<>""),1,0) -> 0 | N37: =IF(AND(L37=0,M37=0,K37<>""),1,0) -> 0 | O37: =IF(COUNTIF(L37:N37,0)=3,1,0) -> 1 | P37: =IF(D37<>"扶養","",IF(E37<>"確認待ち",1,IF(OR(AND(G37="本人の結婚",O37=1),AND(H37="減",OR(N37=1,O37=1))),1,0))) | Q37: =COUNTIF('責任職 企業局→市長部局'!A:A,SQLデータ!B37) -> 0 | R37: =COUNTIF('一般職員 企業局→市長部局'!A:F,SQLデータ!B37) -> 0
A38: 202530000470 | B38: 1162079 | C38: 46105 | D38: 児童（改定） | E38: 確認済 | G38: NULL | L38: =IF(ISBLANK(J38),0,1) -> 0 | M38: =IF(AND(L38=0,I38<>""),1,0) -> 0 | N38: =IF(AND(L38=0,M38=0,K38<>""),1,0) -> 0 | O38: =IF(COUNTIF(L38:N38,0)=3,1,0) -> 1 | P38: =IF(D38<>"扶養","",IF(E38<>"確認待ち",1,IF(OR(AND(G38="本人の結婚",O38=1),AND(H38="減",OR(N38=1,O38=1))),1,0))) | Q38: =COUNTIF('責任職 企業局→市長部局'!A:A,SQLデータ!B38) -> 0 | R38: =COUNTIF('一般職員 企業局→市長部局'!A:F,SQLデータ!B38) -> 0
A39: 202530000471 | B39: 1176039 | C39: 46104 | D39: 児童（改定） | E39: ＯＰ確認中 | F39: オペレータ保留 | G39: NULL | L39: =IF(ISBLANK(J39),0,1) -> 0 | M39: =IF(AND(L39=0,I39<>""),1,0) -> 0 | N39: =IF(AND(L39=0,M39=0,K39<>""),1,0) -> 0 | O39: =IF(COUNTIF(L39:N39,0)=3,1,0) -> 1 | P39: =IF(D39<>"扶養","",IF(E39<>"確認待ち",1,IF(OR(AND(G39="本人の結婚",O39=1),AND(H39="減",OR(N39=1,O39=1))),1,0))) | Q39: =COUNTIF('責任職 企業局→市長部局'!A:A,SQLデータ!B39) -> 0 | R39: =COUNTIF('一般職員 企業局→市長部局'!A:F,SQLデータ!B39) -> 0
A40: 202530000475 | B40: 1201040 | C40: 46108 | D40: 児童（改定） | E40: 確認済 | F40: オペレータ保留 | G40: NULL | L40: =IF(ISBLANK(J40),0,1) -> 0 | M40: =IF(AND(L40=0,I40<>""),1,0) -> 0 | N40: =IF(AND(L40=0,M40=0,K40<>""),1,0) -> 0 | O40: =IF(COUNTIF(L40:N40,0)=3,1,0) -> 1 | P40: =IF(D40<>"扶養","",IF(E40<>"確認待ち",1,IF(OR(AND(G40="本人の結婚",O40=1),AND(H40="減",OR(N40=1,O40=1))),1,0))) | Q40: =COUNTIF('責任職 企業局→市長部局'!A:A,SQLデータ!B40) -> 0 | R40: =COUNTIF('一般職員 企業局→市長部局'!A:F,SQLデータ!B40) -> 0
...

Sheet 届出事由・区分・届出年月日ごと集計
A1: 増減 | B1: 届出事由 | C1: 区分 | D1: 申請件数 | E1: 開始日 | F1: 45658 | G1: 46111 | H1: =G1+7 -> 46118 | I1: =H1+7 -> 46125 | J1: =I1+7 -> 46132 | K1: =J1+7 -> 46139 | L1: =K1+7 -> 46146 | M1: =L1+7 -> 46153 | N1: =M1+7 -> 46160 | O1: =N1+7 -> 46167 | ... T1: =S1+7 -> 46202
E2: 終了日 | F2: 46110 | G2: 46117 | H2: =G2+7 -> 46124 | I2: =H2+7 -> 46131 | J2: =I2+7 -> 46138 | K2: =J2+7 -> 46145 | L2: =K2+7 -> 46152 | M2: =L2+7 -> 46159 | N2: =M2+7 -> 46166 | O2: =N2+7 -> 46173 | ... T2: =S2+7 -> 46208
A3: 増 | B3: 出生 | C3: 共済あり | D3: =COUNTIFS(SQLデータ!$D:$D,"扶養",SQLデータ!$H:$H,届出事由・区分・届出年月日ごと集計!$A3,SQLデータ!$G:$G,届出事由・区分・届出年月日ごと集計!$B3,SQLデータ!$L:$L,1) -> 17 | F3: =COUNTIFS(SQLデータ!$D:$D,"扶養",SQLデータ!$P:$P,1,SQLデータ!$H:$H,届出事由・区分・届出年月日ごと集計!$A3,SQLデータ!$G:$G,届出事由・区分・届出年月日ごと集計!$B3,SQLデータ!$L:$L,1,SQLデータ!$F:$F,"",SQLデータ!$C:$C,">="&届出事由・区分・届出年月日ごと集計!F$1,SQLデータ!$C:$C,"<="&届出事由・区分・届出年月日ごと集計!F$2) -> 1 | G3: =COUNTIFS(SQLデータ!$D:$D,"扶養",SQLデータ!$P:$P,1,SQLデータ!$H:$H,届出事由・区分・届出年月日ごと集計!$A3,SQLデータ!$G:$G,届出事由・区分・届出年月日ごと集計!$B3,SQLデータ!$L:$L,1,SQLデータ!$F:$F,"",SQLデータ!$C:$C,">="&届出事由・区分・届出年月日ごと集計!G$1,SQLデータ!$C:$C,"<="&届出事由・区分・届出年月日ごと集計!G$2) -> 0 | H3: =COUNTIFS(SQLデータ!$D:$D,"扶養",SQLデータ!$P:$P,1,SQLデータ!$H:$H,届出事由・区分・届出年月日ごと集計!$A3,SQLデータ!$G:$G,届出事由・区分・届出年月日ごと集計!$B3,SQLデータ!$L:$L,1,SQLデータ!$F:$F,"",SQLデータ!$C:$C,">="&届出事由・区分・届出年月日ごと集計!H$1,SQLデータ!$C:$C,"<="&届出事由・区分・届出年月日ごと集計!H$2) -> 0 | I3: =COUNTIFS(SQLデータ!$D:$D,"扶養",SQLデータ!$P:$P,1,SQLデータ!$H:$H,届出事由・区分・届出年月日ごと集計!$A3,SQLデータ!$G:$G,届出事由・区分・届出年月日ごと集計!$B3,SQLデータ!$L:$L,1,SQLデータ!$F:$F,"",SQLデータ!$C:$C,">="&届出事由・区分・届出年月日ごと集計!I$1,SQLデータ!$C:$C,"<="&届出事由・区分・届出年月日ごと集計!I$2) -> 1 | J3: =COUNTIFS(SQLデータ!$D:$D,"扶養",SQLデータ!$P:$P,1,SQLデータ!$H:$H,届出事由・区分・届出年月日ごと集計!$A3,SQLデータ!$G:$G,届出事由・区分・届出年月日ごと集計!$B3,SQLデータ!$L:$L,1,SQLデータ!$F:$F,"",SQLデータ!$C:$C,">="&届出事由・区分・届出年月日ごと集計!J$1,SQLデータ!$C:$C,"<="&届出事由・区分・届出年月日ごと集計!J$2) -> 0 | K3: =COUNTIFS(SQLデータ!$D:$D,"扶養",SQLデータ!$P:$P,1,SQLデータ!$H:$H,届出事由・区分・届出年月日ごと集計!$A3,SQLデータ!$G:$G,届出事由・区分・届出年月日ごと集計!$B3,SQLデータ!$L:$L,1,SQLデータ!$F:$F,"",SQLデータ!$C:$C,">="&届出事由・区分・届出年月日ごと集計!K$1,SQLデータ!$C:$C,"<="&届出事由・区分・届出年月日ごと集計!K$2) -> 0 | L3: =COUNTIFS(SQLデータ!$D:$D,"扶養",SQLデータ!$P:$P,1,SQLデータ!$H:$H,届出事由・区分・届出年月日ごと集計!$A3,SQLデータ!$G:$G,届出事由・区分・届出年月日ごと集計!$B3,SQLデータ!$L:$L,1,SQLデータ!$F:$F,"",SQLデータ!$C:$C,">="&届出事由・区分・届出年月日ごと集計!L$1,SQLデータ!$C:$C,"<="&届出事由・区分・届出年月日ごと集計!L$2) -> 0 | M3: =COUNTIFS(SQLデータ!$D:$D,"扶養",SQLデータ!$P:$P,1,SQLデータ!$H:$H,届出事由・区分・届出年月日ごと集計!$A3,SQLデータ!$G:$G,届出事由・区分・届出年月日ごと集計!$B3,SQLデータ!$L:$L,1,SQLデータ!$F:$F,"",SQLデータ!$C:$C,">="&届出事由・区分・届出年月日ごと集計!M$1,SQLデータ!$C:$C,"<="&届出事由・区分・届出年月日ごと集計!M$2) -> 0 | ... T3: =COUNTIFS(SQLデータ!$D:$D,"扶養",SQLデータ!$P:$P,1,SQLデータ!$H:$H,届出事由・区分・届出年月日ごと集計!$A3,SQLデータ!$G:$G,届出事由・区分・届出年月日ごと集計!$B3,SQLデータ!$L:$L,1,SQLデータ!$F:$F,"",SQLデータ!$C:$C,">="&届出事由・区分・届出年月日ごと集計!T$1,SQLデータ!$C:$C,"<="&届出事由・区分・届出年月日ごと集計!T$2) -> 0
A4: 増 | B4: 出生 | C4: 扶養手当あり | D4: =COUNTIFS(SQLデータ!$D:$D,"扶養",SQLデータ!$H:$H,届出事由・区分・届出年月日ごと集計!$A4,SQLデータ!$G:$G,届出事由・区分・届出年月日ごと集計!$B4,SQLデータ!$M:$M,1) -> 2 | F4: =COUNTIFS(SQLデータ!$D:$D,"扶養",SQLデータ!$P:$P,1,SQLデータ!$H:$H,届出事由・区分・届出年月日ごと集計!$A4,SQLデータ!$G:$G,届出事由・区分・届出年月日ごと集計!$B4,SQLデータ!$M:$M,1,SQLデータ!$F:$F,"",SQLデータ!$C:$C,">="&届出事由・区分・届出年月日ごと集計!F$1,SQLデータ!$C:$C,"<="&届出事由・区分・届出年月日ごと集計!F$2) -> 0 | G4: =COUNTIFS(SQLデータ!$D:$D,"扶養",SQLデータ!$P:$P,1,SQLデータ!$H:$H,届出事由・区分・届出年月日ごと集計!$A4,SQLデータ!$G:$G,届出事由・区分・届出年月日ごと集計!$B4,SQLデータ!$M:$M,1,SQLデータ!$F:$F,"",SQLデータ!$C:$C,">="&届出事由・区分・届出年月日ごと集計!G$1,SQLデータ!$C:$C,"<="&届出事由・区分・届出年月日ごと集計!G$2) -> 0 | H4: =COUNTIFS(SQLデータ!$D:$D,"扶養",SQLデータ!$P:$P,1,SQLデータ!$H:$H,届出事由・区分・届出年月日ごと集計!$A4,SQLデータ!$G:$G,届出事由・区分・届出年月日ごと集計!$B4,SQLデータ!$M:$M,1,SQLデータ!$F:$F,"",SQLデータ!$C:$C,">="&届出事由・区分・届出年月日ごと集計!H$1,SQLデータ!$C:$C,"<="&届出事由・区分・届出年月日ごと集計!H$2) -> 0 | I4: =COUNTIFS(SQLデータ!$D:$D,"扶養",SQLデータ!$P:$P,1,SQLデータ!$H:$H,届出事由・区分・届出年月日ごと集計!$A4,SQLデータ!$G:$G,届出事由・区分・届出年月日ごと集計!$B4,SQLデータ!$M:$M,1,SQLデータ!$F:$F,"",SQLデータ!$C:$C,">="&届出事由・区分・届出年月日ごと集計!I$1,SQLデータ!$C:$C,"<="&届出事由・区分・届出年月日ごと集計!I$2) -> 0 | J4: =COUNTIFS(SQLデータ!$D:$D,"扶養",SQLデータ!$P:$P,1,SQLデータ!$H:$H,届出事由・区分・届出年月日ごと集計!$A4,SQLデータ!$G:$G,届出事由・区分・届出年月日ごと集計!$B4,SQLデータ!$M:$M,1,SQLデータ!$F:$F,"",SQLデータ!$C:$C,">="&届出事由・区分・届出年月日ごと集計!J$1,SQLデータ!$C:$C,"<="&届出事由・区分・届出年月日ごと集計!J$2) -> 0 | K4: =COUNTIFS(SQLデータ!$D:$D,"扶養",SQLデータ!$P:$P,1,SQLデータ!$H:$H,届出事由・区分・届出年月日ごと集計!$A4,SQLデータ!$G:$G,届出事由・区分・届出年月日ごと集計!$B4,SQLデータ!$M:$M,1,SQLデータ!$F:$F,"",SQLデータ!$C:$C,">="&届出事由・区分・届出年月日ごと集計!K$1,SQLデータ!$C:$C,"<="&届出事由・区分・届出年月日ごと集計!K$2) -> 0 | L4: =COUNTIFS(SQLデータ!$D:$D,"扶養",SQLデータ!$P:$P,1,SQLデータ!$H:$H,届出事由・区分・届出年月日ごと集計!$A4,SQLデータ!$G:$G,届出事由・区分・届出年月日ごと集計!$B4,SQLデータ!$M:$M,1,SQLデータ!$F:$F,"",SQLデータ!$C:$C,">="&届出事由・区分・届出年月日ごと集計!L$1,SQLデータ!$C:$C,"<="&届出事由・区分・届出年月日ごと集計!L$2) -> 0 | M4: =COUNTIFS(SQLデータ!$D:$D,"扶養",SQLデータ!$P:$P,1,SQLデータ!$H:$H,届出事由・区分・届出年月日ごと集計!$A4,SQLデータ!$G:$G,届出事由・区分・届出年月日ごと集計!$B4,SQLデータ!$M:$M,1,SQLデータ!$F:$F,"",SQLデータ!$C:$C,">="&届出事由・区分・届出年月日ごと集計!M$1,SQLデータ!$C:$C,"<="&届出事由・区分・届出年月日ごと集計!M$2) -> 0 | ... T4: =COUNTIFS(SQLデータ!$D:$D,"扶養",SQLデータ!$P:$P,1,SQLデータ!$H:$H,届出事由・区分・届出年月日ごと集計!$A4,SQLデータ!$G:$G,届出事由・区分・届出年月日ごと集計!$B4,SQLデータ!$M:$M,1,SQLデータ!$F:$F,"",SQLデータ!$C:$C,">="&届出事由・区分・届出年月日ごと集計!T$1,SQLデータ!$C:$C,"<="&届出事由・区分・届出年月日ごと集計!T$2) -> 0
A5: 増 | B5: 出生 | C5: 税控除のみ | D5: =COUNTIFS(SQLデータ!$D:$D,"扶養",SQLデータ!$H:$H,届出事由・区分・届出年月日ごと集計!$A5,SQLデータ!$G:$G,届出事由・区分・届出年月日ごと集計!$B5,SQLデータ!$N:$N,1) -> 0 | F5: =COUNTIFS(SQLデータ!$D:$D,"扶養",SQLデータ!$P:$P,1,SQLデータ!$H:$H,届出事由・区分・届出年月日ごと集計!$A5,SQLデータ!$G:$G,届出事由・区分・届出年月日ごと集計!$B5,SQLデータ!$N:$N,1,SQLデータ!$F:$F,"",SQLデータ!$C:$C,">="&届出事由・区分・届出年月日ごと集計!F$1,SQLデータ!$C:$C,"<="&届出事由・区分・届出年月日ごと集計!F$2) -> 0 | G5: =COUNTIFS(SQLデータ!$D:$D,"扶養",SQLデータ!$P:$P,1,SQLデータ!$H:$H,届出事由・区分・届出年月日ごと集計!$A5,SQLデータ!$G:$G,届出事由・区分・届出年月日ごと集計!$B5,SQLデータ!$N:$N,1,SQLデータ!$F:$F,"",SQLデータ!$C:$C,">="&届出事由・区分・届出年月日ごと集計!G$1,SQLデータ!$C:$C,"<="&届出事由・区分・届出年月日ごと集計!G$2) -> 0 | H5: =COUNTIFS(SQLデータ!$D:$D,"扶養",SQLデータ!$P:$P,1,SQLデータ!$H:$H,届出事由・区分・届出年月日ごと集計!$A5,SQLデータ!$G:$G,届出事由・区分・届出年月日ごと集計!$B5,SQLデータ!$N:$N,1,SQLデータ!$F:$F,"",SQLデータ!$C:$C,">="&届出事由・区分・届出年月日ごと集計!H$1,SQLデータ!$C:$C,"<="&届出事由・区分・届出年月日ごと集計!H$2) -> 0 | I5: =COUNTIFS(SQLデータ!$D:$D,"扶養",SQLデータ!$P:$P,1,SQLデータ!$H:$H,届出事由・区分・届出年月日ごと集計!$A5,SQLデータ!$G:$G,届出事由・区分・届出年月日ごと集計!$B5,SQLデータ!$N:$N,1,SQLデータ!$F:$F,"",SQLデータ!$C:$C,">="&届出事由・区分・届出年月日ごと集計!I$1,SQLデータ!$C:$C,"<="&届出事由・区分・届出年月日ごと集計!I$2) -> 0 | J5: =COUNTIFS(SQLデータ!$D:$D,"扶養",SQLデータ!$P:$P,1,SQLデータ!$H:$H,届出事由・区分・届出年月日ごと集計!$A5,SQLデータ!$G:$G,届出事由・区分・届出年月日ごと集計!$B5,SQLデータ!$N:$N,1,SQLデータ!$F:$F,"",SQLデータ!$C:$C,">="&届出事由・区分・届出年月日ごと集計!J$1,SQLデータ!$C:$C,"<="&届出事由・区分・届出年月日ごと集計!J$2) -> 0 | K5: =COUNTIFS(SQLデータ!$D:$D,"扶養",SQLデータ!$P:$P,1,SQLデータ!$H:$H,届出事由・区分・届出年月日ごと集計!$A5,SQLデータ!$G:$G,届出事由・区分・届出年月日ごと集計!$B5,SQLデータ!$N:$N,1,SQLデータ!$F:$F,"",SQLデータ!$C:$C,">="&届出事由・区分・届出年月日ごと集計!K$1,SQLデータ!$C:$C,"<="&届出事由・区分・届出年月日ごと集計!K$2) -> 0 | L5: =COUNTIFS(SQLデータ!$D:$D,"扶養",SQLデータ!$P:$P,1,SQLデータ!$H:$H,届出事由・区分・届出年月日ごと集計!$A5,SQLデータ!$G:$G,届出事由・区分・届出年月日ごと集計!$B5,SQLデータ!$N:$N,1,SQLデータ!$F:$F,"",SQLデータ!$C:$C,">="&届出事由・区分・届出年月日ごと集計!L$1,SQLデータ!$C:$C,"<="&届出事由・区分・届出年月日ごと集計!L$2) -> 0 | M5: =COUNTIFS(SQLデータ!$D:$D,"扶養",SQLデータ!$P:$P,1,SQLデータ!$H:$H,届出事由・区分・届出年月日ごと集計!$A5,SQLデータ!$G:$G,届出事由・区分・届出年月日ごと集計!$B5,SQLデータ!$N:$N,1,SQLデータ!$F:$F,"",SQLデータ!$C:$C,">="&届出事由・区分・届出年月日ごと集計!M$1,SQLデータ!$C:$C,"<="&届出事由・区分・届出年月日ごと集計!M$2) -> 0 | ... T5: =COUNTIFS(SQLデータ!$D:$D,"扶養",SQLデータ!$P:$P,1,SQLデータ!$H:$H,届出事由・区分・届出年月日ごと集計!$A5,SQLデータ!$G:$G,届出事由・区分・届出年月日ごと集計!$B5,SQLデータ!$N:$N,1,SQLデータ!$F:$F,"",SQLデータ!$C:$C,">="&届出事由・区分・届出年月日ごと集計!T$1,SQLデータ!$C:$C,"<="&届出事由・区分・届出年月日ごと集計!T$2) -> 0
A6: 増 | B6: 出生 | C6: 本人税のみ | D6: =COUNTIFS(SQLデータ!$D:$D,"扶養",SQLデータ!$H:$H,届出事由・区分・届出年月日ごと集計!$A6,SQLデータ!$G:$G,届出事由・区分・届出年月日ごと集計!$B6,SQLデータ!$O:$O,1) -> 0 | F6: =COUNTIFS(SQLデータ!$D:$D,"扶養",SQLデータ!$P:$P,1,SQLデータ!$H:$H,届出事由・区分・届出年月日ごと集計!$A6,SQLデータ!$G:$G,届出事由・区分・届出年月日ごと集計!$B6,SQLデータ!$O:$O,1,SQLデータ!$F:$F,"",SQLデータ!$C:$C,">="&届出事由・区分・届出年月日ごと集計!F$1,SQLデータ!$C:$C,"<="&届出事由・区分・届出年月日ごと集計!F$2) -> 0 | G6: =COUNTIFS(SQLデータ!$D:$D,"扶養",SQLデータ!$P:$P,1,SQLデータ!$H:$H,届出事由・区分・届出年月日ごと集計!$A6,SQLデータ!$G:$G,届出事由・区分・届出年月日ごと集計!$B6,SQLデータ!$O:$O,1,SQLデータ!$F:$F,"",SQLデータ!$C:$C,">="&届出事由・区分・届出年月日ごと集計!G$1,SQLデータ!$C:$C,"<="&届出事由・区分・届出年月日ごと集計!G$2) -> 0 | H6: =COUNTIFS(SQLデータ!$D:$D,"扶養",SQLデータ!$P:$P,1,SQLデータ!$H:$H,届出事由・区分・届出年月日ごと集計!$A6,SQLデータ!$G:$G,届出事由・区分・届出年月日ごと集計!$B6,SQLデータ!$O:$O,1,SQLデータ!$F:$F,"",SQLデータ!$C:$C,">="&届出事由・区分・届出年月日ごと集計!H$1,SQLデータ!$C:$C,"<="&届出事由・区分・届出年月日ごと集計!H$2) -> 0 | I6: =COUNTIFS(SQLデータ!$D:$D,"扶養",SQLデータ!$P:$P,1,SQLデータ!$H:$H,届出事由・区分・届出年月日ごと集計!$A6,SQLデータ!$G:$G,届出事由・区分・届出年月日ごと集計!$B6,SQLデータ!$O:$O,1,SQLデータ!$F:$F,"",SQLデータ!$C:$C,">="&届出事由・区分・届出年月日ごと集計!I$1,SQLデータ!$C:$C,"<="&届出事由・区分・届出年月日ごと集計!I$2) -> 0 | J6: =COUNTIFS(SQLデータ!$D:$D,"扶養",SQLデータ!$P:$P,1,SQLデータ!$H:$H,届出事由・区分・届出年月日ごと集計!$A6,SQLデータ!$G:$G,届出事由・区分・届出年月日ごと集計!$B6,SQLデータ!$O:$O,1,SQLデータ!$F:$F,"",SQLデータ!$C:$C,">="&届出事由・区分・届出年月日ごと集計!J$1,SQLデータ!$C:$C,"<="&届出事由・区分・届出年月日ごと集計!J$2) -> 0 | K6: =COUNTIFS(SQLデータ!$D:$D,"扶養",SQLデータ!$P:$P,1,SQLデータ!$H:$H,届出事由・区分・届出年月日ごと集計!$A6,SQLデータ!$G:$G,届出事由・区分・届出年月日ごと集計!$B6,SQLデータ!$O:$O,1,SQLデータ!$F:$F,"",SQLデータ!$C:$C,">="&届出事由・区分・届出年月日ごと集計!K$1,SQLデータ!$C:$C,"<="&届出事由・区分・届出年月日ごと集計!K$2) -> 0 | L6: =COUNTIFS(SQLデータ!$D:$D,"扶養",SQLデータ!$P:$P,1,SQLデータ!$H:$H,届出事由・区分・届出年月日ごと集計!$A6,SQLデータ!$G:$G,届出事由・区分・届出年月日ごと集計!$B6,SQLデータ!$O:$O,1,SQLデータ!$F:$F,"",SQLデータ!$C:$C,">="&届出事由・区分・届出年月日ごと集計!L$1,SQLデータ!$C:$C,"<="&届出事由・区分・届出年月日ごと集計!L$2) -> 0 | M6: =COUNTIFS(SQLデータ!$D:$D,"扶養",SQLデータ!$P:$P,1,SQLデータ!$H:$H,届出事由・区分・届出年月日ごと集計!$A6,SQLデータ!$G:$G,届出事由・区分・届出年月日ごと集計!$B6,SQLデータ!$O:$O,1,SQLデータ!$F:$F,"",SQLデータ!$C:$C,">="&届出事由・区分・届出年月日ごと集計!M$1,SQLデータ!$C:$C,"<="&届出事由・区分・届出年月日ごと集計!M$2) -> 0 | ... T6: =COUNTIFS(SQLデータ!$D:$D,"扶養",SQLデータ!$P:$P,1,SQLデータ!$H:$H,届出事由・区分・届出年月日ごと集計!$A6,SQLデータ!$G:$G,届出事由・区分・届出年月日ごと集計!$B6,SQLデータ!$O:$O,1,SQLデータ!$F:$F,"",SQLデータ!$C:$C,">="&届出事由・区分・届出年月日ごと集計!T$1,SQLデータ!$C:$C,"<="&届出事由・区分・届出年月日ごと集計!T$2) -> 0
A7: 増 | B7: 扶養親族の退職 | C7: 共済あり | D7: =COUNTIFS(SQLデータ!$D:$D,"扶養",SQLデータ!$H:$H,届出事由・区分・届出年月日ごと集計!$A7,SQLデータ!$G:$G,届出事由・区分・届出年月日ごと集計!$B7,SQLデータ!$L:$L,1) -> 19 | F7: =COUNTIFS(SQLデータ!$D:$D,"扶養",SQLデータ!$P:$P,1,SQLデータ!$H:$H,届出事由・区分・届出年月日ごと集計!$A7,SQLデータ!$G:$G,届出事由・区分・届出年月日ごと集計!$B7,SQLデータ!$L:$L,1,SQLデータ!$F:$F,"",SQLデータ!$C:$C,">="&届出事由・区分・届出年月日ごと集計!F$1,SQLデータ!$C:$C,"<="&届出事由・区分・届出年月日ごと集計!F$2) -> 2 | G7: =COUNTIFS(SQLデータ!$D:$D,"扶養",SQLデータ!$P:$P,1,SQLデータ!$H:$H,届出事由・区分・届出年月日ごと集計!$A7,SQLデータ!$G:$G,届出事由・区分・届出年月日ごと集計!$B7,SQLデータ!$L:$L,1,SQLデータ!$F:$F,"",SQLデータ!$C:$C,">="&届出事由・区分・届出年月日ごと集計!G$1,SQLデータ!$C:$C,"<="&届出事由・区分・届出年月日ごと集計!G$2) -> 3 | H7: =COUNTIFS(SQLデータ!$D:$D,"扶養",SQLデータ!$P:$P,1,SQLデータ!$H:$H,届出事由・区分・届出年月日ごと集計!$A7,SQLデータ!$G:$G,届出事由・区分・届出年月日ごと集計!$B7,SQLデータ!$L:$L,1,SQLデータ!$F:$F,"",SQLデータ!$C:$C,">="&届出事由・区分・届出年月日ごと集計!H$1,SQLデータ!$C:$C,"<="&届出事由・区分・届出年月日ごと集計!H$2) -> 1 | I7: =COUNTIFS(SQLデータ!$D:$D,"扶養",SQLデータ!$P:$P,1,SQLデータ!$H:$H,届出事由・区分・届出年月日ごと集計!$A7,SQLデータ!$G:$G,届出事由・区分・届出年月日ごと集計!$B7,SQLデータ!$L:$L,1,SQLデータ!$F:$F,"",SQLデータ!$C:$C,">="&届出事由・区分・届出年月日ごと集計!I$1,SQLデータ!$C:$C,"<="&届出事由・区分・届出年月日ごと集計!I$2) -> 0 | J7: =COUNTIFS(SQLデータ!$D:$D,"扶養",SQLデータ!$P:$P,1,SQLデータ!$H:$H,届出事由・区分・届出年月日ごと集計!$A7,SQLデータ!$G:$G,届出事由・区分・届出年月日ごと集計!$B7,SQLデータ!$L:$L,1,SQLデータ!$F:$F,"",SQLデータ!$C:$C,">="&届出事由・区分・届出年月日ごと集計!J$1,SQLデータ!$C:$C,"<="&届出事由・区分・届出年月日ごと集計!J$2) -> 0 | K7: =COUNTIFS(SQLデータ!$D:$D,"扶養",SQLデータ!$P:$P,1,SQLデータ!$H:$H,届出事由・区分・届出年月日ごと集計!$A7,SQLデータ!$G:$G,届出事由・区分・届出年月日ごと集計!$B7,SQLデータ!$L:$L,1,SQLデータ!$F:$F,"",SQLデータ!$C:$C,">="&届出事由・区分・届出年月日ごと集計!K$1,SQLデータ!$C:$C,"<="&届出事由・区分・届出年月日ごと集計!K$2) -> 0 | L7: =COUNTIFS(SQLデータ!$D:$D,"扶養",SQLデータ!$P:$P,1,SQLデータ!$H:$H,届出事由・区分・届出年月日ごと集計!$A7,SQLデータ!$G:$G,届出事由・区分・届出年月日ごと集計!$B7,SQLデータ!$L:$L,1,SQLデータ!$F:$F,"",SQLデータ!$C:$C,">="&届出事由・区分・届出年月日ごと集計!L$1,SQLデータ!$C:$C,"<="&届出事由・区分・届出年月日ごと集計!L$2) -> 0 | M7: =COUNTIFS(SQLデータ!$D:$D,"扶養",SQLデータ!$P:$P,1,SQLデータ!$H:$H,届出事由・区分・届出年月日ごと集計!$A7,SQLデータ!$G:$G,届出事由・区分・届出年月日ごと集計!$B7,SQLデータ!$L:$L,1,SQLデータ!$F:$F,"",SQLデータ!$C:$C,">="&届出事由・区分・届出年月日ごと集計!M$1,SQLデータ!$C:$C,"<="&届出事由・区分・届出年月日ごと集計!M$2) -> 0 | ... T7: =COUNTIFS(SQLデータ!$D:$D,"扶養",SQLデータ!$P:$P,1,SQLデータ!$H:$H,届出事由・区分・届出年月日ごと集計!$A7,SQLデータ!$G:$G,届出事由・区分・届出年月日ごと集計!$B7,SQLデータ!$L:$L,1,SQLデータ!$F:$F,"",SQLデータ!$C:$C,">="&届出事由・区分・届出年月日ごと集計!T$1,SQLデータ!$C:$C,"<="&届出事由・区分・届出年月日ごと集計!T$2) -> 0
A8: 増 | B8: 扶養親族の退職 | C8: 扶養手当あり | D8: =COUNTIFS(SQLデータ!$D:$D,"扶養",SQLデータ!$H:$H,届出事由・区分・届出年月日ごと集計!$A8,SQLデータ!$G:$G,届出事由・区分・届出年月日ごと集計!$B8,SQLデータ!$M:$M,1) -> 0 | F8: =COUNTIFS(SQLデータ!$D:$D,"扶養",SQLデータ!$P:$P,1,SQLデータ!$H:$H,届出事由・区分・届出年月日ごと集計!$A8,SQLデータ!$G:$G,届出事由・区分・届出年月日ごと集計!$B8,SQLデータ!$M:$M,1,SQLデータ!$F:$F,"",SQLデータ!$C:$C,">="&届出事由・区分・届出年月日ごと集計!F$1,SQLデータ!$C:$C,"<="&届出事由・区分・届出年月日ごと集計!F$2) -> 0 | G8: =COUNTIFS(SQLデータ!$D:$D,"扶養",SQLデータ!$P:$P,1,SQLデータ!$H:$H,届出事由・区分・届出年月日ごと集計!$A8,SQLデータ!$G:$G,届出事由・区分・届出年月日ごと集計!$B8,SQLデータ!$M:$M,1,SQLデータ!$F:$F,"",SQLデータ!$C:$C,">="&届出事由・区分・届出年月日ごと集計!G$1,SQLデータ!$C:$C,"<="&届出事由・区分・届出年月日ごと集計!G$2) -> 0 | H8: =COUNTIFS(SQLデータ!$D:$D,"扶養",SQLデータ!$P:$P,1,SQLデータ!$H:$H,届出事由・区分・届出年月日ごと集計!$A8,SQLデータ!$G:$G,届出事由・区分・届出年月日ごと集計!$B8,SQLデータ!$M:$M,1,SQLデータ!$F:$F,"",SQLデータ!$C:$C,">="&届出事由・区分・届出年月日ごと集計!H$1,SQLデータ!$C:$C,"<="&届出事由・区分・届出年月日ごと集計!H$2) -> 0 | I8: =COUNTIFS(SQLデータ!$D:$D,"扶養",SQLデータ!$P:$P,1,SQLデータ!$H:$H,届出事由・区分・届出年月日ごと集計!$A8,SQLデータ!$G:$G,届出事由・区分・届出年月日ごと集計!$B8,SQLデータ!$M:$M,1,SQLデータ!$F:$F,"",SQLデータ!$C:$C,">="&届出事由・区分・届出年月日ごと集計!I$1,SQLデータ!$C:$C,"<="&届出事由・区分・届出年月日ごと集計!I$2) -> 0 | J8: =COUNTIFS(SQLデータ!$D:$D,"扶養",SQLデータ!$P:$P,1,SQLデータ!$H:$H,届出事由・区分・届出年月日ごと集計!$A8,SQLデータ!$G:$G,届出事由・区分・届出年月日ごと集計!$B8,SQLデータ!$M:$M,1,SQLデータ!$F:$F,"",SQLデータ!$C:$C,">="&届出事由・区分・届出年月日ごと集計!J$1,SQLデータ!$C:$C,"<="&届出事由・区分・届出年月日ごと集計!J$2) -> 0 | K8: =COUNTIFS(SQLデータ!$D:$D,"扶養",SQLデータ!$P:$P,1,SQLデータ!$H:$H,届出事由・区分・届出年月日ごと集計!$A8,SQLデータ!$G:$G,届出事由・区分・届出年月日ごと集計!$B8,SQLデータ!$M:$M,1,SQLデータ!$F:$F,"",SQLデータ!$C:$C,">="&届出事由・区分・届出年月日ごと集計!K$1,SQLデータ!$C:$C,"<="&届出事由・区分・届出年月日ごと集計!K$2) -> 0 | L8: =COUNTIFS(SQLデータ!$D:$D,"扶養",SQLデータ!$P:$P,1,SQLデータ!$H:$H,届出事由・区分・届出年月日ごと集計!$A8,SQLデータ!$G:$G,届出事由・区分・届出年月日ごと集計!$B8,SQLデータ!$M:$M,1,SQLデータ!$F:$F,"",SQLデータ!$C:$C,">="&届出事由・区分・届出年月日ごと集計!L$1,SQLデータ!$C:$C,"<="&届出事由・区分・届出年月日ごと集計!L$2) -> 0 | M8: =COUNTIFS(SQLデータ!$D:$D,"扶養",SQLデータ!$P:$P,1,SQLデータ!$H:$H,届出事由・区分・届出年月日ごと集計!$A8,SQLデータ!$G:$G,届出事由・区分・届出年月日ごと集計!$B8,SQLデータ!$M:$M,1,SQLデータ!$F:$F,"",SQLデータ!$C:$C,">="&届出事由・区分・届出年月日ごと集計!M$1,SQLデータ!$C:$C,"<="&届出事由・区分・届出年月日ごと集計!M$2) -> 0 | ... T8: =COUNTIFS(SQLデータ!$D:$D,"扶養",SQLデータ!$P:$P,1,SQLデータ!$H:$H,届出事由・区分・届出年月日ごと集計!$A8,SQLデータ!$G:$G,届出事由・区分・届出年月日ごと集計!$B8,SQLデータ!$M:$M,1,SQLデータ!$F:$F,"",SQLデータ!$C:$C,">="&届出事由・区分・届出年月日ごと集計!T$1,SQLデータ!$C:$C,"<="&届出事由・区分・届出年月日ごと集計!T$2) -> 0
A9: 増 | B9: 扶養親族の退職 | C9: 税控除のみ | D9: =COUNTIFS(SQLデータ!$D:$D,"扶養",SQLデータ!$H:$H,届出事由・区分・届出年月日ごと集計!$A9,SQLデータ!$G:$G,届出事由・区分・届出年月日ごと集計!$B9,SQLデータ!$N:$N,1) -> 0 | F9: =COUNTIFS(SQLデータ!$D:$D,"扶養",SQLデータ!$P:$P,1,SQLデータ!$H:$H,届出事由・区分・届出年月日ごと集計!$A9,SQLデータ!$G:$G,届出事由・区分・届出年月日ごと集計!$B9,SQLデータ!$N:$N,1,SQLデータ!$F:$F,"",SQLデータ!$C:$C,">="&届出事由・区分・届出年月日ごと集計!F$1,SQLデータ!$C:$C,"<="&届出事由・区分・届出年月日ごと集計!F$2) -> 0 | G9: =COUNTIFS(SQLデータ!$D:$D,"扶養",SQLデータ!$P:$P,1,SQLデータ!$H:$H,届出事由・区分・届出年月日ごと集計!$A9,SQLデータ!$G:$G,届出事由・区分・届出年月日ごと集計!$B9,SQLデータ!$N:$N,1,SQLデータ!$F:$F,"",SQLデータ!$C:$C,">="&届出事由・区分・届出年月日ごと集計!G$1,SQLデータ!$C:$C,"<="&届出事由・区分・届出年月日ごと集計!G$2) -> 0 | H9: =COUNTIFS(SQLデータ!$D:$D,"扶養",SQLデータ!$P:$P,1,SQLデータ!$H:$H,届出事由・区分・届出年月日ごと集計!$A9,SQLデータ!$G:$G,届出事由・区分・届出年月日ごと集計!$B9,SQLデータ!$N:$N,1,SQLデータ!$F:$F,"",SQLデータ!$C:$C,">="&届出事由・区分・届出年月日ごと集計!H$1,SQLデータ!$C:$C,"<="&届出事由・区分・届出年月日ごと集計!H$2) -> 0 | I9: =COUNTIFS(SQLデータ!$D:$D,"扶養",SQLデータ!$P:$P,1,SQLデータ!$H:$H,届出事由・区分・届出年月日ごと集計!$A9,SQLデータ!$G:$G,届出事由・区分・届出年月日ごと集計!$B9,SQLデータ!$N:$N,1,SQLデータ!$F:$F,"",SQLデータ!$C:$C,">="&届出事由・区分・届出年月日ごと集計!I$1,SQLデータ!$C:$C,"<="&届出事由・区分・届出年月日ごと集計!I$2) -> 0 | J9: =COUNTIFS(SQLデータ!$D:$D,"扶養",SQLデータ!$P:$P,1,SQLデータ!$H:$H,届出事由・区分・届出年月日ごと集計!$A9,SQLデータ!$G:$G,届出事由・区分・届出年月日ごと集計!$B9,SQLデータ!$N:$N,1,SQLデータ!$F:$F,"",SQLデータ!$C:$C,">="&届出事由・区分・届出年月日ごと集計!J$1,SQLデータ!$C:$C,"<="&届出事由・区分・届出年月日ごと集計!J$2) -> 0 | K9: =COUNTIFS(SQLデータ!$D:$D,"扶養",SQLデータ!$P:$P,1,SQLデータ!$H:$H,届出事由・区分・届出年月日ごと集計!$A9,SQLデータ!$G:$G,届出事由・区分・届出年月日ごと集計!$B9,SQLデータ!$N:$N,1,SQLデータ!$F:$F,"",SQLデータ!$C:$C,">="&届出事由・区分・届出年月日ごと集計!K$1,SQLデータ!$C:$C,"<="&届出事由・区分・届出年月日ごと集計!K$2) -> 0 | L9: =COUNTIFS(SQLデータ!$D:$D,"扶養",SQLデータ!$P:$P,1,SQLデータ!$H:$H,届出事由・区分・届出年月日ごと集計!$A9,SQLデータ!$G:$G,届出事由・区分・届出年月日ごと集計!$B9,SQLデータ!$N:$N,1,SQLデータ!$F:$F,"",SQLデータ!$C:$C,">="&届出事由・区分・届出年月日ごと集計!L$1,SQLデータ!$C:$C,"<="&届出事由・区分・届出年月日ごと集計!L$2) -> 0 | M9: =COUNTIFS(SQLデータ!$D:$D,"扶養",SQLデータ!$P:$P,1,SQLデータ!$H:$H,届出事由・区分・届出年月日ごと集計!$A9,SQLデータ!$G:$G,届出事由・区分・届出年月日ごと集計!$B9,SQLデータ!$N:$N,1,SQLデータ!$F:$F,"",SQLデータ!$C:$C,">="&届出事由・区分・届出年月日ごと集計!M$1,SQLデータ!$C:$C,"<="&届出事由・区分・届出年月日ごと集計!M$2) -> 0 | ... T9: =COUNTIFS(SQLデータ!$D:$D,"扶養",SQLデータ!$P:$P,1,SQLデータ!$H:$H,届出事由・区分・届出年月日ごと集計!$A9,SQLデータ!$G:$G,届出事由・区分・届出年月日ごと集計!$B9,SQLデータ!$N:$N,1,SQLデータ!$F:$F,"",SQLデータ!$C:$C,">="&届出事由・区分・届出年月日ごと集計!T$1,SQLデータ!$C:$C,"<="&届出事由・区分・届出年月日ごと集計!T$2) -> 0
A10: 増 | B10: 扶養親族の退職 | C10: 本人税のみ | D10: =COUNTIFS(SQLデータ!$D:$D,"扶養",SQLデータ!$H:$H,届出事由・区分・届出年月日ごと集計!$A10,SQLデータ!$G:$G,届出事由・区分・届出年月日ごと集計!$B10,SQLデータ!$O:$O,1) -> 0 | F10: =COUNTIFS(SQLデータ!$D:$D,"扶養",SQLデータ!$P:$P,1,SQLデータ!$H:$H,届出事由・区分・届出年月日ごと集計!$A10,SQLデータ!$G:$G,届出事由・区分・届出年月日ごと集計!$B10,SQLデータ!$O:$O,1,SQLデータ!$F:$F,"",SQLデータ!$C:$C,">="&届出事由・区分・届出年月日ごと集計!F$1,SQLデータ!$C:$C,"<="&届出事由・区分・届出年月日ごと集計!F$2) -> 0 | G10: =COUNTIFS(SQLデータ!$D:$D,"扶養",SQLデータ!$P:$P,1,SQLデータ!$H:$H,届出事由・区分・届出年月日ごと集計!$A10,SQLデータ!$G:$G,届出事由・区分・届出年月日ごと集計!$B10,SQLデータ!$O:$O,1,SQLデータ!$F:$F,"",SQLデータ!$C:$C,">="&届出事由・区分・届出年月日ごと集計!G$1,SQLデータ!$C:$C,"<="&届出事由・区分・届出年月日ごと集計!G$2) -> 0 | H10: =COUNTIFS(SQLデータ!$D:$D,"扶養",SQLデータ!$P:$P,1,SQLデータ!$H:$H,届出事由・区分・届出年月日ごと集計!$A10,SQLデータ!$G:$G,届出事由・区分・届出年月日ごと集計!$B10,SQLデータ!$O:$O,1,SQLデータ!$F:$F,"",SQLデータ!$C:$C,">="&届出事由・区分・届出年月日ごと集計!H$1,SQLデータ!$C:$C,"<="&届出事由・区分・届出年月日ごと集計!H$2) -> 0 | I10: =COUNTIFS(SQLデータ!$D:$D,"扶養",SQLデータ!$P:$P,1,SQLデータ!$H:$H,届出事由・区分・届出年月日ごと集計!$A10,SQLデータ!$G:$G,届出事由・区分・届出年月日ごと集計!$B10,SQLデータ!$O:$O,1,SQLデータ!$F:$F,"",SQLデータ!$C:$C,">="&届出事由・区分・届出年月日ごと集計!I$1,SQLデータ!$C:$C,"<="&届出事由・区分・届出年月日ごと集計!I$2) -> 0 | J10: =COUNTIFS(SQLデータ!$D:$D,"扶養",SQLデータ!$P:$P,1,SQLデータ!$H:$H,届出事由・区分・届出年月日ごと集計!$A10,SQLデータ!$G:$G,届出事由・区分・届出年月日ごと集計!$B10,SQLデータ!$O:$O,1,SQLデータ!$F:$F,"",SQLデータ!$C:$C,">="&届出事由・区分・届出年月日ごと集計!J$1,SQLデータ!$C:$C,"<="&届出事由・区分・届出年月日ごと集計!J$2) -> 0 | K10: =COUNTIFS(SQLデータ!$D:$D,"扶養",SQLデータ!$P:$P,1,SQLデータ!$H:$H,届出事由・区分・届出年月日ごと集計!$A10,SQLデータ!$G:$G,届出事由・区分・届出年月日ごと集計!$B10,SQLデータ!$O:$O,1,SQLデータ!$F:$F,"",SQLデータ!$C:$C,">="&届出事由・区分・届出年月日ごと集計!K$1,SQLデータ!$C:$C,"<="&届出事由・区分・届出年月日ごと集計!K$2) -> 0 | L10: =COUNTIFS(SQLデータ!$D:$D,"扶養",SQLデータ!$P:$P,1,SQLデータ!$H:$H,届出事由・区分・届出年月日ごと集計!$A10,SQLデータ!$G:$G,届出事由・区分・届出年月日ごと集計!$B10,SQLデータ!$O:$O,1,SQLデータ!$F:$F,"",SQLデータ!$C:$C,">="&届出事由・区分・届出年月日ごと集計!L$1,SQLデータ!$C:$C,"<="&届出事由・区分・届出年月日ごと集計!L$2) -> 0 | M10: =COUNTIFS(SQLデータ!$D:$D,"扶養",SQLデータ!$P:$P,1,SQLデータ!$H:$H,届出事由・区分・届出年月日ごと集計!$A10,SQLデータ!$G:$G,届出事由・区分・届出年月日ごと集計!$B10,SQLデータ!$O:$O,1,SQLデータ!$F:$F,"",SQLデータ!$C:$C,">="&届出事由・区分・届出年月日ごと集計!M$1,SQLデータ!$C:$C,"<="&届出事由・区分・届出年月日ごと集計!M$2) -> 0 | ... T10: =COUNTIFS(SQLデータ!$D:$D,"扶養",SQLデータ!$P:$P,1,SQLデータ!$H:$H,届出事由・区分・届出年月日ごと集計!$A10,SQLデータ!$G:$G,届出事由・区分・届出年月日ごと集計!$B10,SQLデータ!$O:$O,1,SQLデータ!$F:$F,"",SQLデータ!$C:$C,">="&届出事由・区分・届出年月日ごと集計!T$1,SQLデータ!$C:$C,"<="&届出事由・区分・届出年月日ごと集計!T$2) -> 0
A11: 増 | B11: 本人の結婚 | C11: 共済あり | D11: =COUNTIFS(SQLデータ!$D:$D,"扶養",SQLデータ!$H:$H,届出事由・区分・届出年月日ごと集計!$A11,SQLデータ!$G:$G,届出事由・区分・届出年月日ごと集計!$B11,SQLデータ!$L:$L,1) -> 3 | F11: =COUNTIFS(SQLデータ!$D:$D,"扶養",SQLデータ!$P:$P,1,SQLデータ!$H:$H,届出事由・区分・届出年月日ごと集計!$A11,SQLデータ!$G:$G,届出事由・区分・届出年月日ごと集計!$B11,SQLデータ!$L:$L,1,SQLデータ!$F:$F,"",SQLデータ!$C:$C,">="&届出事由・区分・届出年月日ごと集計!F$1,SQLデータ!$C:$C,"<="&届出事由・区分・届出年月日ごと集計!F$2) -> 0 | G11: =COUNTIFS(SQLデータ!$D:$D,"扶養",SQLデータ!$P:$P,1,SQLデータ!$H:$H,届出事由・区分・届出年月日ごと集計!$A11,SQLデータ!$G:$G,届出事由・区分・届出年月日ごと集計!$B11,SQLデータ!$L:$L,1,SQLデータ!$F:$F,"",SQLデータ!$C:$C,">="&届出事由・区分・届出年月日ごと集計!G$1,SQLデータ!$C:$C,"<="&届出事由・区分・届出年月日ごと集計!G$2) -> 1 | H11: =COUNTIFS(SQLデータ!$D:$D,"扶養",SQLデータ!$P:$P,1,SQLデータ!$H:$H,届出事由・区分・届出年月日ごと集計!$A11,SQLデータ!$G:$G,届出事由・区分・届出年月日ごと集計!$B11,SQLデータ!$L:$L,1,SQLデータ!$F:$F,"",SQLデータ!$C:$C,">="&届出事由・区分・届出年月日ごと集計!H$1,SQLデータ!$C:$C,"<="&届出事由・区分・届出年月日ごと集計!H$2) -> 0 | I11: =COUNTIFS(SQLデータ!$D:$D,"扶養",SQLデータ!$P:$P,1,SQLデータ!$H:$H,届出事由・区分・届出年月日ごと集計!$A11,SQLデータ!$G:$G,届出事由・区分・届出年月日ごと集計!$B11,SQLデータ!$L:$L,1,SQLデータ!$F:$F,"",SQLデータ!$C:$C,">="&届出事由・区分・届出年月日ごと集計!I$1,SQLデータ!$C:$C,"<="&届出事由・区分・届出年月日ごと集計!I$2) -> 0 | J11: =COUNTIFS(SQLデータ!$D:$D,"扶養",SQLデータ!$P:$P,1,SQLデータ!$H:$H,届出事由・区分・届出年月日ごと集計!$A11,SQLデータ!$G:$G,届出事由・区分・届出年月日ごと集計!$B11,SQLデータ!$L:$L,1,SQLデータ!$F:$F,"",SQLデータ!$C:$C,">="&届出事由・区分・届出年月日ごと集計!J$1,SQLデータ!$C:$C,"<="&届出事由・区分・届出年月日ごと集計!J$2) -> 0 | K11: =COUNTIFS(SQLデータ!$D:$D,"扶養",SQLデータ!$P:$P,1,SQLデータ!$H:$H,届出事由・区分・届出年月日ごと集計!$A11,SQLデータ!$G:$G,届出事由・区分・届出年月日ごと集計!$B11,SQLデータ!$L:$L,1,SQLデータ!$F:$F,"",SQLデータ!$C:$C,">="&届出事由・区分・届出年月日ごと集計!K$1,SQLデータ!$C:$C,"<="&届出事由・区分・届出年月日ごと集計!K$2) -> 0 | L11: =COUNTIFS(SQLデータ!$D:$D,"扶養",SQLデータ!$P:$P,1,SQLデータ!$H:$H,届出事由・区分・届出年月日ごと集計!$A11,SQLデータ!$G:$G,届出事由・区分・届出年月日ごと集計!$B11,SQLデータ!$L:$L,1,SQLデータ!$F:$F,"",SQLデータ!$C:$C,">="&届出事由・区分・届出年月日ごと集計!L$1,SQLデータ!$C:$C,"<="&届出事由・区分・届出年月日ごと集計!L$2) -> 0 | M11: =COUNTIFS(SQLデータ!$D:$D,"扶養",SQLデータ!$P:$P,1,SQLデータ!$H:$H,届出事由・区分・届出年月日ごと集計!$A11,SQLデータ!$G:$G,届出事由・区分・届出年月日ごと集計!$B11,SQLデータ!$L:$L,1,SQLデータ!$F:$F,"",SQLデータ!$C:$C,">="&届出事由・区分・届出年月日ごと集計!M$1,SQLデータ!$C:$C,"<="&届出事由・区分・届出年月日ごと集計!M$2) -> 0 | ... T11: =COUNTIFS(SQLデータ!$D:$D,"扶養",SQLデータ!$P:$P,1,SQLデータ!$H:$H,届出事由・区分・届出年月日ごと集計!$A11,SQLデータ!$G:$G,届出事由・区分・届出年月日ごと集計!$B11,SQLデータ!$L:$L,1,SQLデータ!$F:$F,"",SQLデータ!$C:$C,">="&届出事由・区分・届出年月日ごと集計!T$1,SQLデータ!$C:$C,"<="&届出事由・区分・届出年月日ごと集計!T$2) -> 0
A12: 増 | B12: 本人の結婚 | C12: 扶養手当あり | D12: =COUNTIFS(SQLデータ!$D:$D,"扶養",SQLデータ!$H:$H,届出事由・区分・届出年月日ごと集計!$A12,SQLデータ!$G:$G,届出事由・区分・届出年月日ごと集計!$B12,SQLデータ!$M:$M,1) -> 0 | F12: =COUNTIFS(SQLデータ!$D:$D,"扶養",SQLデータ!$P:$P,1,SQLデータ!$H:$H,届出事由・区分・届出年月日ごと集計!$A12,SQLデータ!$G:$G,届出事由・区分・届出年月日ごと集計!$B12,SQLデータ!$M:$M,1,SQLデータ!$F:$F,"",SQLデータ!$C:$C,">="&届出事由・区分・届出年月日ごと集計!F$1,SQLデータ!$C:$C,"<="&届出事由・区分・届出年月日ごと集計!F$2) -> 0 | G12: =COUNTIFS(SQLデータ!$D:$D,"扶養",SQLデータ!$P:$P,1,SQLデータ!$H:$H,届出事由・区分・届出年月日ごと集計!$A12,SQLデータ!$G:$G,届出事由・区分・届出年月日ごと集計!$B12,SQLデータ!$M:$M,1,SQLデータ!$F:$F,"",SQLデータ!$C:$C,">="&届出事由・区分・届出年月日ごと集計!G$1,SQLデータ!$C:$C,"<="&届出事由・区分・届出年月日ごと集計!G$2) -> 0 | H12: =COUNTIFS(SQLデータ!$D:$D,"扶養",SQLデータ!$P:$P,1,SQLデータ!$H:$H,届出事由・区分・届出年月日ごと集計!$A12,SQLデータ!$G:$G,届出事由・区分・届出年月日ごと集計!$B12,SQLデータ!$M:$M,1,SQLデータ!$F:$F,"",SQLデータ!$C:$C,">="&届出事由・区分・届出年月日ごと集計!H$1,SQLデータ!$C:$C,"<="&届出事由・区分・届出年月日ごと集計!H$2) -> 0 | I12: =COUNTIFS(SQLデータ!$D:$D,"扶養",SQLデータ!$P:$P,1,SQLデータ!$H:$H,届出事由・区分・届出年月日ごと集計!$A12,SQLデータ!$G:$G,届出事由・区分・届出年月日ごと集計!$B12,SQLデータ!$M:$M,1,SQLデータ!$F:$F,"",SQLデータ!$C:$C,">="&届出事由・区分・届出年月日ごと集計!I$1,SQLデータ!$C:$C,"<="&届出事由・区分・届出年月日ごと集計!I$2) -> 0 | J12: =COUNTIFS(SQLデータ!$D:$D,"扶養",SQLデータ!$P:$P,1,SQLデータ!$H:$H,届出事由・区分・届出年月日ごと集計!$A12,SQLデータ!$G:$G,届出事由・区分・届出年月日ごと集計!$B12,SQLデータ!$M:$M,1,SQLデータ!$F:$F,"",SQLデータ!$C:$C,">="&届出事由・区分・届出年月日ごと集計!J$1,SQLデータ!$C:$C,"<="&届出事由・区分・届出年月日ごと集計!J$2) -> 0 | K12: =COUNTIFS(SQLデータ!$D:$D,"扶養",SQLデータ!$P:$P,1,SQLデータ!$H:$H,届出事由・区分・届出年月日ごと集計!$A12,SQLデータ!$G:$G,届出事由・区分・届出年月日ごと集計!$B12,SQLデータ!$M:$M,1,SQLデータ!$F:$F,"",SQLデータ!$C:$C,">="&届出事由・区分・届出年月日ごと集計!K$1,SQLデータ!$C:$C,"<="&届出事由・区分・届出年月日ごと集計!K$2) -> 0 | L12: =COUNTIFS(SQLデータ!$D:$D,"扶養",SQLデータ!$P:$P,1,SQLデータ!$H:$H,届出事由・区分・届出年月日ごと集計!$A12,SQLデータ!$G:$G,届出事由・区分・届出年月日ごと集計!$B12,SQLデータ!$M:$M,1,SQLデータ!$F:$F,"",SQLデータ!$C:$C,">="&届出事由・区分・届出年月日ごと集計!L$1,SQLデータ!$C:$C,"<="&届出事由・区分・届出年月日ごと集計!L$2) -> 0 | M12: =COUNTIFS(SQLデータ!$D:$D,"扶養",SQLデータ!$P:$P,1,SQLデータ!$H:$H,届出事由・区分・届出年月日ごと集計!$A12,SQLデータ!$G:$G,届出事由・区分・届出年月日ごと集計!$B12,SQLデータ!$M:$M,1,SQLデータ!$F:$F,"",SQLデータ!$C:$C,">="&届出事由・区分・届出年月日ごと集計!M$1,SQLデータ!$C:$C,"<="&届出事由・区分・届出年月日ごと集計!M$2) -> 0 | ... T12: =COUNTIFS(SQLデータ!$D:$D,"扶養",SQLデータ!$P:$P,1,SQLデータ!$H:$H,届出事由・区分・届出年月日ごと集計!$A12,SQLデータ!$G:$G,届出事由・区分・届出年月日ごと集計!$B12,SQLデータ!$M:$M,1,SQLデータ!$F:$F,"",SQLデータ!$C:$C,">="&届出事由・区分・届出年月日ごと集計!T$1,SQLデータ!$C:$C,"<="&届出事由・区分・届出年月日ごと集計!T$2) -> 0
A13: 増 | B13: 本人の結婚 | C13: 税控除のみ | D13: =COUNTIFS(SQLデータ!$D:$D,"扶養",SQLデータ!$H:$H,届出事由・区分・届出年月日ごと集計!$A13,SQLデータ!$G:$G,届出事由・区分・届出年月日ごと集計!$B13,SQLデータ!$N:$N,1) -> 1 | F13: =COUNTIFS(SQLデータ!$D:$D,"扶養",SQLデータ!$P:$P,1,SQLデータ!$H:$H,届出事由・区分・届出年月日ごと集計!$A13,SQLデータ!$G:$G,届出事由・区分・届出年月日ごと集計!$B13,SQLデータ!$N:$N,1,SQLデータ!$F:$F,"",SQLデータ!$C:$C,">="&届出事由・区分・届出年月日ごと集計!F$1,SQLデータ!$C:$C,"<="&届出事由・区分・届出年月日ごと集計!F$2) -> 0 | G13: =COUNTIFS(SQLデータ!$D:$D,"扶養",SQLデータ!$P:$P,1,SQLデータ!$H:$H,届出事由・区分・届出年月日ごと集計!$A13,SQLデータ!$G:$G,届出事由・区分・届出年月日ごと集計!$B13,SQLデータ!$N:$N,1,SQLデータ!$F:$F,"",SQLデータ!$C:$C,">="&届出事由・区分・届出年月日ごと集計!G$1,SQLデータ!$C:$C,"<="&届出事由・区分・届出年月日ごと集計!G$2) -> 0 | H13: =COUNTIFS(SQLデータ!$D:$D,"扶養",SQLデータ!$P:$P,1,SQLデータ!$H:$H,届出事由・区分・届出年月日ごと集計!$A13,SQLデータ!$G:$G,届出事由・区分・届出年月日ごと集計!$B13,SQLデータ!$N:$N,1,SQLデータ!$F:$F,"",SQLデータ!$C:$C,">="&届出事由・区分・届出年月日ごと集計!H$1,SQLデータ!$C:$C,"<="&届出事由・区分・届出年月日ごと集計!H$2) -> 0 | I13: =COUNTIFS(SQLデータ!$D:$D,"扶養",SQLデータ!$P:$P,1,SQLデータ!$H:$H,届出事由・区分・届出年月日ごと集計!$A13,SQLデータ!$G:$G,届出事由・区分・届出年月日ごと集計!$B13,SQLデータ!$N:$N,1,SQLデータ!$F:$F,"",SQLデータ!$C:$C,">="&届出事由・区分・届出年月日ごと集計!I$1,SQLデータ!$C:$C,"<="&届出事由・区分・届出年月日ごと集計!I$2) -> 0 | J13: =COUNTIFS(SQLデータ!$D:$D,"扶養",SQLデータ!$P:$P,1,SQLデータ!$H:$H,届出事由・区分・届出年月日ごと集計!$A13,SQLデータ!$G:$G,届出事由・区分・届出年月日ごと集計!$B13,SQLデータ!$N:$N,1,SQLデータ!$F:$F,"",SQLデータ!$C:$C,">="&届出事由・区分・届出年月日ごと集計!J$1,SQLデータ!$C:$C,"<="&届出事由・区分・届出年月日ごと集計!J$2) -> 0 | K13: =COUNTIFS(SQLデータ!$D:$D,"扶養",SQLデータ!$P:$P,1,SQLデータ!$H:$H,届出事由・区分・届出年月日ごと集計!$A13,SQLデータ!$G:$G,届出事由・区分・届出年月日ごと集計!$B13,SQLデータ!$N:$N,1,SQLデータ!$F:$F,"",SQLデータ!$C:$C,">="&届出事由・区分・届出年月日ごと集計!K$1,SQLデータ!$C:$C,"<="&届出事由・区分・届出年月日ごと集計!K$2) -> 0 | L13: =COUNTIFS(SQLデータ!$D:$D,"扶養",SQLデータ!$P:$P,1,SQLデータ!$H:$H,届出事由・区分・届出年月日ごと集計!$A13,SQLデータ!$G:$G,届出事由・区分・届出年月日ごと集計!$B13,SQLデータ!$N:$N,1,SQLデータ!$F:$F,"",SQLデータ!$C:$C,">="&届出事由・区分・届出年月日ごと集計!L$1,SQLデータ!$C:$C,"<="&届出事由・区分・届出年月日ごと集計!L$2) -> 0 | M13: =COUNTIFS(SQLデータ!$D:$D,"扶養",SQLデータ!$P:$P,1,SQLデータ!$H:$H,届出事由・区分・届出年月日ごと集計!$A13,SQLデータ!$G:$G,届出事由・区分・届出年月日ごと集計!$B13,SQLデータ!$N:$N,1,SQLデータ!$F:$F,"",SQLデータ!$C:$C,">="&届出事由・区分・届出年月日ごと集計!M$1,SQLデータ!$C:$C,"<="&届出事由・区分・届出年月日ごと集計!M$2) -> 0 | ... T13: =COUNTIFS(SQLデータ!$D:$D,"扶養",SQLデータ!$P:$P,1,SQLデータ!$H:$H,届出事由・区分・届出年月日ごと集計!$A13,SQLデータ!$G:$G,届出事由・区分・届出年月日ごと集計!$B13,SQLデータ!$N:$N,1,SQLデータ!$F:$F,"",SQLデータ!$C:$C,">="&届出事由・区分・届出年月日ごと集計!T$1,SQLデータ!$C:$C,"<="&届出事由・区分・届出年月日ごと集計!T$2) -> 0
A14: 増 | B14: 本人の結婚 | C14: 本人税のみ | D14: =COUNTIFS(SQLデータ!$D:$D,"扶養",SQLデータ!$H:$H,届出事由・区分・届出年月日ごと集計!$A14,SQLデータ!$G:$G,届出事由・区分・届出年月日ごと集計!$B14,SQLデータ!$O:$O,1) -> 40 | F14: =COUNTIFS(SQLデータ!$D:$D,"扶養",SQLデータ!$P:$P,1,SQLデータ!$H:$H,届出事由・区分・届出年月日ごと集計!$A14,SQLデータ!$G:$G,届出事由・区分・届出年月日ごと集計!$B14,SQLデータ!$O:$O,1,SQLデータ!$F:$F,"",SQLデータ!$C:$C,">="&届出事由・区分・届出年月日ごと集計!F$1,SQLデータ!$C:$C,"<="&届出事由・区分・届出年月日ごと集計!F$2) -> 27 | G14: =COUNTIFS(SQLデータ!$D:$D,"扶養",SQLデータ!$P:$P,1,SQLデータ!$H:$H,届出事由・区分・届出年月日ごと集計!$A14,SQLデータ!$G:$G,届出事由・区分・届出年月日ごと集計!$B14,SQLデータ!$O:$O,1,SQLデータ!$F:$F,"",SQLデータ!$C:$C,">="&届出事由・区分・届出年月日ごと集計!G$1,SQLデータ!$C:$C,"<="&届出事由・区分・届出年月日ごと集計!G$2) -> 3 | H14: =COUNTIFS(SQLデータ!$D:$D,"扶養",SQLデータ!$P:$P,1,SQLデータ!$H:$H,届出事由・区分・届出年月日ごと集計!$A14,SQLデータ!$G:$G,届出事由・区分・届出年月日ごと集計!$B14,SQLデータ!$O:$O,1,SQLデータ!$F:$F,"",SQLデータ!$C:$C,">="&届出事由・区分・届出年月日ごと集計!H$1,SQLデータ!$C:$C,"<="&届出事由・区分・届出年月日ごと集計!H$2) -> 5 | I14: =COUNTIFS(SQLデータ!$D:$D,"扶養",SQLデータ!$P:$P,1,SQLデータ!$H:$H,届出事由・区分・届出年月日ごと集計!$A14,SQLデータ!$G:$G,届出事由・区分・届出年月日ごと集計!$B14,SQLデータ!$O:$O,1,SQLデータ!$F:$F,"",SQLデータ!$C:$C,">="&届出事由・区分・届出年月日ごと集計!I$1,SQLデータ!$C:$C,"<="&届出事由・区分・届出年月日ごと集計!I$2) -> 5 | J14: =COUNTIFS(SQLデータ!$D:$D,"扶養",SQLデータ!$P:$P,1,SQLデータ!$H:$H,届出事由・区分・届出年月日ごと集計!$A14,SQLデータ!$G:$G,届出事由・区分・届出年月日ごと集計!$B14,SQLデータ!$O:$O,1,SQLデータ!$F:$F,"",SQLデータ!$C:$C,">="&届出事由・区分・届出年月日ごと集計!J$1,SQLデータ!$C:$C,"<="&届出事由・区分・届出年月日ごと集計!J$2) -> 0 | K14: =COUNTIFS(SQLデータ!$D:$D,"扶養",SQLデータ!$P:$P,1,SQLデータ!$H:$H,届出事由・区分・届出年月日ごと集計!$A14,SQLデータ!$G:$G,届出事由・区分・届出年月日ごと集計!$B14,SQLデータ!$O:$O,1,SQLデータ!$F:$F,"",SQLデータ!$C:$C,">="&届出事由・区分・届出年月日ごと集計!K$1,SQLデータ!$C:$C,"<="&届出事由・区分・届出年月日ごと集計!K$2) -> 0 | L14: =COUNTIFS(SQLデータ!$D:$D,"扶養",SQLデータ!$P:$P,1,SQLデータ!$H:$H,届出事由・区分・届出年月日ごと集計!$A14,SQLデータ!$G:$G,届出事由・区分・届出年月日ごと集計!$B14,SQLデータ!$O:$O,1,SQLデータ!$F:$F,"",SQLデータ!$C:$C,">="&届出事由・区分・届出年月日ごと集計!L$1,SQLデータ!$C:$C,"<="&届出事由・区分・届出年月日ごと集計!L$2) -> 0 | M14: =COUNTIFS(SQLデータ!$D:$D,"扶養",SQLデータ!$P:$P,1,SQLデータ!$H:$H,届出事由・区分・届出年月日ごと集計!$A14,SQLデータ!$G:$G,届出事由・区分・届出年月日ごと集計!$B14,SQLデータ!$O:$O,1,SQLデータ!$F:$F,"",SQLデータ!$C:$C,">="&届出事由・区分・届出年月日ごと集計!M$1,SQLデータ!$C:$C,"<="&届出事由・区分・届出年月日ごと集計!M$2) -> 0 | ... T14: =COUNTIFS(SQLデータ!$D:$D,"扶養",SQLデータ!$P:$P,1,SQLデータ!$H:$H,届出事由・区分・届出年月日ごと集計!$A14,SQLデータ!$G:$G,届出事由・区分・届出年月日ごと集計!$B14,SQLデータ!$O:$O,1,SQLデータ!$F:$F,"",SQLデータ!$C:$C,">="&届出事由・区分・届出年月日ごと集計!T$1,SQLデータ!$C:$C,"<="&届出事由・区分・届出年月日ごと集計!T$2) -> 0
A15: 増 | B15: 雇用保険受給終了 | C15: 共済あり | D15: =COUNTIFS(SQLデータ!$D:$D,"扶養",SQLデータ!$H:$H,届出事由・区分・届出年月日ごと集計!$A15,SQLデータ!$G:$G,届出事由・区分・届出年月日ごと集計!$B15,SQLデータ!$L:$L,1) -> 3 | F15: =COUNTIFS(SQLデータ!$D:$D,"扶養",SQLデータ!$P:$P,1,SQLデータ!$H:$H,届出事由・区分・届出年月日ごと集計!$A15,SQLデータ!$G:$G,届出事由・区分・届出年月日ごと集計!$B15,SQLデータ!$L:$L,1,SQLデータ!$F:$F,"",SQLデータ!$C:$C,">="&届出事由・区分・届出年月日ごと集計!F$1,SQLデータ!$C:$C,"<="&届出事由・区分・届出年月日ごと集計!F$2) -> 1 | G15: =COUNTIFS(SQLデータ!$D:$D,"扶養",SQLデータ!$P:$P,1,SQLデータ!$H:$H,届出事由・区分・届出年月日ごと集計!$A15,SQLデータ!$G:$G,届出事由・区分・届出年月日ごと集計!$B15,SQLデータ!$L:$L,1,SQLデータ!$F:$F,"",SQLデータ!$C:$C,">="&届出事由・区分・届出年月日ごと集計!G$1,SQLデータ!$C:$C,"<="&届出事由・区分・届出年月日ごと集計!G$2) -> 0 | H15: =COUNTIFS(SQLデータ!$D:$D,"扶養",SQLデータ!$P:$P,1,SQLデータ!$H:$H,届出事由・区分・届出年月日ごと集計!$A15,SQLデータ!$G:$G,届出事由・区分・届出年月日ごと集計!$B15,SQLデータ!$L:$L,1,SQLデータ!$F:$F,"",SQLデータ!$C:$C,">="&届出事由・区分・届出年月日ごと集計!H$1,SQLデータ!$C:$C,"<="&届出事由・区分・届出年月日ごと集計!H$2) -> 0 | I15: =COUNTIFS(SQLデータ!$D:$D,"扶養",SQLデータ!$P:$P,1,SQLデータ!$H:$H,届出事由・区分・届出年月日ごと集計!$A15,SQLデータ!$G:$G,届出事由・区分・届出年月日ごと集計!$B15,SQLデータ!$L:$L,1,SQLデータ!$F:$F,"",SQLデータ!$C:$C,">="&届出事由・区分・届出年月日ごと集計!I$1,SQLデータ!$C:$C,"<="&届出事由・区分・届出年月日ごと集計!I$2) -> 0 | J15: =COUNTIFS(SQLデータ!$D:$D,"扶養",SQLデータ!$P:$P,1,SQLデータ!$H:$H,届出事由・区分・届出年月日ごと集計!$A15,SQLデータ!$G:$G,届出事由・区分・届出年月日ごと集計!$B15,SQLデータ!$L:$L,1,SQLデータ!$F:$F,"",SQLデータ!$C:$C,">="&届出事由・区分・届出年月日ごと集計!J$1,SQLデータ!$C:$C,"<="&届出事由・区分・届出年月日ごと集計!J$2) -> 0 | K15: =COUNTIFS(SQLデータ!$D:$D,"扶養",SQLデータ!$P:$P,1,SQLデータ!$H:$H,届出事由・区分・届出年月日ごと集計!$A15,SQLデータ!$G:$G,届出事由・区分・届出年月日ごと集計!$B15,SQLデータ!$L:$L,1,SQLデータ!$F:$F,"",SQLデータ!$C:$C,">="&届出事由・区分・届出年月日ごと集計!K$1,SQLデータ!$C:$C,"<="&届出事由・区分・届出年月日ごと集計!K$2) -> 0 | L15: =COUNTIFS(SQLデータ!$D:$D,"扶養",SQLデータ!$P:$P,1,SQLデータ!$H:$H,届出事由・区分・届出年月日ごと集計!$A15,SQLデータ!$G:$G,届出事由・区分・届出年月日ごと集計!$B15,SQLデータ!$L:$L,1,SQLデータ!$F:$F,"",SQLデータ!$C:$C,">="&届出事由・区分・届出年月日ごと集計!L$1,SQLデータ!$C:$C,"<="&届出事由・区分・届出年月日ごと集計!L$2) -> 0 | M15: =COUNTIFS(SQLデータ!$D:$D,"扶養",SQLデータ!$P:$P,1,SQLデータ!$H:$H,届出事由・区分・届出年月日ごと集計!$A15,SQLデータ!$G:$G,届出事由・区分・届出年月日ごと集計!$B15,SQLデータ!$L:$L,1,SQLデータ!$F:$F,"",SQLデータ!$C:$C,">="&届出事由・区分・届出年月日ごと集計!M$1,SQLデータ!$C:$C,"<="&届出事由・区分・届出年月日ごと集計!M$2) -> 0 | ... T15: =COUNTIFS(SQLデータ!$D:$D,"扶養",SQLデータ!$P:$P,1,SQLデータ!$H:$H,届出事由・区分・届出年月日ごと集計!$A15,SQLデータ!$G:$G,届出事由・区分・届出年月日ごと集計!$B15,SQLデータ!$L:$L,1,SQLデータ!$F:$F,"",SQLデータ!$C:$C,">="&届出事由・区分・届出年月日ごと集計!T$1,SQLデータ!$C:$C,"<="&届出事由・区分・届出年月日ごと集計!T$2) -> 0
A16: 増 | B16: 雇用保険受給終了 | C16: 扶養手当あり | D16: =COUNTIFS(SQLデータ!$D:$D,"扶養",SQLデータ!$H:$H,届出事由・区分・届出年月日ごと集計!$A16,SQLデータ!$G:$G,届出事由・区分・届出年月日ごと集計!$B16,SQLデータ!$M:$M,1) -> 0 | F16: =COUNTIFS(SQLデータ!$D:$D,"扶養",SQLデータ!$P:$P,1,SQLデータ!$H:$H,届出事由・区分・届出年月日ごと集計!$A16,SQLデータ!$G:$G,届出事由・区分・届出年月日ごと集計!$B16,SQLデータ!$M:$M,1,SQLデータ!$F:$F,"",SQLデータ!$C:$C,">="&届出事由・区分・届出年月日ごと集計!F$1,SQLデータ!$C:$C,"<="&届出事由・区分・届出年月日ごと集計!F$2) -> 0 | G16: =COUNTIFS(SQLデータ!$D:$D,"扶養",SQLデータ!$P:$P,1,SQLデータ!$H:$H,届出事由・区分・届出年月日ごと集計!$A16,SQLデータ!$G:$G,届出事由・区分・届出年月日ごと集計!$B16,SQLデータ!$M:$M,1,SQLデータ!$F:$F,"",SQLデータ!$C:$C,">="&届出事由・区分・届出年月日ごと集計!G$1,SQLデータ!$C:$C,"<="&届出事由・区分・届出年月日ごと集計!G$2) -> 0 | H16: =COUNTIFS(SQLデータ!$D:$D,"扶養",SQLデータ!$P:$P,1,SQLデータ!$H:$H,届出事由・区分・届出年月日ごと集計!$A16,SQLデータ!$G:$G,届出事由・区分・届出年月日ごと集計!$B16,SQLデータ!$M:$M,1,SQLデータ!$F:$F,"",SQLデータ!$C:$C,">="&届出事由・区分・届出年月日ごと集計!H$1,SQLデータ!$C:$C,"<="&届出事由・区分・届出年月日ごと集計!H$2) -> 0 | I16: =COUNTIFS(SQLデータ!$D:$D,"扶養",SQLデータ!$P:$P,1,SQLデータ!$H:$H,届出事由・区分・届出年月日ごと集計!$A16,SQLデータ!$G:$G,届出事由・区分・届出年月日ごと集計!$B16,SQLデータ!$M:$M,1,SQLデータ!$F:$F,"",SQLデータ!$C:$C,">="&届出事由・区分・届出年月日ごと集計!I$1,SQLデータ!$C:$C,"<="&届出事由・区分・届出年月日ごと集計!I$2) -> 0 | J16: =COUNTIFS(SQLデータ!$D:$D,"扶養",SQLデータ!$P:$P,1,SQLデータ!$H:$H,届出事由・区分・届出年月日ごと集計!$A16,SQLデータ!$G:$G,届出事由・区分・届出年月日ごと集計!$B16,SQLデータ!$M:$M,1,SQLデータ!$F:$F,"",SQLデータ!$C:$C,">="&届出事由・区分・届出年月日ごと集計!J$1,SQLデータ!$C:$C,"<="&届出事由・区分・届出年月日ごと集計!J$2) -> 0 | K16: =COUNTIFS(SQLデータ!$D:$D,"扶養",SQLデータ!$P:$P,1,SQLデータ!$H:$H,届出事由・区分・届出年月日ごと集計!$A16,SQLデータ!$G:$G,届出事由・区分・届出年月日ごと集計!$B16,SQLデータ!$M:$M,1,SQLデータ!$F:$F,"",SQLデータ!$C:$C,">="&届出事由・区分・届出年月日ごと集計!K$1,SQLデータ!$C:$C,"<="&届出事由・区分・届出年月日ごと集計!K$2) -> 0 | L16: =COUNTIFS(SQLデータ!$D:$D,"扶養",SQLデータ!$P:$P,1,SQLデータ!$H:$H,届出事由・区分・届出年月日ごと集計!$A16,SQLデータ!$G:$G,届出事由・区分・届出年月日ごと集計!$B16,SQLデータ!$M:$M,1,SQLデータ!$F:$F,"",SQLデータ!$C:$C,">="&届出事由・区分・届出年月日ごと集計!L$1,SQLデータ!$C:$C,"<="&届出事由・区分・届出年月日ごと集計!L$2) -> 0 | M16: =COUNTIFS(SQLデータ!$D:$D,"扶養",SQLデータ!$P:$P,1,SQLデータ!$H:$H,届出事由・区分・届出年月日ごと集計!$A16,SQLデータ!$G:$G,届出事由・区分・届出年月日ごと集計!$B16,SQLデータ!$M:$M,1,SQLデータ!$F:$F,"",SQLデータ!$C:$C,">="&届出事由・区分・届出年月日ごと集計!M$1,SQLデータ!$C:$C,"<="&届出事由・区分・届出年月日ごと集計!M$2) -> 0 | ... T16: =COUNTIFS(SQLデータ!$D:$D,"扶養",SQLデータ!$P:$P,1,SQLデータ!$H:$H,届出事由・区分・届出年月日ごと集計!$A16,SQLデータ!$G:$G,届出事由・区分・届出年月日ごと集計!$B16,SQLデータ!$M:$M,1,SQLデータ!$F:$F,"",SQLデータ!$C:$C,">="&届出事由・区分・届出年月日ごと集計!T$1,SQLデータ!$C:$C,"<="&届出事由・区分・届出年月日ごと集計!T$2) -> 0
A17: 増 | B17: 雇用保険受給終了 | C17: 税控除のみ | D17: =COUNTIFS(SQLデータ!$D:$D,"扶養",SQLデータ!$H:$H,届出事由・区分・届出年月日ごと集計!$A17,SQLデータ!$G:$G,届出事由・区分・届出年月日ごと集計!$B17,SQLデータ!$N:$N,1) -> 1 | F17: =COUNTIFS(SQLデータ!$D:$D,"扶養",SQLデータ!$P:$P,1,SQLデータ!$H:$H,届出事由・区分・届出年月日ごと集計!$A17,SQLデータ!$G:$G,届出事由・区分・届出年月日ごと集計!$B17,SQLデータ!$N:$N,1,SQLデータ!$F:$F,"",SQLデータ!$C:$C,">="&届出事由・区分・届出年月日ごと集計!F$1,SQLデータ!$C:$C,"<="&届出事由・区分・届出年月日ごと集計!F$2) -> 0 | G17: =COUNTIFS(SQLデータ!$D:$D,"扶養",SQLデータ!$P:$P,1,SQLデータ!$H:$H,届出事由・区分・届出年月日ごと集計!$A17,SQLデータ!$G:$G,届出事由・区分・届出年月日ごと集計!$B17,SQLデータ!$N:$N,1,SQLデータ!$F:$F,"",SQLデータ!$C:$C,">="&届出事由・区分・届出年月日ごと集計!G$1,SQLデータ!$C:$C,"<="&届出事由・区分・届出年月日ごと集計!G$2) -> 0 | H17: =COUNTIFS(SQLデータ!$D:$D,"扶養",SQLデータ!$P:$P,1,SQLデータ!$H:$H,届出事由・区分・届出年月日ごと集計!$A17,SQLデータ!$G:$G,届出事由・区分・届出年月日ごと集計!$B17,SQLデータ!$N:$N,1,SQLデータ!$F:$F,"",SQLデータ!$C:$C,">="&届出事由・区分・届出年月日ごと集計!H$1,SQLデータ!$C:$C,"<="&届出事由・区分・届出年月日ごと集計!H$2) -> 0 | I17: =COUNTIFS(SQLデータ!$D:$D,"扶養",SQLデータ!$P:$P,1,SQLデータ!$H:$H,届出事由・区分・届出年月日ごと集計!$A17,SQLデータ!$G:$G,届出事由・区分・届出年月日ごと集計!$B17,SQLデータ!$N:$N,1,SQLデータ!$F:$F,"",SQLデータ!$C:$C,">="&届出事由・区分・届出年月日ごと集計!I$1,SQLデータ!$C:$C,"<="&届出事由・区分・届出年月日ごと集計!I$2) -> 1 | J17: =COUNTIFS(SQLデータ!$D:$D,"扶養",SQLデータ!$P:$P,1,SQLデータ!$H:$H,届出事由・区分・届出年月日ごと集計!$A17,SQLデータ!$G:$G,届出事由・区分・届出年月日ごと集計!$B17,SQLデータ!$N:$N,1,SQLデータ!$F:$F,"",SQLデータ!$C:$C,">="&届出事由・区分・届出年月日ごと集計!J$1,SQLデータ!$C:$C,"<="&届出事由・区分・届出年月日ごと集計!J$2) -> 0 | K17: =COUNTIFS(SQLデータ!$D:$D,"扶養",SQLデータ!$P:$P,1,SQLデータ!$H:$H,届出事由・区分・届出年月日ごと集計!$A17,SQLデータ!$G:$G,届出事由・区分・届出年月日ごと集計!$B17,SQLデータ!$N:$N,1,SQLデータ!$F:$F,"",SQLデータ!$C:$C,">="&届出事由・区分・届出年月日ごと集計!K$1,SQLデータ!$C:$C,"<="&届出事由・区分・届出年月日ごと集計!K$2) -> 0 | L17: =COUNTIFS(SQLデータ!$D:$D,"扶養",SQLデータ!$P:$P,1,SQLデータ!$H:$H,届出事由・区分・届出年月日ごと集計!$A17,SQLデータ!$G:$G,届出事由・区分・届出年月日ごと集計!$B17,SQLデータ!$N:$N,1,SQLデータ!$F:$F,"",SQLデータ!$C:$C,">="&届出事由・区分・届出年月日ごと集計!L$1,SQLデータ!$C:$C,"<="&届出事由・区分・届出年月日ごと集計!L$2) -> 0 | M17: =COUNTIFS(SQLデータ!$D:$D,"扶養",SQLデータ!$P:$P,1,SQLデータ!$H:$H,届出事由・区分・届出年月日ごと集計!$A17,SQLデータ!$G:$G,届出事由・区分・届出年月日ごと集計!$B17,SQLデータ!$N:$N,1,SQLデータ!$F:$F,"",SQLデータ!$C:$C,">="&届出事由・区分・届出年月日ごと集計!M$1,SQLデータ!$C:$C,"<="&届出事由・区分・届出年月日ごと集計!M$2) -> 0 | ... T17: =COUNTIFS(SQLデータ!$D:$D,"扶養",SQLデータ!$P:$P,1,SQLデータ!$H:$H,届出事由・区分・届出年月日ごと集計!$A17,SQLデータ!$G:$G,届出事由・区分・届出年月日ごと集計!$B17,SQLデータ!$N:$N,1,SQLデータ!$F:$F,"",SQLデータ!$C:$C,">="&届出事由・区分・届出年月日ごと集計!T$1,SQLデータ!$C:$C,"<="&届出事由・区分・届出年月日ごと集計!T$2) -> 0
A18: 増 | B18: 雇用保険受給終了 | C18: 本人税のみ | D18: =COUNTIFS(SQLデータ!$D:$D,"扶養",SQLデータ!$H:$H,届出事由・区分・届出年月日ごと集計!$A18,SQLデータ!$G:$G,届出事由・区分・届出年月日ごと集計!$B18,SQLデータ!$O:$O,1) -> 0 | F18: =COUNTIFS(SQLデータ!$D:$D,"扶養",SQLデータ!$P:$P,1,SQLデータ!$H:$H,届出事由・区分・届出年月日ごと集計!$A18,SQLデータ!$G:$G,届出事由・区分・届出年月日ごと集計!$B18,SQLデータ!$O:$O,1,SQLデータ!$F:$F,"",SQLデータ!$C:$C,">="&届出事由・区分・届出年月日ごと集計!F$1,SQLデータ!$C:$C,"<="&届出事由・区分・届出年月日ごと集計!F$2) -> 0 | G18: =COUNTIFS(SQLデータ!$D:$D,"扶養",SQLデータ!$P:$P,1,SQLデータ!$H:$H,届出事由・区分・届出年月日ごと集計!$A18,SQLデータ!$G:$G,届出事由・区分・届出年月日ごと集計!$B18,SQLデータ!$O:$O,1,SQLデータ!$F:$F,"",SQLデータ!$C:$C,">="&届出事由・区分・届出年月日ごと集計!G$1,SQLデータ!$C:$C,"<="&届出事由・区分・届出年月日ごと集計!G$2) -> 0 | H18: =COUNTIFS(SQLデータ!$D:$D,"扶養",SQLデータ!$P:$P,1,SQLデータ!$H:$H,届出事由・区分・届出年月日ごと集計!$A18,SQLデータ!$G:$G,届出事由・区分・届出年月日ごと集計!$B18,SQLデータ!$O:$O,1,SQLデータ!$F:$F,"",SQLデータ!$C:$C,">="&届出事由・区分・届出年月日ごと集計!H$1,SQLデータ!$C:$C,"<="&届出事由・区分・届出年月日ごと集計!H$2) -> 0 | I18: =COUNTIFS(SQLデータ!$D:$D,"扶養",SQLデータ!$P:$P,1,SQLデータ!$H:$H,届出事由・区分・届出年月日ごと集計!$A18,SQLデータ!$G:$G,届出事由・区分・届出年月日ごと集計!$B18,SQLデータ!$O:$O,1,SQLデータ!$F:$F,"",SQLデータ!$C:$C,">="&届出事由・区分・届出年月日ごと集計!I$1,SQLデータ!$C:$C,"<="&届出事由・区分・届出年月日ごと集計!I$2) -> 0 | J18: =COUNTIFS(SQLデータ!$D:$D,"扶養",SQLデータ!$P:$P,1,SQLデータ!$H:$H,届出事由・区分・届出年月日ごと集計!$A18,SQLデータ!$G:$G,届出事由・区分・届出年月日ごと集計!$B18,SQLデータ!$O:$O,1,SQLデータ!$F:$F,"",SQLデータ!$C:$C,">="&届出事由・区分・届出年月日ごと集計!J$1,SQLデータ!$C:$C,"<="&届出事由・区分・届出年月日ごと集計!J$2) -> 0 | K18: =COUNTIFS(SQLデータ!$D:$D,"扶養",SQLデータ!$P:$P,1,SQLデータ!$H:$H,届出事由・区分・届出年月日ごと集計!$A18,SQLデータ!$G:$G,届出事由・区分・届出年月日ごと集計!$B18,SQLデータ!$O:$O,1,SQLデータ!$F:$F,"",SQLデータ!$C:$C,">="&届出事由・区分・届出年月日ごと集計!K$1,SQLデータ!$C:$C,"<="&届出事由・区分・届出年月日ごと集計!K$2) -> 0 | L18: =COUNTIFS(SQLデータ!$D:$D,"扶養",SQLデータ!$P:$P,1,SQLデータ!$H:$H,届出事由・区分・届出年月日ごと集計!$A18,SQLデータ!$G:$G,届出事由・区分・届出年月日ごと集計!$B18,SQLデータ!$O:$O,1,SQLデータ!$F:$F,"",SQLデータ!$C:$C,">="&届出事由・区分・届出年月日ごと集計!L$1,SQLデータ!$C:$C,"<="&届出事由・区分・届出年月日ごと集計!L$2) -> 0 | M18: =COUNTIFS(SQLデータ!$D:$D,"扶養",SQLデータ!$P:$P,1,SQLデータ!$H:$H,届出事由・区分・届出年月日ごと集計!$A18,SQLデータ!$G:$G,届出事由・区分・届出年月日ごと集計!$B18,SQLデータ!$O:$O,1,SQLデータ!$F:$F,"",SQLデータ!$C:$C,">="&届出事由・区分・届出年月日ごと集計!M$1,SQLデータ!$C:$C,"<="&届出事由・区分・届出年月日ごと集計!M$2) -> 0 | ... T18: =COUNTIFS(SQLデータ!$D:$D,"扶養",SQLデータ!$P:$P,1,SQLデータ!$H:$H,届出事由・区分・届出年月日ごと集計!$A18,SQLデータ!$G:$G,届出事由・区分・届出年月日ごと集計!$B18,SQLデータ!$O:$O,1,SQLデータ!$F:$F,"",SQLデータ!$C:$C,">="&届出事由・区分・届出年月日ごと集計!T$1,SQLデータ!$C:$C,"<="&届出事由・区分・届出年月日ごと集計!T$2) -> 0
A19: 増 | B19: 育休 | C19: 共済あり | D19: =COUNTIFS(SQLデータ!$D:$D,"扶養",SQLデータ!$H:$H,届出事由・区分・届出年月日ごと集計!$A19,SQLデータ!$G:$G,届出事由・区分・届出年月日ごと集計!$B19,SQLデータ!$L:$L,1) -> 0 | F19: =COUNTIFS(SQLデータ!$D:$D,"扶養",SQLデータ!$P:$P,1,SQLデータ!$H:$H,届出事由・区分・届出年月日ごと集計!$A19,SQLデータ!$G:$G,届出事由・区分・届出年月日ごと集計!$B19,SQLデータ!$L:$L,1,SQLデータ!$F:$F,"",SQLデータ!$C:$C,">="&届出事由・区分・届出年月日ごと集計!F$1,SQLデータ!$C:$C,"<="&届出事由・区分・届出年月日ごと集計!F$2) -> 0 | G19: =COUNTIFS(SQLデータ!$D:$D,"扶養",SQLデータ!$P:$P,1,SQLデータ!$H:$H,届出事由・区分・届出年月日ごと集計!$A19,SQLデータ!$G:$G,届出事由・区分・届出年月日ごと集計!$B19,SQLデータ!$L:$L,1,SQLデータ!$F:$F,"",SQLデータ!$C:$C,">="&届出事由・区分・届出年月日ごと集計!G$1,SQLデータ!$C:$C,"<="&届出事由・区分・届出年月日ごと集計!G$2) -> 0 | H19: =COUNTIFS(SQLデータ!$D:$D,"扶養",SQLデータ!$P:$P,1,SQLデータ!$H:$H,届出事由・区分・届出年月日ごと集計!$A19,SQLデータ!$G:$G,届出事由・区分・届出年月日ごと集計!$B19,SQLデータ!$L:$L,1,SQLデータ!$F:$F,"",SQLデータ!$C:$C,">="&届出事由・区分・届出年月日ごと集計!H$1,SQLデータ!$C:$C,"<="&届出事由・区分・届出年月日ごと集計!H$2) -> 0 | I19: =COUNTIFS(SQLデータ!$D:$D,"扶養",SQLデータ!$P:$P,1,SQLデータ!$H:$H,届出事由・区分・届出年月日ごと集計!$A19,SQLデータ!$G:$G,届出事由・区分・届出年月日ごと集計!$B19,SQLデータ!$L:$L,1,SQLデータ!$F:$F,"",SQLデータ!$C:$C,">="&届出事由・区分・届出年月日ごと集計!I$1,SQLデータ!$C:$C,"<="&届出事由・区分・届出年月日ごと集計!I$2) -> 0 | J19: =COUNTIFS(SQLデータ!$D:$D,"扶養",SQLデータ!$P:$P,1,SQLデータ!$H:$H,届出事由・区分・届出年月日ごと集計!$A19,SQLデータ!$G:$G,届出事由・区分・届出年月日ごと集計!$B19,SQLデータ!$L:$L,1,SQLデータ!$F:$F,"",SQLデータ!$C:$C,">="&届出事由・区分・届出年月日ごと集計!J$1,SQLデータ!$C:$C,"<="&届出事由・区分・届出年月日ごと集計!J$2) -> 0 | K19: =COUNTIFS(SQLデータ!$D:$D,"扶養",SQLデータ!$P:$P,1,SQLデータ!$H:$H,届出事由・区分・届出年月日ごと集計!$A19,SQLデータ!$G:$G,届出事由・区分・届出年月日ごと集計!$B19,SQLデータ!$L:$L,1,SQLデータ!$F:$F,"",SQLデータ!$C:$C,">="&届出事由・区分・届出年月日ごと集計!K$1,SQLデータ!$C:$C,"<="&届出事由・区分・届出年月日ごと集計!K$2) -> 0 | L19: =COUNTIFS(SQLデータ!$D:$D,"扶養",SQLデータ!$P:$P,1,SQLデータ!$H:$H,届出事由・区分・届出年月日ごと集計!$A19,SQLデータ!$G:$G,届出事由・区分・届出年月日ごと集計!$B19,SQLデータ!$L:$L,1,SQLデータ!$F:$F,"",SQLデータ!$C:$C,">="&届出事由・区分・届出年月日ごと集計!L$1,SQLデータ!$C:$C,"<="&届出事由・区分・届出年月日ごと集計!L$2) -> 0 | M19: =COUNTIFS(SQLデータ!$D:$D,"扶養",SQLデータ!$P:$P,1,SQLデータ!$H:$H,届出事由・区分・届出年月日ごと集計!$A19,SQLデータ!$G:$G,届出事由・区分・届出年月日ごと集計!$B19,SQLデータ!$L:$L,1,SQLデータ!$F:$F,"",SQLデータ!$C:$C,">="&届出事由・区分・届出年月日ごと集計!M$1,SQLデータ!$C:$C,"<="&届出事由・区分・届出年月日ごと集計!M$2) -> 0 | ... T19: =COUNTIFS(SQLデータ!$D:$D,"扶養",SQLデータ!$P:$P,1,SQLデータ!$H:$H,届出事由・区分・届出年月日ごと集計!$A19,SQLデータ!$G:$G,届出事由・区分・届出年月日ごと集計!$B19,SQLデータ!$L:$L,1,SQLデータ!$F:$F,"",SQLデータ!$C:$C,">="&届出事由・区分・届出年月日ごと集計!T$1,SQLデータ!$C:$C,"<="&届出事由・区分・届出年月日ごと集計!T$2) -> 0
