Workbook

Sheet 元データ
A1: ApplyReceptionNo | B1: ApplyStaffId | C1: ApplyStaffName | D1: CenterMatterStatusCD | E1: CenterMatterStatusName | F1: HistoryExistCD | G1: HistoryExistName | H1: ReasonGenerateDate | I1: ApplyDate | J1: ApplyReceptionDate | K1: ContactPersonRegistDate | L1: ApprovedRegistDate | M1: ApplyDataOutputDate | N1: CompletedRegistDate | O1: CenterProcessTypeText | P1: hasTenpu | Q1: hasJyumin | R1: hasHassin | S1: hasKakunin | T1: hasKanri | U1: hasSV | V1: hasData | W1: hasSakujyo | X1: hasTokubetsu | Y1: hasTokubetsu1 | Z1: hasTokubetsu2 | AA1: hasTokubetsu3 | AB1: NotificationReasonCD | AC1: NotificationReasonKbn | AD1: NotificationReasonKbnText | AE1: NotificationReasonKbnContent | AF1: AlimonyFlg | AG1: HealthInsuranceFlg | AH1: TaxBiteFlg | AI1: cancelFlgText | AJ1: TemporaryText | AK1: ApplyContent | AL1: ★最下行 | AM1: ★経過日数 | AN1: ★未完了 | AO1: ★共済あり | AP1: ★フラグ文字列
A2: 200860002045 | D2: 31 | E2: 31 ＯＰ確認中 | H2: 39904 | I2: 39898 | J2: 41984 | K2: 41984 | O2: 21 担当者登録 | AB2: 47 | AC2: 0 | AD2: 減 | AE2: 47 扶養親族の就職 | AF2: 減 | AG2: 減 | AH2: 減 | AK2: 対応不要 該当職員無し | AL2: =IF(A2="","",IF(COUNTIF(A2:A$2001,A2)=1,1,0)) | AM2: =IF(I2="","",TODAY()-I2) | AN2: =IF(A2="","",IF(AND(E2<>"33 確認済",E2<>"36 送付中"),1,0)) | AO2: =IF(A2="","",IF(AG2<>"",1,0)) | AP2: =IF(P2<>"","・添待ち","")&IF(Q2<>"","・住民票","")&IF(R2<>"","・発信","")&IF(S2<>"","・確認事項","")&IF(T2<>"","・管","")&IF(U2<>"","・SV","")&IF(V2<>"","・データ送付待ち","")&IF(W2<>"","・削除","")
A3: 200860002058 | D3: 31 | E3: 31 ＯＰ確認中 | H3: 39872 | I3: 39898 | J3: 41984 | K3: 41984 | O3: 21 担当者登録 | AB3: 22 | AC3: 1 | AD3: 増 | AE3: 22 扶養親族の退職 | AG3: 増 | AK3: 対応不要 | AL3: =IF(A3="","",IF(COUNTIF(A3:A$2001,A3)=1,1,0)) | AM3: =IF(I3="","",TODAY()-I3) | AN3: =IF(A3="","",IF(AND(E3<>"33 確認済",E3<>"36 送付中"),1,0)) | AO3: =IF(A3="","",IF(AG3<>"",1,0)) | AP3: =IF(P3<>"","・添待ち","")&IF(Q3<>"","・住民票","")&IF(R3<>"","・発信","")&IF(S3<>"","・確認事項","")&IF(T3<>"","・管","")&IF(U3<>"","・SV","")&IF(V3<>"","・データ送付待ち","")&IF(W3<>"","・削除","")
A4: 200960002795 | D4: 40 | E4: 40 差戻し | F4: 20 | G4: 20 差戻し | H4: 30829 | I4: 40233 | J4: 40234 | K4: 40238 | O4: 40 ＳＶ承認 | AB4: 23 | AC4: 1 | AD4: 増 | AE4: 23 本人の結婚 | AL4: =IF(A4="","",IF(COUNTIF(A4:A$2001,A4)=1,1,0)) | AM4: =IF(I4="","",TODAY()-I4) | AN4: =IF(A4="","",IF(AND(E4<>"33 確認済",E4<>"36 送付中"),1,0)) | AO4: =IF(A4="","",IF(AG4<>"",1,0)) | AP4: =IF(P4<>"","・添待ち","")&IF(Q4<>"","・住民票","")&IF(R4<>"","・発信","")&IF(S4<>"","・確認事項","")&IF(T4<>"","・管","")&IF(U4<>"","・SV","")&IF(V4<>"","・データ送付待ち","")&IF(W4<>"","・削除","")
A5: 200960002795 | D5: 40 | E5: 40 差戻し | F5: 20 | G5: 20 差戻し | H5: 30829 | I5: 40233 | J5: 40234 | K5: 40238 | O5: 40 ＳＶ承認 | AB5: 23 | AC5: 1 | AD5: 増 | AE5: 23 結婚 | AL5: =IF(A5="","",IF(COUNTIF(A5:A$2001,A5)=1,1,0)) | AM5: =IF(I5="","",TODAY()-I5) | AN5: =IF(A5="","",IF(AND(E5<>"33 確認済",E5<>"36 送付中"),1,0)) | AO5: =IF(A5="","",IF(AG5<>"",1,0)) | AP5: =IF(P5<>"","・添待ち","")&IF(Q5<>"","・住民票","")&IF(R5<>"","・発信","")&IF(S5<>"","・確認事項","")&IF(T5<>"","・管","")&IF(U5<>"","・SV","")&IF(V5<>"","・データ送付待ち","")&IF(W5<>"","・削除","")
A6: 200960002929 | D6: 31 | E6: 31 ＯＰ確認中 | H6: 40251 | I6: 40252 | J6: 41984 | K6: 41984 | O6: 21 担当者登録 | AB6: 25 | AC6: 1 | AD6: 増 | AE6: 25 育休 | AL6: =IF(A6="","",IF(COUNTIF(A6:A$2001,A6)=1,1,0)) | AM6: =IF(I6="","",TODAY()-I6) | AN6: =IF(A6="","",IF(AND(E6<>"33 確認済",E6<>"36 送付中"),1,0)) | AO6: =IF(A6="","",IF(AG6<>"",1,0)) | AP6: =IF(P6<>"","・添待ち","")&IF(Q6<>"","・住民票","")&IF(R6<>"","・発信","")&IF(S6<>"","・確認事項","")&IF(T6<>"","・管","")&IF(U6<>"","・SV","")&IF(V6<>"","・データ送付待ち","")&IF(W6<>"","・削除","")
A7: 200960002933 | D7: 31 | E7: 31 ＯＰ確認中 | H7: 40238 | I7: 40253 | J7: 41984 | K7: 41984 | O7: 21 担当者登録 | AB7: 21 | AC7: 1 | AD7: 増 | AE7: 21 出生 | AF7: 増 | AG7: 増 | AH7: 増 | AL7: =IF(A7="","",IF(COUNTIF(A7:A$2001,A7)=1,1,0)) | AM7: =IF(I7="","",TODAY()-I7) | AN7: =IF(A7="","",IF(AND(E7<>"33 確認済",E7<>"36 送付中"),1,0)) | AO7: =IF(A7="","",IF(AG7<>"",1,0)) | AP7: =IF(P7<>"","・添待ち","")&IF(Q7<>"","・住民票","")&IF(R7<>"","・発信","")&IF(S7<>"","・確認事項","")&IF(T7<>"","・管","")&IF(U7<>"","・SV","")&IF(V7<>"","・データ送付待ち","")&IF(W7<>"","・削除","")
A8: 200960002999 | D8: 31 | E8: 31 ＯＰ確認中 | H8: 40238 | I8: 40262 | J8: 40266 | K8: 40266 | O8: 22 担当者変更 | AB8: 26 | AC8: 1 | AD8: 増 | AE8: 26 扶養者の変更 | AF8: 増 | AG8: 増 | AH8: 増 | AL8: =IF(A8="","",IF(COUNTIF(A8:A$2001,A8)=1,1,0)) | AM8: =IF(I8="","",TODAY()-I8) | AN8: =IF(A8="","",IF(AND(E8<>"33 確認済",E8<>"36 送付中"),1,0)) | AO8: =IF(A8="","",IF(AG8<>"",1,0)) | AP8: =IF(P8<>"","・添待ち","")&IF(Q8<>"","・住民票","")&IF(R8<>"","・発信","")&IF(S8<>"","・確認事項","")&IF(T8<>"","・管","")&IF(U8<>"","・SV","")&IF(V8<>"","・データ送付待ち","")&IF(W8<>"","・削除","")
A9: 200960003028 | D9: 31 | E9: 31 ＯＰ確認中 | H9: 40254 | I9: 40266 | J9: 40267 | K9: 40616 | O9: 22 担当者変更 | S9: 確 | AB9: 23 | AC9: 1 | AD9: 増 | AE9: 23 本人の結婚 | AL9: =IF(A9="","",IF(COUNTIF(A9:A$2001,A9)=1,1,0)) | AM9: =IF(I9="","",TODAY()-I9) | AN9: =IF(A9="","",IF(AND(E9<>"33 確認済",E9<>"36 送付中"),1,0)) | AO9: =IF(A9="","",IF(AG9<>"",1,0)) | AP9: =IF(P9<>"","・添待ち","")&IF(Q9<>"","・住民票","")&IF(R9<>"","・発信","")&IF(S9<>"","・確認事項","")&IF(T9<>"","・管","")&IF(U9<>"","・SV","")&IF(V9<>"","・データ送付待ち","")&IF(W9<>"","・削除","")
A10: 200960003028 | D10: 31 | E10: 31 ＯＰ確認中 | H10: 40254 | I10: 40266 | J10: 40267 | K10: 40616 | O10: 22 担当者変更 | S10: 確 | AB10: 23 | AC10: 1 | AD10: 増 | AE10: 23 結婚 | AL10: =IF(A10="","",IF(COUNTIF(A10:A$2001,A10)=1,1,0)) | AM10: =IF(I10="","",TODAY()-I10) | AN10: =IF(A10="","",IF(AND(E10<>"33 確認済",E10<>"36 送付中"),1,0)) | AO10: =IF(A10="","",IF(AG10<>"",1,0)) | AP10: =IF(P10<>"","・添待ち","")&IF(Q10<>"","・住民票","")&IF(R10<>"","・発信","")&IF(S10<>"","・確認事項","")&IF(T10<>"","・管","")&IF(U10<>"","・SV","")&IF(V10<>"","・データ送付待ち","")&IF(W10<>"","・削除","")
A11: 201060000063 | D11: 31 | E11: 31 ＯＰ確認中 | F11: 20 | G11: 20 差戻し | H11: 40268 | I11: 40270 | J11: 41984 | K11: 41984 | O11: 21 担当者登録 | AB11: 50 | AC11: 0 | AD11: 減 | AE11: 50 扶養者の変更 | AF11: 減 | AG11: 減 | AH11: 減 | AL11: =IF(A11="","",IF(COUNTIF(A11:A$2001,A11)=1,1,0)) | AM11: =IF(I11="","",TODAY()-I11) | AN11: =IF(A11="","",IF(AND(E11<>"33 確認済",E11<>"36 送付中"),1,0)) | AO11: =IF(A11="","",IF(AG11<>"",1,0)) | AP11: =IF(P11<>"","・添待ち","")&IF(Q11<>"","・住民票","")&IF(R11<>"","・発信","")&IF(S11<>"","・確認事項","")&IF(T11<>"","・管","")&IF(U11<>"","・SV","")&IF(V11<>"","・データ送付待ち","")&IF(W11<>"","・削除","")
A12: 201060002518 | D12: 40 | E12: 40 差戻し | F12: 20 | G12: 20 差戻し | H12: 40273 | I12: 40574 | J12: 40617 | K12: 40617 | O12: 40 ＳＶ承認 | P12: 添 | AB12: 99 | AC12: 1 | AD12: 増 | AE12: 99 その他 | AF12: 増 | AG12: 増 | AL12: =IF(A12="","",IF(COUNTIF(A12:A$2001,A12)=1,1,0)) | AM12: =IF(I12="","",TODAY()-I12) | AN12: =IF(A12="","",IF(AND(E12<>"33 確認済",E12<>"36 送付中"),1,0)) | AO12: =IF(A12="","",IF(AG12<>"",1,0)) | AP12: =IF(P12<>"","・添待ち","")&IF(Q12<>"","・住民票","")&IF(R12<>"","・発信","")&IF(S12<>"","・確認事項","")&IF(T12<>"","・管","")&IF(U12<>"","・SV","")&IF(V12<>"","・データ送付待ち","")&IF(W12<>"","・削除","")
A13: 201160000813 | D13: 31 | E13: 31 ＯＰ確認中 | F13: 20 | G13: 20 差戻し | H13: 40634 | I13: 40721 | J13: 41984 | K13: 41984 | O13: 21 担当者登録 | AB13: 47 | AC13: 0 | AD13: 減 | AE13: 47 扶養親族の就職 | AG13: 減 | AL13: =IF(A13="","",IF(COUNTIF(A13:A$2001,A13)=1,1,0)) | AM13: =IF(I13="","",TODAY()-I13) | AN13: =IF(A13="","",IF(AND(E13<>"33 確認済",E13<>"36 送付中"),1,0)) | AO13: =IF(A13="","",IF(AG13<>"",1,0)) | AP13: =IF(P13<>"","・添待ち","")&IF(Q13<>"","・住民票","")&IF(R13<>"","・発信","")&IF(S13<>"","・確認事項","")&IF(T13<>"","・管","")&IF(U13<>"","・SV","")&IF(V13<>"","・データ送付待ち","")&IF(W13<>"","・削除","")
A14: 201260002213 | D14: 31 | E14: 31 ＯＰ確認中 | H14: 41259 | I14: 41260 | J14: 41984 | K14: 41984 | O14: 21 担当者登録 | AB14: 22 | AC14: 1 | AD14: 増 | AE14: 22 扶養親族の退職 | AF14: 増 | AG14: 増 | AH14: 増 | AL14: =IF(A14="","",IF(COUNTIF(A14:A$2001,A14)=1,1,0)) | AM14: =IF(I14="","",TODAY()-I14) | AN14: =IF(A14="","",IF(AND(E14<>"33 確認済",E14<>"36 送付中"),1,0)) | AO14: =IF(A14="","",IF(AG14<>"",1,0)) | AP14: =IF(P14<>"","・添待ち","")&IF(Q14<>"","・住民票","")&IF(R14<>"","・発信","")&IF(S14<>"","・確認事項","")&IF(T14<>"","・管","")&IF(U14<>"","・SV","")&IF(V14<>"","・データ送付待ち","")&IF(W14<>"","・削除","")
A15: 201260002232 | D15: 31 | E15: 31 ＯＰ確認中 | H15: 41258 | I15: 41262 | J15: 41984 | K15: 41984 | O15: 21 担当者登録 | AB15: 22 | AC15: 1 | AD15: 増 | AE15: 22 扶養親族の退職 | AF15: 増 | AG15: 増 | AH15: 増 | AL15: =IF(A15="","",IF(COUNTIF(A15:A$2001,A15)=1,1,0)) | AM15: =IF(I15="","",TODAY()-I15) | AN15: =IF(A15="","",IF(AND(E15<>"33 確認済",E15<>"36 送付中"),1,0)) | AO15: =IF(A15="","",IF(AG15<>"",1,0)) | AP15: =IF(P15<>"","・添待ち","")&IF(Q15<>"","・住民票","")&IF(R15<>"","・発信","")&IF(S15<>"","・確認事項","")&IF(T15<>"","・管","")&IF(U15<>"","・SV","")&IF(V15<>"","・データ送付待ち","")&IF(W15<>"","・削除","")
A16: 201260002479 | D16: 31 | E16: 31 ＯＰ確認中 | H16: 41309 | I16: 41309 | J16: 41984 | K16: 41984 | O16: 21 担当者登録 | AB16: 26 | AC16: 1 | AD16: 増 | AE16: 26 扶養者の変更 | AG16: 増 | AL16: =IF(A16="","",IF(COUNTIF(A16:A$2001,A16)=1,1,0)) | AM16: =IF(I16="","",TODAY()-I16) | AN16: =IF(A16="","",IF(AND(E16<>"33 確認済",E16<>"36 送付中"),1,0)) | AO16: =IF(A16="","",IF(AG16<>"",1,0)) | AP16: =IF(P16<>"","・添待ち","")&IF(Q16<>"","・住民票","")&IF(R16<>"","・発信","")&IF(S16<>"","・確認事項","")&IF(T16<>"","・管","")&IF(U16<>"","・SV","")&IF(V16<>"","・データ送付待ち","")&IF(W16<>"","・削除","")
A17: 201360001338 | D17: 40 | E17: 40 差戻し | F17: 20 | G17: 20 差戻し | H17: 41518 | I17: 41554 | J17: 41554 | K17: 41554 | O17: 57 削除待ち登録 | W17: 削 | AB17: 47 | AC17: 0 | AD17: 減 | AE17: 47 扶養親族の就職 | AH17: 減 | AL17: =IF(A17="","",IF(COUNTIF(A17:A$2001,A17)=1,1,0)) | AM17: =IF(I17="","",TODAY()-I17) | AN17: =IF(A17="","",IF(AND(E17<>"33 確認済",E17<>"36 送付中"),1,0)) | AO17: =IF(A17="","",IF(AG17<>"",1,0)) | AP17: =IF(P17<>"","・添待ち","")&IF(Q17<>"","・住民票","")&IF(R17<>"","・発信","")&IF(S17<>"","・確認事項","")&IF(T17<>"","・管","")&IF(U17<>"","・SV","")&IF(V17<>"","・データ送付待ち","")&IF(W17<>"","・削除","")
A18: 201360002263 | D18: 40 | E18: 40 差戻し | F18: 20 | G18: 20 差戻し | H18: 41646 | I18: 41647 | J18: 41648 | K18: 41648 | O18: 57 削除待ち登録 | W18: 削 | AB18: 23 | AC18: 1 | AD18: 増 | AE18: 23 本人の結婚 | AF18: 増 | AG18: 増 | AH18: 増 | AL18: =IF(A18="","",IF(COUNTIF(A18:A$2001,A18)=1,1,0)) | AM18: =IF(I18="","",TODAY()-I18) | AN18: =IF(A18="","",IF(AND(E18<>"33 確認済",E18<>"36 送付中"),1,0)) | AO18: =IF(A18="","",IF(AG18<>"",1,0)) | AP18: =IF(P18<>"","・添待ち","")&IF(Q18<>"","・住民票","")&IF(R18<>"","・発信","")&IF(S18<>"","・確認事項","")&IF(T18<>"","・管","")&IF(U18<>"","・SV","")&IF(V18<>"","・データ送付待ち","")&IF(W18<>"","・削除","")
A19: 201360002263 | D19: 40 | E19: 40 差戻し | F19: 20 | G19: 20 差戻し | H19: 41646 | I19: 41647 | J19: 41648 | K19: 41648 | O19: 57 削除待ち登録 | W19: 削 | AB19: 23 | AC19: 1 | AD19: 増 | AE19: 23 結婚 | AF19: 増 | AG19: 増 | AH19: 増 | AL19: =IF(A19="","",IF(COUNTIF(A19:A$2001,A19)=1,1,0)) | AM19: =IF(I19="","",TODAY()-I19) | AN19: =IF(A19="","",IF(AND(E19<>"33 確認済",E19<>"36 送付中"),1,0)) | AO19: =IF(A19="","",IF(AG19<>"",1,0)) | AP19: =IF(P19<>"","・添待ち","")&IF(Q19<>"","・住民票","")&IF(R19<>"","・発信","")&IF(S19<>"","・確認事項","")&IF(T19<>"","・管","")&IF(U19<>"","・SV","")&IF(V19<>"","・データ送付待ち","")&IF(W19<>"","・削除","")
A20: 201460000430 | D20: 31 | E20: 31 ＯＰ確認中 | H20: 41754 | I20: 41754 | J20: 41985 | K20: 41985 | O20: 21 担当者登録 | AB20: 47 | AC20: 0 | AD20: 減 | AE20: 47 扶養親族の就職 | AF20: 減 | AG20: 減 | AH20: 減 | AL20: =IF(A20="","",IF(COUNTIF(A20:A$2001,A20)=1,1,0)) | AM20: =IF(I20="","",TODAY()-I20) | AN20: =IF(A20="","",IF(AND(E20<>"33 確認済",E20<>"36 送付中"),1,0)) | AO20: =IF(A20="","",IF(AG20<>"",1,0)) | AP20: =IF(P20<>"","・添待ち","")&IF(Q20<>"","・住民票","")&IF(R20<>"","・発信","")&IF(S20<>"","・確認事項","")&IF(T20<>"","・管","")&IF(U20<>"","・SV","")&IF(V20<>"","・データ送付待ち","")&IF(W20<>"","・削除","")
A21: 201560001259 | D21: 31 | E21: 31 ＯＰ確認中 | H21: 42189 | I21: 42230 | J21: 42431 | K21: 42431 | O21: 21 担当者登録 | T21: 管 | AB21: 99 | AC21: 1 | AD21: 増 | AE21: 99 その他 | AF21: 増 | AH21: 増 | AL21: =IF(A21="","",IF(COUNTIF(A21:A$2001,A21)=1,1,0)) | AM21: =IF(I21="","",TODAY()-I21) | AN21: =IF(A21="","",IF(AND(E21<>"33 確認済",E21<>"36 送付中"),1,0)) | AO21: =IF(A21="","",IF(AG21<>"",1,0)) | AP21: =IF(P21<>"","・添待ち","")&IF(Q21<>"","・住民票","")&IF(R21<>"","・発信","")&IF(S21<>"","・確認事項","")&IF(T21<>"","・管","")&IF(U21<>"","・SV","")&IF(V21<>"","・データ送付待ち","")&IF(W21<>"","・削除","")
A22: 201560002704 | D22: 40 | E22: 40 差戻し | F22: 20 | G22: 20 差戻し | H22: 42370 | I22: 42408 | J22: 42408 | K22: 42408 | O22: 57 削除待ち登録 | W22: 削 | AB22: 99 | AC22: 0 | AD22: 減 | AE22: 99 その他 | AH22: 減 | AL22: =IF(A22="","",IF(COUNTIF(A22:A$2001,A22)=1,1,0)) | AM22: =IF(I22="","",TODAY()-I22) | AN22: =IF(A22="","",IF(AND(E22<>"33 確認済",E22<>"36 送付中"),1,0)) | AO22: =IF(A22="","",IF(AG22<>"",1,0)) | AP22: =IF(P22<>"","・添待ち","")&IF(Q22<>"","・住民票","")&IF(R22<>"","・発信","")&IF(S22<>"","・確認事項","")&IF(T22<>"","・管","")&IF(U22<>"","・SV","")&IF(V22<>"","・データ送付待ち","")&IF(W22<>"","・削除","")
A23: 201660002819 | D23: 40 | E23: 40 差戻し | F23: 20 | G23: 20 差戻し | H23: 42566 | I23: 42732 | J23: 42739 | K23: 42739 | O23: 57 削除待ち登録 | W23: 削 | AB23: 9 | AC23: 0 | AD23: 減 | AE23: 09 死亡 | AF23: 減 | AG23: 減 | AH23: 減 | AL23: =IF(A23="","",IF(COUNTIF(A23:A$2001,A23)=1,1,0)) | AM23: =IF(I23="","",TODAY()-I23) | AN23: =IF(A23="","",IF(AND(E23<>"33 確認済",E23<>"36 送付中"),1,0)) | AO23: =IF(A23="","",IF(AG23<>"",1,0)) | AP23: =IF(P23<>"","・添待ち","")&IF(Q23<>"","・住民票","")&IF(R23<>"","・発信","")&IF(S23<>"","・確認事項","")&IF(T23<>"","・管","")&IF(U23<>"","・SV","")&IF(V23<>"","・データ送付待ち","")&IF(W23<>"","・削除","")
A24: 201760002086 | D24: 40 | E24: 40 差戻し | F24: 20 | G24: 20 差戻し | H24: 43031 | I24: 43036 | J24: 43038 | K24: 43041 | O24: 57 削除待ち登録 | W24: 削 | AB24: 27 | AC24: 1 | AD24: 増 | AE24: 27 収入限度額以下 | AH24: 増 | AL24: =IF(A24="","",IF(COUNTIF(A24:A$2001,A24)=1,1,0)) | AM24: =IF(I24="","",TODAY()-I24) | AN24: =IF(A24="","",IF(AND(E24<>"33 確認済",E24<>"36 送付中"),1,0)) | AO24: =IF(A24="","",IF(AG24<>"",1,0)) | AP24: =IF(P24<>"","・添待ち","")&IF(Q24<>"","・住民票","")&IF(R24<>"","・発信","")&IF(S24<>"","・確認事項","")&IF(T24<>"","・管","")&IF(U24<>"","・SV","")&IF(V24<>"","・データ送付待ち","")&IF(W24<>"","・削除","")
A25: 201860001388 | D25: 40 | E25: 40 差戻し | F25: 20 | G25: 20 差戻し | H25: 43321 | I25: 43321 | J25: 43325 | K25: 43325 | O25: 55 添付書類待ち登録 | P25: 添 | U25: Ｓ | AB25: 21 | AC25: 1 | AD25: 増 | AE25: 21 出生 | AG25: 増 | AL25: =IF(A25="","",IF(COUNTIF(A25:A$2001,A25)=1,1,0)) | AM25: =IF(I25="","",TODAY()-I25) | AN25: =IF(A25="","",IF(AND(E25<>"33 確認済",E25<>"36 送付中"),1,0)) | AO25: =IF(A25="","",IF(AG25<>"",1,0)) | AP25: =IF(P25<>"","・添待ち","")&IF(Q25<>"","・住民票","")&IF(R25<>"","・発信","")&IF(S25<>"","・確認事項","")&IF(T25<>"","・管","")&IF(U25<>"","・SV","")&IF(V25<>"","・データ送付待ち","")&IF(W25<>"","・削除","")
A26: 201860001862 | D26: 31 | E26: 31 ＯＰ確認中 | H26: 43341 | I26: 43371 | J26: 43411 | K26: 43411 | O26: 21 担当者登録 | AB26: 9 | AC26: 0 | AD26: 減 | AE26: 09 死亡 | AF26: 減 | AG26: 減 | AH26: 減 | AL26: =IF(A26="","",IF(COUNTIF(A26:A$2001,A26)=1,1,0)) | AM26: =IF(I26="","",TODAY()-I26) | AN26: =IF(A26="","",IF(AND(E26<>"33 確認済",E26<>"36 送付中"),1,0)) | AO26: =IF(A26="","",IF(AG26<>"",1,0)) | AP26: =IF(P26<>"","・添待ち","")&IF(Q26<>"","・住民票","")&IF(R26<>"","・発信","")&IF(S26<>"","・確認事項","")&IF(T26<>"","・管","")&IF(U26<>"","・SV","")&IF(V26<>"","・データ送付待ち","")&IF(W26<>"","・削除","")
A27: 202060000569 | D27: 31 | E27: 31 ＯＰ確認中 | H27: 43937 | I27: 43951 | J27: 44013 | K27: 44013 | O27: 21 担当者登録 | AB27: 22 | AC27: 1 | AD27: 増 | AE27: 22 扶養親族の退職 | AG27: 増 | AL27: =IF(A27="","",IF(COUNTIF(A27:A$2001,A27)=1,1,0)) | AM27: =IF(I27="","",TODAY()-I27) | AN27: =IF(A27="","",IF(AND(E27<>"33 確認済",E27<>"36 送付中"),1,0)) | AO27: =IF(A27="","",IF(AG27<>"",1,0)) | AP27: =IF(P27<>"","・添待ち","")&IF(Q27<>"","・住民票","")&IF(R27<>"","・発信","")&IF(S27<>"","・確認事項","")&IF(T27<>"","・管","")&IF(U27<>"","・SV","")&IF(V27<>"","・データ送付待ち","")&IF(W27<>"","・削除","")
A28: 202060001460 | D28: 40 | E28: 40 差戻し | F28: 20 | G28: 20 差戻し | H28: 43191 | I28: 44139 | J28: 44501 | K28: 44504 | O28: 55 添付書類待ち登録 | P28: 添 | AB28: 27 | AC28: 1 | AD28: 増 | AE28: 27 収入限度額以下 | AF28: 増 | AG28: 増 | AH28: 増 | AL28: =IF(A28="","",IF(COUNTIF(A28:A$2001,A28)=1,1,0)) | AM28: =IF(I28="","",TODAY()-I28) | AN28: =IF(A28="","",IF(AND(E28<>"33 確認済",E28<>"36 送付中"),1,0)) | AO28: =IF(A28="","",IF(AG28<>"",1,0)) | AP28: =IF(P28<>"","・添待ち","")&IF(Q28<>"","・住民票","")&IF(R28<>"","・発信","")&IF(S28<>"","・確認事項","")&IF(T28<>"","・管","")&IF(U28<>"","・SV","")&IF(V28<>"","・データ送付待ち","")&IF(W28<>"","・削除","")
A29: 202060002466 | D29: 20 | E29: 20 確認待ち | F29: 20 | G29: 20 差戻し | H29: 44197 | I29: 44210 | J29: 44243 | K29: 45617 | O29: 99 データメンテナンス | R29: 発 | W29: 削 | AB29: 27 | AC29: 1 | AD29: 増 | AE29: 27 収入限度額以下 | AF29: 増 | AG29: 増 | AL29: =IF(A29="","",IF(COUNTIF(A29:A$2001,A29)=1,1,0)) | AM29: =IF(I29="","",TODAY()-I29) | AN29: =IF(A29="","",IF(AND(E29<>"33 確認済",E29<>"36 送付中"),1,0)) | AO29: =IF(A29="","",IF(AG29<>"",1,0)) | AP29: =IF(P29<>"","・添待ち","")&IF(Q29<>"","・住民票","")&IF(R29<>"","・発信","")&IF(S29<>"","・確認事項","")&IF(T29<>"","・管","")&IF(U29<>"","・SV","")&IF(V29<>"","・データ送付待ち","")&IF(W29<>"","・削除","")
A30: 202060002824 | D30: 40 | E30: 40 差戻し | F30: 20 | G30: 20 差戻し | H30: 43497 | I30: 44232 | J30: 44236 | K30: 44236 | O30: 57 削除待ち登録 | W30: 削 | AB30: 51 | AC30: 0 | AD30: 減 | AE30: 51 収入限度額以上 | AF30: 減 | AG30: 減 | AL30: =IF(A30="","",IF(COUNTIF(A30:A$2001,A30)=1,1,0)) | AM30: =IF(I30="","",TODAY()-I30) | AN30: =IF(A30="","",IF(AND(E30<>"33 確認済",E30<>"36 送付中"),1,0)) | AO30: =IF(A30="","",IF(AG30<>"",1,0)) | AP30: =IF(P30<>"","・添待ち","")&IF(Q30<>"","・住民票","")&IF(R30<>"","・発信","")&IF(S30<>"","・確認事項","")&IF(T30<>"","・管","")&IF(U30<>"","・SV","")&IF(V30<>"","・データ送付待ち","")&IF(W30<>"","・削除","")
A31: 202060003171 | D31: 31 | E31: 31 ＯＰ確認中 | H31: 44280 | I31: 44281 | J31: 44302 | K31: 44302 | O31: 21 担当者登録 | AB31: 50 | AC31: 0 | AD31: 減 | AE31: 50 扶養者の変更 | AF31: 減 | AG31: 減 | AH31: 減 | AL31: =IF(A31="","",IF(COUNTIF(A31:A$2001,A31)=1,1,0)) | AM31: =IF(I31="","",TODAY()-I31) | AN31: =IF(A31="","",IF(AND(E31<>"33 確認済",E31<>"36 送付中"),1,0)) | AO31: =IF(A31="","",IF(AG31<>"",1,0)) | AP31: =IF(P31<>"","・添待ち","")&IF(Q31<>"","・住民票","")&IF(R31<>"","・発信","")&IF(S31<>"","・確認事項","")&IF(T31<>"","・管","")&IF(U31<>"","・SV","")&IF(V31<>"","・データ送付待ち","")&IF(W31<>"","・削除","")
A32: 202360000913 | D32: 31 | E32: 31 ＯＰ確認中 | H32: 45062 | I32: 45096 | J32: 45098 | K32: 45148 | O32: 21 担当者登録 | AB32: 3 | AC32: 0 | AD32: 減 | AE32: 03 離婚 | AL32: =IF(A32="","",IF(COUNTIF(A32:A$2001,A32)=1,1,0)) | AM32: =IF(I32="","",TODAY()-I32) | AN32: =IF(A32="","",IF(AND(E32<>"33 確認済",E32<>"36 送付中"),1,0)) | AO32: =IF(A32="","",IF(AG32<>"",1,0)) | AP32: =IF(P32<>"","・添待ち","")&IF(Q32<>"","・住民票","")&IF(R32<>"","・発信","")&IF(S32<>"","・確認事項","")&IF(T32<>"","・管","")&IF(U32<>"","・SV","")&IF(V32<>"","・データ送付待ち","")&IF(W32<>"","・削除","")
A33: 202360003315 | D33: 31 | E33: 31 ＯＰ確認中 | H33: 45370 | I33: 45370 | J33: 45575 | K33: 45575 | O33: 21 担当者登録 | AB33: 50 | AC33: 0 | AD33: 減 | AE33: 50 扶養者の変更 | AF33: 減 | AG33: 減 | AH33: 減 | AL33: =IF(A33="","",IF(COUNTIF(A33:A$2001,A33)=1,1,0)) | AM33: =IF(I33="","",TODAY()-I33) | AN33: =IF(A33="","",IF(AND(E33<>"33 確認済",E33<>"36 送付中"),1,0)) | AO33: =IF(A33="","",IF(AG33<>"",1,0)) | AP33: =IF(P33<>"","・添待ち","")&IF(Q33<>"","・住民票","")&IF(R33<>"","・発信","")&IF(S33<>"","・確認事項","")&IF(T33<>"","・管","")&IF(U33<>"","・SV","")&IF(V33<>"","・データ送付待ち","")&IF(W33<>"","・削除","")
A34: 202360003320 | D34: 31 | E34: 31 ＯＰ確認中 | H34: 45352 | I34: 45370 | J34: 45373 | K34: 45373 | O34: 22 担当者変更 | AB34: 23 | AC34: 1 | AD34: 増 | AE34: 23 本人の結婚 | AL34: =IF(A34="","",IF(COUNTIF(A34:A$2001,A34)=1,1,0)) | AM34: =IF(I34="","",TODAY()-I34) | AN34: =IF(A34="","",IF(AND(E34<>"33 確認済",E34<>"36 送付中"),1,0)) | AO34: =IF(A34="","",IF(AG34<>"",1,0)) | AP34: =IF(P34<>"","・添待ち","")&IF(Q34<>"","・住民票","")&IF(R34<>"","・発信","")&IF(S34<>"","・確認事項","")&IF(T34<>"","・管","")&IF(U34<>"","・SV","")&IF(V34<>"","・データ送付待ち","")&IF(W34<>"","・削除","")
A35: 202360003320 | D35: 31 | E35: 31 ＯＰ確認中 | H35: 45352 | I35: 45370 | J35: 45373 | K35: 45373 | O35: 22 担当者変更 | AB35: 23 | AC35: 1 | AD35: 増 | AE35: 23 結婚 | AL35: =IF(A35="","",IF(COUNTIF(A35:A$2001,A35)=1,1,0)) | AM35: =IF(I35="","",TODAY()-I35) | AN35: =IF(A35="","",IF(AND(E35<>"33 確認済",E35<>"36 送付中"),1,0)) | AO35: =IF(A35="","",IF(AG35<>"",1,0)) | AP35: =IF(P35<>"","・添待ち","")&IF(Q35<>"","・住民票","")&IF(R35<>"","・発信","")&IF(S35<>"","・確認事項","")&IF(T35<>"","・管","")&IF(U35<>"","・SV","")&IF(V35<>"","・データ送付待ち","")&IF(W35<>"","・削除","")
A36: 202460000110 | D36: 20 | E36: 20 確認待ち | F36: 20 | G36: 20 差戻し | H36: 45383 | I36: 45405 | J36: 45387 | K36: 45617 | O36: 57 削除待ち登録 | W36: 削 | AB36: 22 | AC36: 1 | AD36: 増 | AE36: 22 扶養親族の退職 | AF36: 増 | AG36: 増 | AL36: =IF(A36="","",IF(COUNTIF(A36:A$2001,A36)=1,1,0)) | AM36: =IF(I36="","",TODAY()-I36) | AN36: =IF(A36="","",IF(AND(E36<>"33 確認済",E36<>"36 送付中"),1,0)) | AO36: =IF(A36="","",IF(AG36<>"",1,0)) | AP36: =IF(P36<>"","・添待ち","")&IF(Q36<>"","・住民票","")&IF(R36<>"","・発信","")&IF(S36<>"","・確認事項","")&IF(T36<>"","・管","")&IF(U36<>"","・SV","")&IF(V36<>"","・データ送付待ち","")&IF(W36<>"","・削除","")
A37: 202460000121 | D37: 40 | E37: 40 差戻し | F37: 20 | G37: 20 差戻し | H37: 45383 | I37: 45386 | J37: 45390 | K37: 45390 | O37: 57 削除待ち登録 | W37: 削 | AB37: 47 | AC37: 0 | AD37: 減 | AE37: 47 扶養親族の就職 | AF37: 減 | AG37: 減 | AH37: 減 | AL37: =IF(A37="","",IF(COUNTIF(A37:A$2001,A37)=1,1,0)) | AM37: =IF(I37="","",TODAY()-I37) | AN37: =IF(A37="","",IF(AND(E37<>"33 確認済",E37<>"36 送付中"),1,0)) | AO37: =IF(A37="","",IF(AG37<>"",1,0)) | AP37: =IF(P37<>"","・添待ち","")&IF(Q37<>"","・住民票","")&IF(R37<>"","・発信","")&IF(S37<>"","・確認事項","")&IF(T37<>"","・管","")&IF(U37<>"","・SV","")&IF(V37<>"","・データ送付待ち","")&IF(W37<>"","・削除","")
A38: 202460000142 | D38: 40 | E38: 40 差戻し | F38: 20 | G38: 20 差戻し | H38: 45413 | I38: 45386 | J38: 45750 | K38: 45750 | O38: 57 削除待ち登録 | W38: 削 | AB38: 47 | AC38: 0 | AD38: 減 | AE38: 47 扶養親族の就職 | AG38: 減 | AL38: =IF(A38="","",IF(COUNTIF(A38:A$2001,A38)=1,1,0)) | AM38: =IF(I38="","",TODAY()-I38) | AN38: =IF(A38="","",IF(AND(E38<>"33 確認済",E38<>"36 送付中"),1,0)) | AO38: =IF(A38="","",IF(AG38<>"",1,0)) | AP38: =IF(P38<>"","・添待ち","")&IF(Q38<>"","・住民票","")&IF(R38<>"","・発信","")&IF(S38<>"","・確認事項","")&IF(T38<>"","・管","")&IF(U38<>"","・SV","")&IF(V38<>"","・データ送付待ち","")&IF(W38<>"","・削除","")
A39: 202460000609 | D39: 31 | E39: 31 ＯＰ確認中 | H39: 45296 | I39: 45413 | J39: 45420 | K39: 45425 | O39: 22 担当者変更 | S39: 確 | AB39: 99 | AC39: 1 | AD39: 増 | AE39: 99 その他 | AF39: 増 | AG39: 増 | AH39: 増 | AL39: =IF(A39="","",IF(COUNTIF(A39:A$2001,A39)=1,1,0)) | AM39: =IF(I39="","",TODAY()-I39) | AN39: =IF(A39="","",IF(AND(E39<>"33 確認済",E39<>"36 送付中"),1,0)) | AO39: =IF(A39="","",IF(AG39<>"",1,0)) | AP39: =IF(P39<>"","・添待ち","")&IF(Q39<>"","・住民票","")&IF(R39<>"","・発信","")&IF(S39<>"","・確認事項","")&IF(T39<>"","・管","")&IF(U39<>"","・SV","")&IF(V39<>"","・データ送付待ち","")&IF(W39<>"","・削除","")
A40: 202460002704 | D40: 32 | E40: 32 ＳＶ確認中 | H40: 45641 | I40: 45642 | J40: 45651 | K40: 45651 | O40: 30 登録 | AB40: 98 | AC40: 0 | AD40: 減 | AE40: 98 年金支給に係る変更 | AG40: 減 | AL40: =IF(A40="","",IF(COUNTIF(A40:A$2001,A40)=1,1,0)) | AM40: =IF(I40="","",TODAY()-I40) | AN40: =IF(A40="","",IF(AND(E40<>"33 確認済",E40<>"36 送付中"),1,0)) | AO40: =IF(A40="","",IF(AG40<>"",1,0)) | AP40: =IF(P40<>"","・添待ち","")&IF(Q40<>"","・住民票","")&IF(R40<>"","・発信","")&IF(S40<>"","・確認事項","")&IF(T40<>"","・管","")&IF(U40<>"","・SV","")&IF(V40<>"","・データ送付待ち","")&IF(W40<>"","・削除","")
...

Sheet ダッシュボード
B2: 扶養異動申請 進捗ダッシュボード | N2: =TODAY()
B4: ▼ 使い方
B5: 手順① | C5: 元データシートを開き、既存データを「一括クリア」マクロで削除する
B6: 手順② | C6: アプリから「扶養検索_YYYYMMDD.xlsx」をダウンロードする
B7: 手順③ | C7: ダウンロードしたファイルをこのファイルと同じフォルダに保存する
B8: 手順④ | C8: 「ファイル読込」マクロを実行すると元データシートに自動展開される
B9: 手順⑤ | C9: ダッシュボードシートに戻ると件数・申請番号がすべて自動で集計・更新される
B10: 注意 | C10: ★黄色列（元データシート右端4列）は作業列。削除・上書き不可
B11: ▼ 以下の案件を確認してください
B19: ▼ 未完了案件サマリー
B20: 未完了 総件数 | F20: センター対応中 | J20: 差戻し中
B21: =SUMPRODUCT((元データ!$AL$2:$AL$2001=1)*(元データ!$AN$2:$AN$2001=1)) | F21: =SUMPRODUCT((元データ!$AL$2:$AL$2001=1)*(元データ!$AN$2:$AN$2001=1))-SUMPRODUCT((元データ!$AL$2:$AL$2001=1)*(元データ!$AN$2:$AN$2001=1)*(元データ!$E$2:$E$2001="40 差戻し")) | J21: =SUMPRODUCT((元データ!$AL$2:$AL$2001=1)*(元データ!$AN$2:$AN$2001=1)*(元データ!$E$2:$E$2001="40 差戻し"))
B23: ▼ ステータス別 件数
B24: ステータス | C24: 総件数 | D24: 申請日から7日以内 | E24: 申請日から8〜14日 | F24: 申請日から15〜21日 | G24: 申請日から1か月超 | H24: 申請日から2か月超
B25: 確認待ち | C25: =SUMPRODUCT((元データ!$AL$2:$AL$2001=1)*(元データ!$AN$2:$AN$2001=1)*(元データ!$E$2:$E$2001="20 確認待ち")) | D25: =SUMPRODUCT((元データ!$AL$2:$AL$2001=1)*(元データ!$AN$2:$AN$2001=1)*(元データ!$E$2:$E$2001="20 確認待ち")*(元データ!$AM$2:$AM$2001<=7)) | E25: =SUMPRODUCT((元データ!$AL$2:$AL$2001=1)*(元データ!$AN$2:$AN$2001=1)*(元データ!$E$2:$E$2001="20 確認待ち")*(元データ!$AM$2:$AM$2001>=8)*(元データ!$AM$2:$AM$2001<=14)) | F25: =SUMPRODUCT((元データ!$AL$2:$AL$2001=1)*(元データ!$AN$2:$AN$2001=1)*(元データ!$E$2:$E$2001="20 確認待ち")*(元データ!$AM$2:$AM$2001>=15)*(元データ!$AM$2:$AM$2001<=21)) | G25: =SUMPRODUCT((元データ!$AL$2:$AL$2001=1)*(元データ!$AN$2:$AN$2001=1)*(元データ!$E$2:$E$2001="20 確認待ち")*(元データ!$AM$2:$AM$2001>=22)*(元データ!$AM$2:$AM$2001<=30)) | H25: =SUMPRODUCT((元データ!$AL$2:$AL$2001=1)*(元データ!$AN$2:$AN$2001=1)*(元データ!$E$2:$E$2001="20 確認待ち")*(元データ!$AM$2:$AM$2001>=31))
B26: 申請受付 | C26: =SUMPRODUCT((元データ!$AL$2:$AL$2001=1)*(元データ!$AN$2:$AN$2001=1)*(元データ!$E$2:$E$2001="30 申請受付")) | D26: =SUMPRODUCT((元データ!$AL$2:$AL$2001=1)*(元データ!$AN$2:$AN$2001=1)*(元データ!$E$2:$E$2001="30 申請受付")*(元データ!$AM$2:$AM$2001<=7)) | E26: =SUMPRODUCT((元データ!$AL$2:$AL$2001=1)*(元データ!$AN$2:$AN$2001=1)*(元データ!$E$2:$E$2001="30 申請受付")*(元データ!$AM$2:$AM$2001>=8)*(元データ!$AM$2:$AM$2001<=14)) | F26: =SUMPRODUCT((元データ!$AL$2:$AL$2001=1)*(元データ!$AN$2:$AN$2001=1)*(元データ!$E$2:$E$2001="30 申請受付")*(元データ!$AM$2:$AM$2001>=15)*(元データ!$AM$2:$AM$2001<=21)) | G26: =SUMPRODUCT((元データ!$AL$2:$AL$2001=1)*(元データ!$AN$2:$AN$2001=1)*(元データ!$E$2:$E$2001="30 申請受付")*(元データ!$AM$2:$AM$2001>=22)*(元データ!$AM$2:$AM$2001<=30)) | H26: =SUMPRODUCT((元データ!$AL$2:$AL$2001=1)*(元データ!$AN$2:$AN$2001=1)*(元データ!$E$2:$E$2001="30 申請受付")*(元データ!$AM$2:$AM$2001>=31))
B27: OP確認中 | C27: =SUMPRODUCT((元データ!$AL$2:$AL$2001=1)*(元データ!$AN$2:$AN$2001=1)*(元データ!$E$2:$E$2001="31 ＯＰ確認中")) | D27: =SUMPRODUCT((元データ!$AL$2:$AL$2001=1)*(元データ!$AN$2:$AN$2001=1)*(元データ!$E$2:$E$2001="31 ＯＰ確認中")*(元データ!$AM$2:$AM$2001<=7)) | E27: =SUMPRODUCT((元データ!$AL$2:$AL$2001=1)*(元データ!$AN$2:$AN$2001=1)*(元データ!$E$2:$E$2001="31 ＯＰ確認中")*(元データ!$AM$2:$AM$2001>=8)*(元データ!$AM$2:$AM$2001<=14)) | F27: =SUMPRODUCT((元データ!$AL$2:$AL$2001=1)*(元データ!$AN$2:$AN$2001=1)*(元データ!$E$2:$E$2001="31 ＯＰ確認中")*(元データ!$AM$2:$AM$2001>=15)*(元データ!$AM$2:$AM$2001<=21)) | G27: =SUMPRODUCT((元データ!$AL$2:$AL$2001=1)*(元データ!$AN$2:$AN$2001=1)*(元データ!$E$2:$E$2001="31 ＯＰ確認中")*(元データ!$AM$2:$AM$2001>=22)*(元データ!$AM$2:$AM$2001<=30)) | H27: =SUMPRODUCT((元データ!$AL$2:$AL$2001=1)*(元データ!$AN$2:$AN$2001=1)*(元データ!$E$2:$E$2001="31 ＯＰ確認中")*(元データ!$AM$2:$AM$2001>=31))
B28: SV確認中 | C28: =SUMPRODUCT((元データ!$AL$2:$AL$2001=1)*(元データ!$AN$2:$AN$2001=1)*(元データ!$E$2:$E$2001="32 ＳＶ確認中")) | D28: =SUMPRODUCT((元データ!$AL$2:$AL$2001=1)*(元データ!$AN$2:$AN$2001=1)*(元データ!$E$2:$E$2001="32 ＳＶ確認中")*(元データ!$AM$2:$AM$2001<=7)) | E28: =SUMPRODUCT((元データ!$AL$2:$AL$2001=1)*(元データ!$AN$2:$AN$2001=1)*(元データ!$E$2:$E$2001="32 ＳＶ確認中")*(元データ!$AM$2:$AM$2001>=8)*(元データ!$AM$2:$AM$2001<=14)) | F28: =SUMPRODUCT((元データ!$AL$2:$AL$2001=1)*(元データ!$AN$2:$AN$2001=1)*(元データ!$E$2:$E$2001="32 ＳＶ確認中")*(元データ!$AM$2:$AM$2001>=15)*(元データ!$AM$2:$AM$2001<=21)) | G28: =SUMPRODUCT((元データ!$AL$2:$AL$2001=1)*(元データ!$AN$2:$AN$2001=1)*(元データ!$E$2:$E$2001="32 ＳＶ確認中")*(元データ!$AM$2:$AM$2001>=22)*(元データ!$AM$2:$AM$2001<=30)) | H28: =SUMPRODUCT((元データ!$AL$2:$AL$2001=1)*(元データ!$AN$2:$AN$2001=1)*(元データ!$E$2:$E$2001="32 ＳＶ確認中")*(元データ!$AM$2:$AM$2001>=31))
B29: 差戻し | C29: =SUMPRODUCT((元データ!$AL$2:$AL$2001=1)*(元データ!$AN$2:$AN$2001=1)*(元データ!$E$2:$E$2001="40 差戻し")) | D29: =SUMPRODUCT((元データ!$AL$2:$AL$2001=1)*(元データ!$AN$2:$AN$2001=1)*(元データ!$E$2:$E$2001="40 差戻し")*(元データ!$AM$2:$AM$2001<=7)) | E29: =SUMPRODUCT((元データ!$AL$2:$AL$2001=1)*(元データ!$AN$2:$AN$2001=1)*(元データ!$E$2:$E$2001="40 差戻し")*(元データ!$AM$2:$AM$2001>=8)*(元データ!$AM$2:$AM$2001<=14)) | F29: =SUMPRODUCT((元データ!$AL$2:$AL$2001=1)*(元データ!$AN$2:$AN$2001=1)*(元データ!$E$2:$E$2001="40 差戻し")*(元データ!$AM$2:$AM$2001>=15)*(元データ!$AM$2:$AM$2001<=21)) | G29: =SUMPRODUCT((元データ!$AL$2:$AL$2001=1)*(元データ!$AN$2:$AN$2001=1)*(元データ!$E$2:$E$2001="40 差戻し")*(元データ!$AM$2:$AM$2001>=22)*(元データ!$AM$2:$AM$2001<=30)) | H29: =SUMPRODUCT((元データ!$AL$2:$AL$2001=1)*(元データ!$AN$2:$AN$2001=1)*(元データ!$E$2:$E$2001="40 差戻し")*(元データ!$AM$2:$AM$2001>=31))
B30: 合計 | C30: =SUMPRODUCT((元データ!$AL$2:$AL$2001=1)*(元データ!$AN$2:$AN$2001=1)) | D30: =SUMPRODUCT((元データ!$AL$2:$AL$2001=1)*(元データ!$AN$2:$AN$2001=1)*(元データ!$AM$2:$AM$2001<=7)) | E30: =SUMPRODUCT((元データ!$AL$2:$AL$2001=1)*(元データ!$AN$2:$AN$2001=1)*(元データ!$AM$2:$AM$2001>=8)*(元データ!$AM$2:$AM$2001<=14)) | F30: =SUMPRODUCT((元データ!$AL$2:$AL$2001=1)*(元データ!$AN$2:$AN$2001=1)*(元データ!$AM$2:$AM$2001>=15)*(元データ!$AM$2:$AM$2001<=21)) | G30: =SUMPRODUCT((元データ!$AL$2:$AL$2001=1)*(元データ!$AN$2:$AN$2001=1)*(元データ!$AM$2:$AM$2001>=22)*(元データ!$AM$2:$AM$2001<=30)) | H30: =SUMPRODUCT((元データ!$AL$2:$AL$2001=1)*(元データ!$AN$2:$AN$2001=1)*(元データ!$AM$2:$AM$2001>=31))
B32: ▼ 事由別 件数（共済あり／なし）
B33: 優先順位 | C33: 事由 | D33: 共済 | E33: 総件数 | F33: 申請日から7日以内 | Q33: 申請日から8〜14日 | AB33: 申請日から15〜21日 | AM33: 申請日から1か月超 | AX33: 申請日から2か月超
F34: 件数 | G34: 確認待 件数 | H34: 確認待 申請番号 | I34: 受付 件数 | J34: 受付 申請番号 | K34: OP 件数 | L34: OP 申請番号 | M34: SV 件数 | N34: SV 申請番号 | O34: 差戻 件数 | P34: 差戻 申請番号 | Q34: 件数 | R34: 確認待 件数 | S34: 確認待 申請番号 | T34: 受付 件数 | U34: 受付 申請番号 | V34: OP 件数 | W34: OP 申請番号 | X34: SV 件数 | Y34: SV 申請番号 | Z34: 差戻 件数 | AA34: 差戻 申請番号 | AB34: 件数 | AC34: 確認待 件数 | AD34: 確認待 申請番号 | AE34: 受付 件数 | AF34: 受付 申請番号 | AG34: OP 件数 | AH34: OP 申請番号 | AI34: SV 件数 | AJ34: SV 申請番号 | AK34: 差戻 件数 | AL34: 差戻 申請番号 | AM34: 件数 | AN34: 確認待 件数 | AO34: 確認待 申請番号 | AP34: 受付 件数 | AQ34: 受付 申請番号 | AR34: OP 件数 | AS34: OP 申請番号 | AT34: SV 件数 | AU34: SV 申請番号 | AV34: 差戻 件数 | AW34: 差戻 申請番号 | AX34: 件数 | AY34: 確認待 件数 | AZ34: 確認待 申請番号 | BA34: 受付 件数 | BB34: 受付 申請番号 | BC34: OP 件数 | BD34: OP 申請番号 | BE34: SV 件数 | BF34: SV 申請番号 | BG34: 差戻 件数 | BH34: 差戻 申請番号
C35: 21 出生 | D35: あり | E35: =SUMPRODUCT((元データ!$AL$2:$AL$2001=1)*(元データ!$AN$2:$AN$2001=1)*(元データ!$AE$2:$AE$2001=$C$35)*(元データ!$AO$2:$AO$2001=1)) | F35: =SUMPRODUCT((元データ!$AL$2:$AL$2001=1)*(元データ!$AN$2:$AN$2001=1)*(元データ!$AE$2:$AE$2001=$C$35)*(元データ!$AO$2:$AO$2001=1)*(元データ!$AM$2:$AM$2001<=7)) | G35: =SUMPRODUCT((元データ!$AL$2:$AL$2001=1)*(元データ!$AN$2:$AN$2001=1)*(元データ!$AE$2:$AE$2001=$C$35)*(元データ!$AO$2:$AO$2001=1)*(元データ!$AM$2:$AM$2001<=7)*(元データ!$E$2:$E$2001="20 確認待ち")) | H35: =IFERROR(_xlfn.TEXTJOIN(CHAR(10),TRUE,IF((元データ!$AL$2:$AL$2001=1)*(元データ!$AN$2:$AN$2001=1)*(元データ!$AE$2:$AE$2001=$C$35)*(元データ!$AO$2:$AO$2001=1)*(元データ!$AM$2:$AM$2001<=7)*(元データ!$E$2:$E$2001="20 確認待ち"),元データ!$A$2:$A$2001&IF(元データ!$AP$2:$AP$2001<>"","（"&MID(元データ!$AP$2:$AP$2001,2,100)&")",""),"")),"") | I35: =SUMPRODUCT((元データ!$AL$2:$AL$2001=1)*(元データ!$AN$2:$AN$2001=1)*(元データ!$AE$2:$AE$2001=$C$35)*(元データ!$AO$2:$AO$2001=1)*(元データ!$AM$2:$AM$2001<=7)*(元データ!$E$2:$E$2001="30 申請受付")) | J35: =IFERROR(_xlfn.TEXTJOIN(CHAR(10),TRUE,IF((元データ!$AL$2:$AL$2001=1)*(元データ!$AN$2:$AN$2001=1)*(元データ!$AE$2:$AE$2001=$C$35)*(元データ!$AO$2:$AO$2001=1)*(元データ!$AM$2:$AM$2001<=7)*(元データ!$E$2:$E$2001="30 申請受付"),元データ!$A$2:$A$2001&IF(元データ!$AP$2:$AP$2001<>"","（"&MID(元データ!$AP$2:$AP$2001,2,100)&")",""),"")),"") | K35: =SUMPRODUCT((元データ!$AL$2:$AL$2001=1)*(元データ!$AN$2:$AN$2001=1)*(元データ!$AE$2:$AE$2001=$C$35)*(元データ!$AO$2:$AO$2001=1)*(元データ!$AM$2:$AM$2001<=7)*(元データ!$E$2:$E$2001="31 ＯＰ確認中")) | L35: =IFERROR(_xlfn.TEXTJOIN(CHAR(10),TRUE,IF((元データ!$AL$2:$AL$2001=1)*(元データ!$AN$2:$AN$2001=1)*(元データ!$AE$2:$AE$2001=$C$35)*(元データ!$AO$2:$AO$2001=1)*(元データ!$AM$2:$AM$2001<=7)*(元データ!$E$2:$E$2001="31 ＯＰ確認中"),元データ!$A$2:$A$2001&IF(元データ!$AP$2:$AP$2001<>"","（"&MID(元データ!$AP$2:$AP$2001,2,100)&")",""),"")),"") | M35: =SUMPRODUCT((元データ!$AL$2:$AL$2001=1)*(元データ!$AN$2:$AN$2001=1)*(元データ!$AE$2:$AE$2001=$C$35)*(元データ!$AO$2:$AO$2001=1)*(元データ!$AM$2:$AM$2001<=7)*(元データ!$E$2:$E$2001="32 ＳＶ確認中")) | N35: =IFERROR(_xlfn.TEXTJOIN(CHAR(10),TRUE,IF((元データ!$AL$2:$AL$2001=1)*(元データ!$AN$2:$AN$2001=1)*(元データ!$AE$2:$AE$2001=$C$35)*(元データ!$AO$2:$AO$2001=1)*(元データ!$AM$2:$AM$2001<=7)*(元データ!$E$2:$E$2001="32 ＳＶ確認中"),元データ!$A$2:$A$2001&IF(元データ!$AP$2:$AP$2001<>"","（"&MID(元データ!$AP$2:$AP$2001,2,100)&")",""),"")),"") | O35: =SUMPRODUCT((元データ!$AL$2:$AL$2001=1)*(元データ!$AN$2:$AN$2001=1)*(元データ!$AE$2:$AE$2001=$C$35)*(元データ!$AO$2:$AO$2001=1)*(元データ!$AM$2:$AM$2001<=7)*(元データ!$E$2:$E$2001="40 差戻し")) | P35: =IFERROR(_xlfn.TEXTJOIN(CHAR(10),TRUE,IF((元データ!$AL$2:$AL$2001=1)*(元データ!$AN$2:$AN$2001=1)*(元データ!$AE$2:$AE$2001=$C$35)*(元データ!$AO$2:$AO$2001=1)*(元データ!$AM$2:$AM$2001<=7)*(元データ!$E$2:$E$2001="40 差戻し"),元データ!$A$2:$A$2001&IF(元データ!$AP$2:$AP$2001<>"","（"&MID(元データ!$AP$2:$AP$2001,2,100)&")",""),"")),"") | Q35: =SUMPRODUCT((元データ!$AL$2:$AL$2001=1)*(元データ!$AN$2:$AN$2001=1)*(元データ!$AE$2:$AE$2001=$C$35)*(元データ!$AO$2:$AO$2001=1)*(元データ!$AM$2:$AM$2001>=8)*(元データ!$AM$2:$AM$2001<=14)) | R35: =SUMPRODUCT((元データ!$AL$2:$AL$2001=1)*(元データ!$AN$2:$AN$2001=1)*(元データ!$AE$2:$AE$2001=$C$35)*(元データ!$AO$2:$AO$2001=1)*(元データ!$AM$2:$AM$2001>=8)*(元データ!$AM$2:$AM$2001<=14)*(元データ!$E$2:$E$2001="20 確認待ち")) | S35: =IFERROR(_xlfn.TEXTJOIN(CHAR(10),TRUE,IF((元データ!$AL$2:$AL$2001=1)*(元データ!$AN$2:$AN$2001=1)*(元データ!$AE$2:$AE$2001=$C$35)*(元データ!$AO$2:$AO$2001=1)*(元データ!$AM$2:$AM$2001>=8)*(元データ!$AM$2:$AM$2001<=14)*(元データ!$E$2:$E$2001="20 確認待ち"),元データ!$A$2:$A$2001&IF(元データ!$AP$2:$AP$2001<>"","（"&MID(元データ!$AP$2:$AP$2001,2,100)&")",""),"")),"") | T35: =SUMPRODUCT((元データ!$AL$2:$AL$2001=1)*(元データ!$AN$2:$AN$2001=1)*(元データ!$AE$2:$AE$2001=$C$35)*(元データ!$AO$2:$AO$2001=1)*(元データ!$AM$2:$AM$2001>=8)*(元データ!$AM$2:$AM$2001<=14)*(元データ!$E$2:$E$2001="30 申請受付")) | U35: =IFERROR(_xlfn.TEXTJOIN(CHAR(10),TRUE,IF((元データ!$AL$2:$AL$2001=1)*(元データ!$AN$2:$AN$2001=1)*(元データ!$AE$2:$AE$2001=$C$35)*(元データ!$AO$2:$AO$2001=1)*(元データ!$AM$2:$AM$2001>=8)*(元データ!$AM$2:$AM$2001<=14)*(元データ!$E$2:$E$2001="30 申請受付"),元データ!$A$2:$A$2001&IF(元データ!$AP$2:$AP$2001<>"","（"&MID(元データ!$AP$2:$AP$2001,2,100)&")",""),"")),"") | V35: =SUMPRODUCT((元データ!$AL$2:$AL$2001=1)*(元データ!$AN$2:$AN$2001=1)*(元データ!$AE$2:$AE$2001=$C$35)*(元データ!$AO$2:$AO$2001=1)*(元データ!$AM$2:$AM$2001>=8)*(元データ!$AM$2:$AM$2001<=14)*(元データ!$E$2:$E$2001="31 ＯＰ確認中")) | W35: =IFERROR(_xlfn.TEXTJOIN(CHAR(10),TRUE,IF((元データ!$AL$2:$AL$2001=1)*(元データ!$AN$2:$AN$2001=1)*(元データ!$AE$2:$AE$2001=$C$35)*(元データ!$AO$2:$AO$2001=1)*(元データ!$AM$2:$AM$2001>=8)*(元データ!$AM$2:$AM$2001<=14)*(元データ!$E$2:$E$2001="31 ＯＰ確認中"),元データ!$A$2:$A$2001&IF(元データ!$AP$2:$AP$2001<>"","（"&MID(元データ!$AP$2:$AP$2001,2,100)&")",""),"")),"") | X35: =SUMPRODUCT((元データ!$AL$2:$AL$2001=1)*(元データ!$AN$2:$AN$2001=1)*(元データ!$AE$2:$AE$2001=$C$35)*(元データ!$AO$2:$AO$2001=1)*(元データ!$AM$2:$AM$2001>=8)*(元データ!$AM$2:$AM$2001<=14)*(元データ!$E$2:$E$2001="32 ＳＶ確認中")) | Y35: =IFERROR(_xlfn.TEXTJOIN(CHAR(10),TRUE,IF((元データ!$AL$2:$AL$2001=1)*(元データ!$AN$2:$AN$2001=1)*(元データ!$AE$2:$AE$2001=$C$35)*(元データ!$AO$2:$AO$2001=1)*(元データ!$AM$2:$AM$2001>=8)*(元データ!$AM$2:$AM$2001<=14)*(元データ!$E$2:$E$2001="32 ＳＶ確認中"),元データ!$A$2:$A$2001&IF(元データ!$AP$2:$AP$2001<>"","（"&MID(元データ!$AP$2:$AP$2001,2,100)&")",""),"")),"") | Z35: =SUMPRODUCT((元データ!$AL$2:$AL$2001=1)*(元データ!$AN$2:$AN$2001=1)*(元データ!$AE$2:$AE$2001=$C$35)*(元データ!$AO$2:$AO$2001=1)*(元データ!$AM$2:$AM$2001>=8)*(元データ!$AM$2:$AM$2001<=14)*(元データ!$E$2:$E$2001="40 差戻し")) | AA35: =IFERROR(_xlfn.TEXTJOIN(CHAR(10),TRUE,IF((元データ!$AL$2:$AL$2001=1)*(元データ!$AN$2:$AN$2001=1)*(元データ!$AE$2:$AE$2001=$C$35)*(元データ!$AO$2:$AO$2001=1)*(元データ!$AM$2:$AM$2001>=8)*(元データ!$AM$2:$AM$2001<=14)*(元データ!$E$2:$E$2001="40 差戻し"),元データ!$A$2:$A$2001&IF(元データ!$AP$2:$AP$2001<>"","（"&MID(元データ!$AP$2:$AP$2001,2,100)&")",""),"")),"") | AB35: =SUMPRODUCT((元データ!$AL$2:$AL$2001=1)*(元データ!$AN$2:$AN$2001=1)*(元データ!$AE$2:$AE$2001=$C$35)*(元データ!$AO$2:$AO$2001=1)*(元データ!$AM$2:$AM$2001>=15)*(元データ!$AM$2:$AM$2001<=21)) | AC35: =SUMPRODUCT((元データ!$AL$2:$AL$2001=1)*(元データ!$AN$2:$AN$2001=1)*(元データ!$AE$2:$AE$2001=$C$35)*(元データ!$AO$2:$AO$2001=1)*(元データ!$AM$2:$AM$2001>=15)*(元データ!$AM$2:$AM$2001<=21)*(元データ!$E$2:$E$2001="20 確認待ち")) | AD35: =IFERROR(_xlfn.TEXTJOIN(CHAR(10),TRUE,IF((元データ!$AL$2:$AL$2001=1)*(元データ!$AN$2:$AN$2001=1)*(元データ!$AE$2:$AE$2001=$C$35)*(元データ!$AO$2:$AO$2001=1)*(元データ!$AM$2:$AM$2001>=15)*(元データ!$AM$2:$AM$2001<=21)*(元データ!$E$2:$E$2001="20 確認待ち"),元データ!$A$2:$A$2001&IF(元データ!$AP$2:$AP$2001<>"","（"&MID(元データ!$AP$2:$AP$2001,2,100)&")",""),"")),"") | AE35: =SUMPRODUCT((元データ!$AL$2:$AL$2001=1)*(元データ!$AN$2:$AN$2001=1)*(元データ!$AE$2:$AE$2001=$C$35)*(元データ!$AO$2:$AO$2001=1)*(元データ!$AM$2:$AM$2001>=15)*(元データ!$AM$2:$AM$2001<=21)*(元データ!$E$2:$E$2001="30 申請受付")) | AF35: =IFERROR(_xlfn.TEXTJOIN(CHAR(10),TRUE,IF((元データ!$AL$2:$AL$2001=1)*(元データ!$AN$2:$AN$2001=1)*(元データ!$AE$2:$AE$2001=$C$35)*(元データ!$AO$2:$AO$2001=1)*(元データ!$AM$2:$AM$2001>=15)*(元データ!$AM$2:$AM$2001<=21)*(元データ!$E$2:$E$2001="30 申請受付"),元データ!$A$2:$A$2001&IF(元データ!$AP$2:$AP$2001<>"","（"&MID(元データ!$AP$2:$AP$2001,2,100)&")",""),"")),"") | AG35: =SUMPRODUCT((元データ!$AL$2:$AL$2001=1)*(元データ!$AN$2:$AN$2001=1)*(元データ!$AE$2:$AE$2001=$C$35)*(元データ!$AO$2:$AO$2001=1)*(元データ!$AM$2:$AM$2001>=15)*(元データ!$AM$2:$AM$2001<=21)*(元データ!$E$2:$E$2001="31 ＯＰ確認中")) | AH35: =IFERROR(_xlfn.TEXTJOIN(CHAR(10),TRUE,IF((元データ!$AL$2:$AL$2001=1)*(元データ!$AN$2:$AN$2001=1)*(元データ!$AE$2:$AE$2001=$C$35)*(元データ!$AO$2:$AO$2001=1)*(元データ!$AM$2:$AM$2001>=15)*(元データ!$AM$2:$AM$2001<=21)*(元データ!$E$2:$E$2001="31 ＯＰ確認中"),元データ!$A$2:$A$2001&IF(元データ!$AP$2:$AP$2001<>"","（"&MID(元データ!$AP$2:$AP$2001,2,100)&")",""),"")),"") | AI35: =SUMPRODUCT((元データ!$AL$2:$AL$2001=1)*(元データ!$AN$2:$AN$2001=1)*(元データ!$AE$2:$AE$2001=$C$35)*(元データ!$AO$2:$AO$2001=1)*(元データ!$AM$2:$AM$2001>=15)*(元データ!$AM$2:$AM$2001<=21)*(元データ!$E$2:$E$2001="32 ＳＶ確認中")) | AJ35: =IFERROR(_xlfn.TEXTJOIN(CHAR(10),TRUE,IF((元データ!$AL$2:$AL$2001=1)*(元データ!$AN$2:$AN$2001=1)*(元データ!$AE$2:$AE$2001=$C$35)*(元データ!$AO$2:$AO$2001=1)*(元データ!$AM$2:$AM$2001>=15)*(元データ!$AM$2:$AM$2001<=21)*(元データ!$E$2:$E$2001="32 ＳＶ確認中"),元データ!$A$2:$A$2001&IF(元データ!$AP$2:$AP$2001<>"","（"&MID(元データ!$AP$2:$AP$2001,2,100)&")",""),"")),"") | AK35: =SUMPRODUCT((元データ!$AL$2:$AL$2001=1)*(元データ!$AN$2:$AN$2001=1)*(元データ!$AE$2:$AE$2001=$C$35)*(元データ!$AO$2:$AO$2001=1)*(元データ!$AM$2:$AM$2001>=15)*(元データ!$AM$2:$AM$2001<=21)*(元データ!$E$2:$E$2001="40 差戻し")) | AL35: =IFERROR(_xlfn.TEXTJOIN(CHAR(10),TRUE,IF((元データ!$AL$2:$AL$2001=1)*(元データ!$AN$2:$AN$2001=1)*(元データ!$AE$2:$AE$2001=$C$35)*(元データ!$AO$2:$AO$2001=1)*(元データ!$AM$2:$AM$2001>=15)*(元データ!$AM$2:$AM$2001<=21)*(元データ!$E$2:$E$2001="40 差戻し"),元データ!$A$2:$A$2001&IF(元データ!$AP$2:$AP$2001<>"","（"&MID(元データ!$AP$2:$AP$2001,2,100)&")",""),"")),"") | AM35: =SUMPRODUCT((元データ!$AL$2:$AL$2001=1)*(元データ!$AN$2:$AN$2001=1)*(元データ!$AE$2:$AE$2001=$C$35)*(元データ!$AO$2:$AO$2001=1)*(元データ!$AM$2:$AM$2001>=22)*(元データ!$AM$2:$AM$2001<=30)) | AN35: =SUMPRODUCT((元データ!$AL$2:$AL$2001=1)*(元データ!$AN$2:$AN$2001=1)*(元データ!$AE$2:$AE$2001=$C$35)*(元データ!$AO$2:$AO$2001=1)*(元データ!$AM$2:$AM$2001>=22)*(元データ!$AM$2:$AM$2001<=30)*(元データ!$E$2:$E$2001="20 確認待ち")) | AO35: =IFERROR(_xlfn.TEXTJOIN(CHAR(10),TRUE,IF((元データ!$AL$2:$AL$2001=1)*(元データ!$AN$2:$AN$2001=1)*(元データ!$AE$2:$AE$2001=$C$35)*(元データ!$AO$2:$AO$2001=1)*(元データ!$AM$2:$AM$2001>=22)*(元データ!$AM$2:$AM$2001<=30)*(元データ!$E$2:$E$2001="20 確認待ち"),元データ!$A$2:$A$2001&IF(元データ!$AP$2:$AP$2001<>"","（"&MID(元データ!$AP$2:$AP$2001,2,100)&")",""),"")),"") | AP35: =SUMPRODUCT((元データ!$AL$2:$AL$2001=1)*(元データ!$AN$2:$AN$2001=1)*(元データ!$AE$2:$AE$2001=$C$35)*(元データ!$AO$2:$AO$2001=1)*(元データ!$AM$2:$AM$2001>=22)*(元データ!$AM$2:$AM$2001<=30)*(元データ!$E$2:$E$2001="30 申請受付")) | AQ35: =IFERROR(_xlfn.TEXTJOIN(CHAR(10),TRUE,IF((元データ!$AL$2:$AL$2001=1)*(元データ!$AN$2:$AN$2001=1)*(元データ!$AE$2:$AE$2001=$C$35)*(元データ!$AO$2:$AO$2001=1)*(元データ!$AM$2:$AM$2001>=22)*(元データ!$AM$2:$AM$2001<=30)*(元データ!$E$2:$E$2001="30 申請受付"),元データ!$A$2:$A$2001&IF(元データ!$AP$2:$AP$2001<>"","（"&MID(元データ!$AP$2:$AP$2001,2,100)&")",""),"")),"") | AR35: =SUMPRODUCT((元データ!$AL$2:$AL$2001=1)*(元データ!$AN$2:$AN$2001=1)*(元データ!$AE$2:$AE$2001=$C$35)*(元データ!$AO$2:$AO$2001=1)*(元データ!$AM$2:$AM$2001>=22)*(元データ!$AM$2:$AM$2001<=30)*(元データ!$E$2:$E$2001="31 ＯＰ確認中")) | AS35: =IFERROR(_xlfn.TEXTJOIN(CHAR(10),TRUE,IF((元データ!$AL$2:$AL$2001=1)*(元データ!$AN$2:$AN$2001=1)*(元データ!$AE$2:$AE$2001=$C$35)*(元データ!$AO$2:$AO$2001=1)*(元データ!$AM$2:$AM$2001>=22)*(元データ!$AM$2:$AM$2001<=30)*(元データ!$E$2:$E$2001="31 ＯＰ確認中"),元データ!$A$2:$A$2001&IF(元データ!$AP$2:$AP$2001<>"","（"&MID(元データ!$AP$2:$AP$2001,2,100)&")",""),"")),"") | AT35: =SUMPRODUCT((元データ!$AL$2:$AL$2001=1)*(元データ!$AN$2:$AN$2001=1)*(元データ!$AE$2:$AE$2001=$C$35)*(元データ!$AO$2:$AO$2001=1)*(元データ!$AM$2:$AM$2001>=22)*(元データ!$AM$2:$AM$2001<=30)*(元データ!$E$2:$E$2001="32 ＳＶ確認中")) | AU35: =IFERROR(_xlfn.TEXTJOIN(CHAR(10),TRUE,IF((元データ!$AL$2:$AL$2001=1)*(元データ!$AN$2:$AN$2001=1)*(元データ!$AE$2:$AE$2001=$C$35)*(元データ!$AO$2:$AO$2001=1)*(元データ!$AM$2:$AM$2001>=22)*(元データ!$AM$2:$AM$2001<=30)*(元データ!$E$2:$E$2001="32 ＳＶ確認中"),元データ!$A$2:$A$2001&IF(元データ!$AP$2:$AP$2001<>"","（"&MID(元データ!$AP$2:$AP$2001,2,100)&")",""),"")),"") | AV35: =SUMPRODUCT((元データ!$AL$2:$AL$2001=1)*(元データ!$AN$2:$AN$2001=1)*(元データ!$AE$2:$AE$2001=$C$35)*(元データ!$AO$2:$AO$2001=1)*(元データ!$AM$2:$AM$2001>=22)*(元データ!$AM$2:$AM$2001<=30)*(元データ!$E$2:$E$2001="40 差戻し")) | AW35: =IFERROR(_xlfn.TEXTJOIN(CHAR(10),TRUE,IF((元データ!$AL$2:$AL$2001=1)*(元データ!$AN$2:$AN$2001=1)*(元データ!$AE$2:$AE$2001=$C$35)*(元データ!$AO$2:$AO$2001=1)*(元データ!$AM$2:$AM$2001>=22)*(元データ!$AM$2:$AM$2001<=30)*(元データ!$E$2:$E$2001="40 差戻し"),元データ!$A$2:$A$2001&IF(元データ!$AP$2:$AP$2001<>"","（"&MID(元データ!$AP$2:$AP$2001,2,100)&")",""),"")),"") | AX35: =SUMPRODUCT((元データ!$AL$2:$AL$2001=1)*(元データ!$AN$2:$AN$2001=1)*(元データ!$AE$2:$AE$2001=$C$35)*(元データ!$AO$2:$AO$2001=1)*(元データ!$AM$2:$AM$2001>=31)) | AY35: =SUMPRODUCT((元データ!$AL$2:$AL$2001=1)*(元データ!$AN$2:$AN$2001=1)*(元データ!$AE$2:$AE$2001=$C$35)*(元データ!$AO$2:$AO$2001=1)*(元データ!$AM$2:$AM$2001>=31)*(元データ!$E$2:$E$2001="20 確認待ち")) | AZ35: =IFERROR(_xlfn.TEXTJOIN(CHAR(10),TRUE,IF((元データ!$AL$2:$AL$2001=1)*(元データ!$AN$2:$AN$2001=1)*(元データ!$AE$2:$AE$2001=$C$35)*(元データ!$AO$2:$AO$2001=1)*(元データ!$AM$2:$AM$2001>=31)*(元データ!$E$2:$E$2001="20 確認待ち"),元データ!$A$2:$A$2001&IF(元データ!$AP$2:$AP$2001<>"","（"&MID(元データ!$AP$2:$AP$2001,2,100)&")",""),"")),"") | BA35: =SUMPRODUCT((元データ!$AL$2:$AL$2001=1)*(元データ!$AN$2:$AN$2001=1)*(元データ!$AE$2:$AE$2001=$C$35)*(元データ!$AO$2:$AO$2001=1)*(元データ!$AM$2:$AM$2001>=31)*(元データ!$E$2:$E$2001="30 申請受付")) | BB35: =IFERROR(_xlfn.TEXTJOIN(CHAR(10),TRUE,IF((元データ!$AL$2:$AL$2001=1)*(元データ!$AN$2:$AN$2001=1)*(元データ!$AE$2:$AE$2001=$C$35)*(元データ!$AO$2:$AO$2001=1)*(元データ!$AM$2:$AM$2001>=31)*(元データ!$E$2:$E$2001="30 申請受付"),元データ!$A$2:$A$2001&IF(元データ!$AP$2:$AP$2001<>"","（"&MID(元データ!$AP$2:$AP$2001,2,100)&")",""),"")),"") | BC35: =SUMPRODUCT((元データ!$AL$2:$AL$2001=1)*(元データ!$AN$2:$AN$2001=1)*(元データ!$AE$2:$AE$2001=$C$35)*(元データ!$AO$2:$AO$2001=1)*(元データ!$AM$2:$AM$2001>=31)*(元データ!$E$2:$E$2001="31 ＯＰ確認中")) | BD35: =IFERROR(_xlfn.TEXTJOIN(CHAR(10),TRUE,IF((元データ!$AL$2:$AL$2001=1)*(元データ!$AN$2:$AN$2001=1)*(元データ!$AE$2:$AE$2001=$C$35)*(元データ!$AO$2:$AO$2001=1)*(元データ!$AM$2:$AM$2001>=31)*(元データ!$E$2:$E$2001="31 ＯＰ確認中"),元データ!$A$2:$A$2001&IF(元データ!$AP$2:$AP$2001<>"","（"&MID(元データ!$AP$2:$AP$2001,2,100)&")",""),"")),"") | BE35: =SUMPRODUCT((元データ!$AL$2:$AL$2001=1)*(元データ!$AN$2:$AN$2001=1)*(元データ!$AE$2:$AE$2001=$C$35)*(元データ!$AO$2:$AO$2001=1)*(元データ!$AM$2:$AM$2001>=31)*(元データ!$E$2:$E$2001="32 ＳＶ確認中")) | BF35: =IFERROR(_xlfn.TEXTJOIN(CHAR(10),TRUE,IF((元データ!$AL$2:$AL$2001=1)*(元データ!$AN$2:$AN$2001=1)*(元データ!$AE$2:$AE$2001=$C$35)*(元データ!$AO$2:$AO$2001=1)*(元データ!$AM$2:$AM$2001>=31)*(元データ!$E$2:$E$2001="32 ＳＶ確認中"),元データ!$A$2:$A$2001&IF(元データ!$AP$2:$AP$2001<>"","（"&MID(元データ!$AP$2:$AP$2001,2,100)&")",""),"")),"") | BG35: =SUMPRODUCT((元データ!$AL$2:$AL$2001=1)*(元データ!$AN$2:$AN$2001=1)*(元データ!$AE$2:$AE$2001=$C$35)*(元データ!$AO$2:$AO$2001=1)*(元データ!$AM$2:$AM$2001>=31)*(元データ!$E$2:$E$2001="40 差戻し")) | BH35: =IFERROR(_xlfn.TEXTJOIN(CHAR(10),TRUE,IF((元データ!$AL$2:$AL$2001=1)*(元データ!$AN$2:$AN$2001=1)*(元データ!$AE$2:$AE$2001=$C$35)*(元データ!$AO$2:$AO$2001=1)*(元データ!$AM$2:$AM$2001>=31)*(元データ!$E$2:$E$2001="40 差戻し"),元データ!$A$2:$A$2001&IF(元データ!$AP$2:$AP$2001<>"","（"&MID(元データ!$AP$2:$AP$2001,2,100)&")",""),"")),"")
D36: なし | E36: =SUMPRODUCT((元データ!$AL$2:$AL$2001=1)*(元データ!$AN$2:$AN$2001=1)*(元データ!$AE$2:$AE$2001=$C$35)*(元データ!$AO$2:$AO$2001=0)) | F36: =SUMPRODUCT((元データ!$AL$2:$AL$2001=1)*(元データ!$AN$2:$AN$2001=1)*(元データ!$AE$2:$AE$2001=$C$35)*(元データ!$AO$2:$AO$2001=0)*(元データ!$AM$2:$AM$2001<=7)) | G36: =SUMPRODUCT((元データ!$AL$2:$AL$2001=1)*(元データ!$AN$2:$AN$2001=1)*(元データ!$AE$2:$AE$2001=$C$35)*(元データ!$AO$2:$AO$2001=0)*(元データ!$AM$2:$AM$2001<=7)*(元データ!$E$2:$E$2001="20 確認待ち")) | H36: =IFERROR(_xlfn.TEXTJOIN(CHAR(10),TRUE,IF((元データ!$AL$2:$AL$2001=1)*(元データ!$AN$2:$AN$2001=1)*(元データ!$AE$2:$AE$2001=$C$35)*(元データ!$AO$2:$AO$2001=0)*(元データ!$AM$2:$AM$2001<=7)*(元データ!$E$2:$E$2001="20 確認待ち"),元データ!$A$2:$A$2001&IF(元データ!$AP$2:$AP$2001<>"","（"&MID(元データ!$AP$2:$AP$2001,2,100)&")",""),"")),"") | I36: =SUMPRODUCT((元データ!$AL$2:$AL$2001=1)*(元データ!$AN$2:$AN$2001=1)*(元データ!$AE$2:$AE$2001=$C$35)*(元データ!$AO$2:$AO$2001=0)*(元データ!$AM$2:$AM$2001<=7)*(元データ!$E$2:$E$2001="30 申請受付")) | J36: =IFERROR(_xlfn.TEXTJOIN(CHAR(10),TRUE,IF((元データ!$AL$2:$AL$2001=1)*(元データ!$AN$2:$AN$2001=1)*(元データ!$AE$2:$AE$2001=$C$35)*(元データ!$AO$2:$AO$2001=0)*(元データ!$AM$2:$AM$2001<=7)*(元データ!$E$2:$E$2001="30 申請受付"),元データ!$A$2:$A$2001&IF(元データ!$AP$2:$AP$2001<>"","（"&MID(元データ!$AP$2:$AP$2001,2,100)&")",""),"")),"") | K36: =SUMPRODUCT((元データ!$AL$2:$AL$2001=1)*(元データ!$AN$2:$AN$2001=1)*(元データ!$AE$2:$AE$2001=$C$35)*(元データ!$AO$2:$AO$2001=0)*(元データ!$AM$2:$AM$2001<=7)*(元データ!$E$2:$E$2001="31 ＯＰ確認中")) | L36: =IFERROR(_xlfn.TEXTJOIN(CHAR(10),TRUE,IF((元データ!$AL$2:$AL$2001=1)*(元データ!$AN$2:$AN$2001=1)*(元データ!$AE$2:$AE$2001=$C$35)*(元データ!$AO$2:$AO$2001=0)*(元データ!$AM$2:$AM$2001<=7)*(元データ!$E$2:$E$2001="31 ＯＰ確認中"),元データ!$A$2:$A$2001&IF(元データ!$AP$2:$AP$2001<>"","（"&MID(元データ!$AP$2:$AP$2001,2,100)&")",""),"")),"") | M36: =SUMPRODUCT((元データ!$AL$2:$AL$2001=1)*(元データ!$AN$2:$AN$2001=1)*(元データ!$AE$2:$AE$2001=$C$35)*(元データ!$AO$2:$AO$2001=0)*(元データ!$AM$2:$AM$2001<=7)*(元データ!$E$2:$E$2001="32 ＳＶ確認中")) | N36: =IFERROR(_xlfn.TEXTJOIN(CHAR(10),TRUE,IF((元データ!$AL$2:$AL$2001=1)*(元データ!$AN$2:$AN$2001=1)*(元データ!$AE$2:$AE$2001=$C$35)*(元データ!$AO$2:$AO$2001=0)*(元データ!$AM$2:$AM$2001<=7)*(元データ!$E$2:$E$2001="32 ＳＶ確認中"),元データ!$A$2:$A$2001&IF(元データ!$AP$2:$AP$2001<>"","（"&MID(元データ!$AP$2:$AP$2001,2,100)&")",""),"")),"") | O36: =SUMPRODUCT((元データ!$AL$2:$AL$2001=1)*(元データ!$AN$2:$AN$2001=1)*(元データ!$AE$2:$AE$2001=$C$35)*(元データ!$AO$2:$AO$2001=0)*(元データ!$AM$2:$AM$2001<=7)*(元データ!$E$2:$E$2001="40 差戻し")) | P36: =IFERROR(_xlfn.TEXTJOIN(CHAR(10),TRUE,IF((元データ!$AL$2:$AL$2001=1)*(元データ!$AN$2:$AN$2001=1)*(元データ!$AE$2:$AE$2001=$C$35)*(元データ!$AO$2:$AO$2001=0)*(元データ!$AM$2:$AM$2001<=7)*(元データ!$E$2:$E$2001="40 差戻し"),元データ!$A$2:$A$2001&IF(元データ!$AP$2:$AP$2001<>"","（"&MID(元データ!$AP$2:$AP$2001,2,100)&")",""),"")),"") | Q36: =SUMPRODUCT((元データ!$AL$2:$AL$2001=1)*(元データ!$AN$2:$AN$2001=1)*(元データ!$AE$2:$AE$2001=$C$35)*(元データ!$AO$2:$AO$2001=0)*(元データ!$AM$2:$AM$2001>=8)*(元データ!$AM$2:$AM$2001<=14)) | R36: =SUMPRODUCT((元データ!$AL$2:$AL$2001=1)*(元データ!$AN$2:$AN$2001=1)*(元データ!$AE$2:$AE$2001=$C$35)*(元データ!$AO$2:$AO$2001=0)*(元データ!$AM$2:$AM$2001>=8)*(元データ!$AM$2:$AM$2001<=14)*(元データ!$E$2:$E$2001="20 確認待ち")) | S36: =IFERROR(_xlfn.TEXTJOIN(CHAR(10),TRUE,IF((元データ!$AL$2:$AL$2001=1)*(元データ!$AN$2:$AN$2001=1)*(元データ!$AE$2:$AE$2001=$C$35)*(元データ!$AO$2:$AO$2001=0)*(元データ!$AM$2:$AM$2001>=8)*(元データ!$AM$2:$AM$2001<=14)*(元データ!$E$2:$E$2001="20 確認待ち"),元データ!$A$2:$A$2001&IF(元データ!$AP$2:$AP$2001<>"","（"&MID(元データ!$AP$2:$AP$2001,2,100)&")",""),"")),"") | T36: =SUMPRODUCT((元データ!$AL$2:$AL$2001=1)*(元データ!$AN$2:$AN$2001=1)*(元データ!$AE$2:$AE$2001=$C$35)*(元データ!$AO$2:$AO$2001=0)*(元データ!$AM$2:$AM$2001>=8)*(元データ!$AM$2:$AM$2001<=14)*(元データ!$E$2:$E$2001="30 申請受付")) | U36: =IFERROR(_xlfn.TEXTJOIN(CHAR(10),TRUE,IF((元データ!$AL$2:$AL$2001=1)*(元データ!$AN$2:$AN$2001=1)*(元データ!$AE$2:$AE$2001=$C$35)*(元データ!$AO$2:$AO$2001=0)*(元データ!$AM$2:$AM$2001>=8)*(元データ!$AM$2:$AM$2001<=14)*(元データ!$E$2:$E$2001="30 申請受付"),元データ!$A$2:$A$2001&IF(元データ!$AP$2:$AP$2001<>"","（"&MID(元データ!$AP$2:$AP$2001,2,100)&")",""),"")),"") | V36: =SUMPRODUCT((元データ!$AL$2:$AL$2001=1)*(元データ!$AN$2:$AN$2001=1)*(元データ!$AE$2:$AE$2001=$C$35)*(元データ!$AO$2:$AO$2001=0)*(元データ!$AM$2:$AM$2001>=8)*(元データ!$AM$2:$AM$2001<=14)*(元データ!$E$2:$E$2001="31 ＯＰ確認中")) | W36: =IFERROR(_xlfn.TEXTJOIN(CHAR(10),TRUE,IF((元データ!$AL$2:$AL$2001=1)*(元データ!$AN$2:$AN$2001=1)*(元データ!$AE$2:$AE$2001=$C$35)*(元データ!$AO$2:$AO$2001=0)*(元データ!$AM$2:$AM$2001>=8)*(元データ!$AM$2:$AM$2001<=14)*(元データ!$E$2:$E$2001="31 ＯＰ確認中"),元データ!$A$2:$A$2001&IF(元データ!$AP$2:$AP$2001<>"","（"&MID(元データ!$AP$2:$AP$2001,2,100)&")",""),"")),"") | X36: =SUMPRODUCT((元データ!$AL$2:$AL$2001=1)*(元データ!$AN$2:$AN$2001=1)*(元データ!$AE$2:$AE$2001=$C$35)*(元データ!$AO$2:$AO$2001=0)*(元データ!$AM$2:$AM$2001>=8)*(元データ!$AM$2:$AM$2001<=14)*(元データ!$E$2:$E$2001="32 ＳＶ確認中")) | Y36: =IFERROR(_xlfn.TEXTJOIN(CHAR(10),TRUE,IF((元データ!$AL$2:$AL$2001=1)*(元データ!$AN$2:$AN$2001=1)*(元データ!$AE$2:$AE$2001=$C$35)*(元データ!$AO$2:$AO$2001=0)*(元データ!$AM$2:$AM$2001>=8)*(元データ!$AM$2:$AM$2001<=14)*(元データ!$E$2:$E$2001="32 ＳＶ確認中"),元データ!$A$2:$A$2001&IF(元データ!$AP$2:$AP$2001<>"","（"&MID(元データ!$AP$2:$AP$2001,2,100)&")",""),"")),"") | Z36: =SUMPRODUCT((元データ!$AL$2:$AL$2001=1)*(元データ!$AN$2:$AN$2001=1)*(元データ!$AE$2:$AE$2001=$C$35)*(元データ!$AO$2:$AO$2001=0)*(元データ!$AM$2:$AM$2001>=8)*(元データ!$AM$2:$AM$2001<=14)*(元データ!$E$2:$E$2001="40 差戻し")) | AA36: =IFERROR(_xlfn.TEXTJOIN(CHAR(10),TRUE,IF((元データ!$AL$2:$AL$2001=1)*(元データ!$AN$2:$AN$2001=1)*(元データ!$AE$2:$AE$2001=$C$35)*(元データ!$AO$2:$AO$2001=0)*(元データ!$AM$2:$AM$2001>=8)*(元データ!$AM$2:$AM$2001<=14)*(元データ!$E$2:$E$2001="40 差戻し"),元データ!$A$2:$A$2001&IF(元データ!$AP$2:$AP$2001<>"","（"&MID(元データ!$AP$2:$AP$2001,2,100)&")",""),"")),"") | AB36: =SUMPRODUCT((元データ!$AL$2:$AL$2001=1)*(元データ!$AN$2:$AN$2001=1)*(元データ!$AE$2:$AE$2001=$C$35)*(元データ!$AO$2:$AO$2001=0)*(元データ!$AM$2:$AM$2001>=15)*(元データ!$AM$2:$AM$2001<=21)) | AC36: =SUMPRODUCT((元データ!$AL$2:$AL$2001=1)*(元データ!$AN$2:$AN$2001=1)*(元データ!$AE$2:$AE$2001=$C$35)*(元データ!$AO$2:$AO$2001=0)*(元データ!$AM$2:$AM$2001>=15)*(元データ!$AM$2:$AM$2001<=21)*(元データ!$E$2:$E$2001="20 確認待ち")) | AD36: =IFERROR(_xlfn.TEXTJOIN(CHAR(10),TRUE,IF((元データ!$AL$2:$AL$2001=1)*(元データ!$AN$2:$AN$2001=1)*(元データ!$AE$2:$AE$2001=$C$35)*(元データ!$AO$2:$AO$2001=0)*(元データ!$AM$2:$AM$2001>=15)*(元データ!$AM$2:$AM$2001<=21)*(元データ!$E$2:$E$2001="20 確認待ち"),元データ!$A$2:$A$2001&IF(元データ!$AP$2:$AP$2001<>"","（"&MID(元データ!$AP$2:$AP$2001,2,100)&")",""),"")),"") | AE36: =SUMPRODUCT((元データ!$AL$2:$AL$2001=1)*(元データ!$AN$2:$AN$2001=1)*(元データ!$AE$2:$AE$2001=$C$35)*(元データ!$AO$2:$AO$2001=0)*(元データ!$AM$2:$AM$2001>=15)*(元データ!$AM$2:$AM$2001<=21)*(元データ!$E$2:$E$2001="30 申請受付")) | AF36: =IFERROR(_xlfn.TEXTJOIN(CHAR(10),TRUE,IF((元データ!$AL$2:$AL$2001=1)*(元データ!$AN$2:$AN$2001=1)*(元データ!$AE$2:$AE$2001=$C$35)*(元データ!$AO$2:$AO$2001=0)*(元データ!$AM$2:$AM$2001>=15)*(元データ!$AM$2:$AM$2001<=21)*(元データ!$E$2:$E$2001="30 申請受付"),元データ!$A$2:$A$2001&IF(元データ!$AP$2:$AP$2001<>"","（"&MID(元データ!$AP$2:$AP$2001,2,100)&")",""),"")),"") | AG36: =SUMPRODUCT((元データ!$AL$2:$AL$2001=1)*(元データ!$AN$2:$AN$2001=1)*(元データ!$AE$2:$AE$2001=$C$35)*(元データ!$AO$2:$AO$2001=0)*(元データ!$AM$2:$AM$2001>=15)*(元データ!$AM$2:$AM$2001<=21)*(元データ!$E$2:$E$2001="31 ＯＰ確認中")) | AH36: =IFERROR(_xlfn.TEXTJOIN(CHAR(10),TRUE,IF((元データ!$AL$2:$AL$2001=1)*(元データ!$AN$2:$AN$2001=1)*(元データ!$AE$2:$AE$2001=$C$35)*(元データ!$AO$2:$AO$2001=0)*(元データ!$AM$2:$AM$2001>=15)*(元データ!$AM$2:$AM$2001<=21)*(元データ!$E$2:$E$2001="31 ＯＰ確認中"),元データ!$A$2:$A$2001&IF(元データ!$AP$2:$AP$2001<>"","（"&MID(元データ!$AP$2:$AP$2001,2,100)&")",""),"")),"") | AI36: =SUMPRODUCT((元データ!$AL$2:$AL$2001=1)*(元データ!$AN$2:$AN$2001=1)*(元データ!$AE$2:$AE$2001=$C$35)*(元データ!$AO$2:$AO$2001=0)*(元データ!$AM$2:$AM$2001>=15)*(元データ!$AM$2:$AM$2001<=21)*(元データ!$E$2:$E$2001="32 ＳＶ確認中")) | AJ36: =IFERROR(_xlfn.TEXTJOIN(CHAR(10),TRUE,IF((元データ!$AL$2:$AL$2001=1)*(元データ!$AN$2:$AN$2001=1)*(元データ!$AE$2:$AE$2001=$C$35)*(元データ!$AO$2:$AO$2001=0)*(元データ!$AM$2:$AM$2001>=15)*(元データ!$AM$2:$AM$2001<=21)*(元データ!$E$2:$E$2001="32 ＳＶ確認中"),元データ!$A$2:$A$2001&IF(元データ!$AP$2:$AP$2001<>"","（"&MID(元データ!$AP$2:$AP$2001,2,100)&")",""),"")),"") | AK36: =SUMPRODUCT((元データ!$AL$2:$AL$2001=1)*(元データ!$AN$2:$AN$2001=1)*(元データ!$AE$2:$AE$2001=$C$35)*(元データ!$AO$2:$AO$2001=0)*(元データ!$AM$2:$AM$2001>=15)*(元データ!$AM$2:$AM$2001<=21)*(元データ!$E$2:$E$2001="40 差戻し")) | AL36: =IFERROR(_xlfn.TEXTJOIN(CHAR(10),TRUE,IF((元データ!$AL$2:$AL$2001=1)*(元データ!$AN$2:$AN$2001=1)*(元データ!$AE$2:$AE$2001=$C$35)*(元データ!$AO$2:$AO$2001=0)*(元データ!$AM$2:$AM$2001>=15)*(元データ!$AM$2:$AM$2001<=21)*(元データ!$E$2:$E$2001="40 差戻し"),元データ!$A$2:$A$2001&IF(元データ!$AP$2:$AP$2001<>"","（"&MID(元データ!$AP$2:$AP$2001,2,100)&")",""),"")),"") | AM36: =SUMPRODUCT((元データ!$AL$2:$AL$2001=1)*(元データ!$AN$2:$AN$2001=1)*(元データ!$AE$2:$AE$2001=$C$35)*(元データ!$AO$2:$AO$2001=0)*(元データ!$AM$2:$AM$2001>=22)*(元データ!$AM$2:$AM$2001<=30)) | AN36: =SUMPRODUCT((元データ!$AL$2:$AL$2001=1)*(元データ!$AN$2:$AN$2001=1)*(元データ!$AE$2:$AE$2001=$C$35)*(元データ!$AO$2:$AO$2001=0)*(元データ!$AM$2:$AM$2001>=22)*(元データ!$AM$2:$AM$2001<=30)*(元データ!$E$2:$E$2001="20 確認待ち")) | AO36: =IFERROR(_xlfn.TEXTJOIN(CHAR(10),TRUE,IF((元データ!$AL$2:$AL$2001=1)*(元データ!$AN$2:$AN$2001=1)*(元データ!$AE$2:$AE$2001=$C$35)*(元データ!$AO$2:$AO$2001=0)*(元データ!$AM$2:$AM$2001>=22)*(元データ!$AM$2:$AM$2001<=30)*(元データ!$E$2:$E$2001="20 確認待ち"),元データ!$A$2:$A$2001&IF(元データ!$AP$2:$AP$2001<>"","（"&MID(元データ!$AP$2:$AP$2001,2,100)&")",""),"")),"") | AP36: =SUMPRODUCT((元データ!$AL$2:$AL$2001=1)*(元データ!$AN$2:$AN$2001=1)*(元データ!$AE$2:$AE$2001=$C$35)*(元データ!$AO$2:$AO$2001=0)*(元データ!$AM$2:$AM$2001>=22)*(元データ!$AM$2:$AM$2001<=30)*(元データ!$E$2:$E$2001="30 申請受付")) | AQ36: =IFERROR(_xlfn.TEXTJOIN(CHAR(10),TRUE,IF((元データ!$AL$2:$AL$2001=1)*(元データ!$AN$2:$AN$2001=1)*(元データ!$AE$2:$AE$2001=$C$35)*(元データ!$AO$2:$AO$2001=0)*(元データ!$AM$2:$AM$2001>=22)*(元データ!$AM$2:$AM$2001<=30)*(元データ!$E$2:$E$2001="30 申請受付"),元データ!$A$2:$A$2001&IF(元データ!$AP$2:$AP$2001<>"","（"&MID(元データ!$AP$2:$AP$2001,2,100)&")",""),"")),"") | AR36: =SUMPRODUCT((元データ!$AL$2:$AL$2001=1)*(元データ!$AN$2:$AN$2001=1)*(元データ!$AE$2:$AE$2001=$C$35)*(元データ!$AO$2:$AO$2001=0)*(元データ!$AM$2:$AM$2001>=22)*(元データ!$AM$2:$AM$2001<=30)*(元データ!$E$2:$E$2001="31 ＯＰ確認中")) | AS36: =IFERROR(_xlfn.TEXTJOIN(CHAR(10),TRUE,IF((元データ!$AL$2:$AL$2001=1)*(元データ!$AN$2:$AN$2001=1)*(元データ!$AE$2:$AE$2001=$C$35)*(元データ!$AO$2:$AO$2001=0)*(元データ!$AM$2:$AM$2001>=22)*(元データ!$AM$2:$AM$2001<=30)*(元データ!$E$2:$E$2001="31 ＯＰ確認中"),元データ!$A$2:$A$2001&IF(元データ!$AP$2:$AP$2001<>"","（"&MID(元データ!$AP$2:$AP$2001,2,100)&")",""),"")),"") | AT36: =SUMPRODUCT((元データ!$AL$2:$AL$2001=1)*(元データ!$AN$2:$AN$2001=1)*(元データ!$AE$2:$AE$2001=$C$35)*(元データ!$AO$2:$AO$2001=0)*(元データ!$AM$2:$AM$2001>=22)*(元データ!$AM$2:$AM$2001<=30)*(元データ!$E$2:$E$2001="32 ＳＶ確認中")) | AU36: =IFERROR(_xlfn.TEXTJOIN(CHAR(10),TRUE,IF((元データ!$AL$2:$AL$2001=1)*(元データ!$AN$2:$AN$2001=1)*(元データ!$AE$2:$AE$2001=$C$35)*(元データ!$AO$2:$AO$2001=0)*(元データ!$AM$2:$AM$2001>=22)*(元データ!$AM$2:$AM$2001<=30)*(元データ!$E$2:$E$2001="32 ＳＶ確認中"),元データ!$A$2:$A$2001&IF(元データ!$AP$2:$AP$2001<>"","（"&MID(元データ!$AP$2:$AP$2001,2,100)&")",""),"")),"") | AV36: =SUMPRODUCT((元データ!$AL$2:$AL$2001=1)*(元データ!$AN$2:$AN$2001=1)*(元データ!$AE$2:$AE$2001=$C$35)*(元データ!$AO$2:$AO$2001=0)*(元データ!$AM$2:$AM$2001>=22)*(元データ!$AM$2:$AM$2001<=30)*(元データ!$E$2:$E$2001="40 差戻し")) | AW36: =IFERROR(_xlfn.TEXTJOIN(CHAR(10),TRUE,IF((元データ!$AL$2:$AL$2001=1)*(元データ!$AN$2:$AN$2001=1)*(元データ!$AE$2:$AE$2001=$C$35)*(元データ!$AO$2:$AO$2001=0)*(元データ!$AM$2:$AM$2001>=22)*(元データ!$AM$2:$AM$2001<=30)*(元データ!$E$2:$E$2001="40 差戻し"),元データ!$A$2:$A$2001&IF(元データ!$AP$2:$AP$2001<>"","（"&MID(元データ!$AP$2:$AP$2001,2,100)&")",""),"")),"") | AX36: =SUMPRODUCT((元データ!$AL$2:$AL$2001=1)*(元データ!$AN$2:$AN$2001=1)*(元データ!$AE$2:$AE$2001=$C$35)*(元データ!$AO$2:$AO$2001=0)*(元データ!$AM$2:$AM$2001>=31)) | AY36: =SUMPRODUCT((元データ!$AL$2:$AL$2001=1)*(元データ!$AN$2:$AN$2001=1)*(元データ!$AE$2:$AE$2001=$C$35)*(元データ!$AO$2:$AO$2001=0)*(元データ!$AM$2:$AM$2001>=31)*(元データ!$E$2:$E$2001="20 確認待ち")) | AZ36: =IFERROR(_xlfn.TEXTJOIN(CHAR(10),TRUE,IF((元データ!$AL$2:$AL$2001=1)*(元データ!$AN$2:$AN$2001=1)*(元データ!$AE$2:$AE$2001=$C$35)*(元データ!$AO$2:$AO$2001=0)*(元データ!$AM$2:$AM$2001>=31)*(元データ!$E$2:$E$2001="20 確認待ち"),元データ!$A$2:$A$2001&IF(元データ!$AP$2:$AP$2001<>"","（"&MID(元データ!$AP$2:$AP$2001,2,100)&")",""),"")),"") | BA36: =SUMPRODUCT((元データ!$AL$2:$AL$2001=1)*(元データ!$AN$2:$AN$2001=1)*(元データ!$AE$2:$AE$2001=$C$35)*(元データ!$AO$2:$AO$2001=0)*(元データ!$AM$2:$AM$2001>=31)*(元データ!$E$2:$E$2001="30 申請受付")) | BB36: =IFERROR(_xlfn.TEXTJOIN(CHAR(10),TRUE,IF((元データ!$AL$2:$AL$2001=1)*(元データ!$AN$2:$AN$2001=1)*(元データ!$AE$2:$AE$2001=$C$35)*(元データ!$AO$2:$AO$2001=0)*(元データ!$AM$2:$AM$2001>=31)*(元データ!$E$2:$E$2001="30 申請受付"),元データ!$A$2:$A$2001&IF(元データ!$AP$2:$AP$2001<>"","（"&MID(元データ!$AP$2:$AP$2001,2,100)&")",""),"")),"") | BC36: =SUMPRODUCT((元データ!$AL$2:$AL$2001=1)*(元データ!$AN$2:$AN$2001=1)*(元データ!$AE$2:$AE$2001=$C$35)*(元データ!$AO$2:$AO$2001=0)*(元データ!$AM$2:$AM$2001>=31)*(元データ!$E$2:$E$2001="31 ＯＰ確認中")) | BD36: =IFERROR(_xlfn.TEXTJOIN(CHAR(10),TRUE,IF((元データ!$AL$2:$AL$2001=1)*(元データ!$AN$2:$AN$2001=1)*(元データ!$AE$2:$AE$2001=$C$35)*(元データ!$AO$2:$AO$2001=0)*(元データ!$AM$2:$AM$2001>=31)*(元データ!$E$2:$E$2001="31 ＯＰ確認中"),元データ!$A$2:$A$2001&IF(元データ!$AP$2:$AP$2001<>"","（"&MID(元データ!$AP$2:$AP$2001,2,100)&")",""),"")),"") | BE36: =SUMPRODUCT((元データ!$AL$2:$AL$2001=1)*(元データ!$AN$2:$AN$2001=1)*(元データ!$AE$2:$AE$2001=$C$35)*(元データ!$AO$2:$AO$2001=0)*(元データ!$AM$2:$AM$2001>=31)*(元データ!$E$2:$E$2001="32 ＳＶ確認中")) | BF36: =IFERROR(_xlfn.TEXTJOIN(CHAR(10),TRUE,IF((元データ!$AL$2:$AL$2001=1)*(元データ!$AN$2:$AN$2001=1)*(元データ!$AE$2:$AE$2001=$C$35)*(元データ!$AO$2:$AO$2001=0)*(元データ!$AM$2:$AM$2001>=31)*(元データ!$E$2:$E$2001="32 ＳＶ確認中"),元データ!$A$2:$A$2001&IF(元データ!$AP$2:$AP$2001<>"","（"&MID(元データ!$AP$2:$AP$2001,2,100)&")",""),"")),"") | BG36: =SUMPRODUCT((元データ!$AL$2:$AL$2001=1)*(元データ!$AN$2:$AN$2001=1)*(元データ!$AE$2:$AE$2001=$C$35)*(元データ!$AO$2:$AO$2001=0)*(元データ!$AM$2:$AM$2001>=31)*(元データ!$E$2:$E$2001="40 差戻し")) | BH36: =IFERROR(_xlfn.TEXTJOIN(CHAR(10),TRUE,IF((元データ!$AL$2:$AL$2001=1)*(元データ!$AN$2:$AN$2001=1)*(元データ!$AE$2:$AE$2001=$C$35)*(元データ!$AO$2:$AO$2001=0)*(元データ!$AM$2:$AM$2001>=31)*(元データ!$E$2:$E$2001="40 差戻し"),元データ!$A$2:$A$2001&IF(元データ!$AP$2:$AP$2001<>"","（"&MID(元データ!$AP$2:$AP$2001,2,100)&")",""),"")),"")
