Workbook
Name 業務名: #REF!

Sheet 0401(予定）
A1: ※SQL(運用作業＞0230.年次＞年度繁忙）
J2: 1 | M2: 1 | N2: 1 | O2: 1 | P2: 1 | Q2: 1 | T2: 1 | U2: 1 | V2: 1 | W2: 1 | X2: 1 | AA2: 1 | AB2: 1 | AC2: 1 | AD2: 1 | AE2: 1 | AH2: 1 | AI2: 1 | AK2: 1 | AL2: =SUM(H2:AK2) -> 19
E3: 予測件数 | F3: 件数/人 | H3: 46113 | N3: システム停止日 | T3: システム停止日 | AL3: *
H4: =H3 -> 46113 | I4: =H4+1 -> 46114 | J4: =I4+1 -> 46115 | K4: =J4+1 -> 46116 | L4: =K4+1 -> 46117 | M4: =L4+1 -> 46118 | N4: =M4+1 -> 46119 | O4: =N4+1 -> 46120 | P4: =O4+1 -> 46121 | ... AK4: =AJ4+1 -> 46142 | AL4: *
H5: =H4 -> 46113 | I5: =I4 -> 46114 | J5: =J4 -> 46115 | K5: =K4 -> 46116 | L5: =L4 -> 46117 | M5: =M4 -> 46118 | N5: =N4 -> 46119 | O5: =O4 -> 46120 | ... AK5: =AK4 -> 46142 | AL5: *
B6: 通勤 | C6: 申請（合計） | E6: =SUM(H6:AK6) -> 4525 | F6: - | G6: 件数 | H6: 0 | I6: 0 | J6: =104+464 -> 568 | K6: 0 | L6: 0 | M6: 487 | N6: 0 | O6: 498 | P6: 43 | Q6: 43 | R6: 0 | S6: 0 | T6: 0 | U6: 226 | V6: 162 | W6: 86 | X6: 866 | Y6: 0 | Z6: 0 | AA6: 356 | AB6: 220 | AC6: 228 | AD6: 161 | AE6: 116 | AF6: 0 | AG6: 0 | AH6: 81 | AI6: 179 | AJ6: 0 | AK6: 205 | AL6: =SUM(H6:AK6) -> 4525
C7: 1次（日別合計） | E7: =SUM(H7:AK7) -> 1520 | F7: - | G7: 件数 | H7: =SUM(H13*$F$13,H14*$F$14,H15*$F$15,$F$16*H16,$F$17*H17,$F$18*H18,$F$19*H19) -> 0 | I7: =SUM(I13*$F$13,I14*$F$14,I15*$F$15,$F$16*I16,$F$17*I17,$F$18*I18,$F$19*I19) -> 0 | J7: =SUM(J13*$F$13,J14*$F$14,J15*$F$15,$F$16*J16,$F$17*J17,$F$18*J18,$F$19*J19) -> 85 | K7: =SUM(K13*$F$13,K14*$F$14,K15*$F$15,$F$16*K16,$F$17*K17,$F$18*K18,$F$19*K19) -> 0 | L7: =SUM(L13*$F$13,L14*$F$14,L15*$F$15,$F$16*L16,$F$17*L17,$F$18*L18,$F$19*L19) -> 0 | M7: =SUM(M13*$F$13,M14*$F$14,M15*$F$15,$F$16*M16,$F$17*M17,$F$18*M18,$F$19*M19) -> 75 | N7: =SUM(N13*$F$13,N14*$F$14,N15*$F$15,$F$16*N16,$F$17*N17,$F$18*N18,$F$19*N19) -> 75 | O7: =SUM(O13*$F$13,O14*$F$14,O15*$F$15,$F$16*O16,$F$17*O17,$F$18*O18,$F$19*O19) -> 75 | ... AK7: =SUM(AK13*$F$13,AK14*$F$14,AK15*$F$15,$F$16*AK16,$F$17*AK17,$F$18*AK18,$F$19*AK19) -> 95 | AL7: *
C8: 1次（累計） | E8: - | F8: - | G8: 件数 | H8: =H7 -> 0 | I8: =H8+I7 -> 0 | J8: =I8+J7 -> 85 | K8: =J8+K7 -> 85 | L8: =K8+L7 -> 85 | M8: =L8+M7 -> 160 | N8: =M8+N7 -> 235 | O8: =N8+O7 -> 310 | P8: =O8+P7 -> 385 | ... AK8: =AJ8+AK7 -> 1520
C9: 2次（日別合計） | E9: =SUM(H9:AK9) -> 1001 | F9: - | G9: 件数 | H9: =SUM(H20:H23) -> 0 | I9: =SUM(I20*$F$20,I21*$F$21,I22*$F$22,I23*$F$23) -> 0 | J9: =SUM(J20*$F$20,J21*$F$21,J22*$F$22,J23*$F$23) -> 39 | K9: =SUM(K20*$F$20,K21*$F$21,K22*$F$22,K23*$F$23) -> 0 | L9: =SUM(L20*$F$20,L21*$F$21,L22*$F$22,L23*$F$23) -> 0 | M9: =SUM(M20*$F$20,M21*$F$21,M22*$F$22,M23*$F$23) -> 35 | N9: =SUM(N20*$F$20,N21*$F$21,N22*$F$22,N23*$F$23) -> 45 | O9: =SUM(O20*$F$20,O21*$F$21,O22*$F$22,O23*$F$23) -> 35 | P9: =SUM(P20*$F$20,P21*$F$21,P22*$F$22,P23*$F$23) -> 35 | ... AK9: =SUM(AK20*$F$20,AK21*$F$21,AK22*$F$22,AK23*$F$23) -> 80 | AL9: *
C10: 2次（累計） | E10: - | F10: - | G10: 件数 | H10: =H9 -> 0 | I10: =H10+I9 -> 0 | J10: =I10+J9 -> 39 | K10: =J10+K9 -> 39 | L10: =K10+L9 -> 39 | M10: =L10+M9 -> 74 | N10: =M10+N9 -> 119 | O10: =N10+O9 -> 154 | P10: =O10+P9 -> 189 | ... AK10: =AJ10+AK9 -> 1001
C11: 1次残件数 | E11: =E6-E7 -> 3005 | F11: - | G11: 件数 | H11: =H6-H7 -> 0 | I11: =H11+I6-I7 -> 0 | J11: =I11+J6-J7 -> 483 | K11: =J11+K6-K7 -> 483 | L11: =K11+L6-L7 -> 483 | M11: =L11+M6-M7 -> 895 | N11: =M11+N6-N7 -> 820 | O11: =N11+O6-O7 -> 1243 | P11: =O11+P6-P7 -> 1211 | ... AK11: =AJ11+AK6-AK7 -> 3005 | AL11: *
C12: 2次残件数 | E12: =E6-E9 -> 3524 | F12: - | G12: 件数 | H12: =SUM($H$6:H6)-SUM($H$9:H9) -> 0 | I12: =H12+I6-I9 -> 0 | J12: =I12+J6-J9 -> 529 | K12: =J12+K6-K9 -> 529 | L12: =K12+L6-L9 -> 529 | M12: =L12+M6-M9 -> 981 | N12: =M12+N6-N9 -> 936 | O12: =N12+O6-O9 -> 1399 | P12: =O12+P6-P9 -> 1407 | ... AK12: =AJ12+AK6-AK9 -> 3524 | AL12: *
C13: 1次 | D13: OP | E13: =SUM(H13:AK13)*F13 -> 210 | F13: 20 | G13: 人数 | J13: 1 | M13: 0.5 | N13: 0.5 | O13: 0.5 | P13: 0.5 | Q13: 1 | T13: 0.5 | U13: 0.5 | V13: 0.5 | W13: 0.5 | X13: 1 | AA13: 0.5 | AB13: 0.5 | AC13: 0.5 | AD13: 0.5 | AE13: 0.5 | AH13: 0.5 | AK13: 0.5 | AL13: *
D14: 大場 | E14: =SUM(H14:AK14)*F14 -> 110 | F14: 20 | G14: 人数 | J14: 0.5 | M14: 0.5 | N14: 0.5 | O14: 0.5 | P14: 0.5 | Q14: 0.5 | AA14: 0.5 | AB14: 0.5 | AC14: 0.5 | AD14: 0.5 | AE14: 0.5 | AL14: *
D15: 平田 | E15: =SUM(H15:AK15)*F15 -> 360 | F15: 20 | G15: 人数 | J15: 1 | M15: 1 | N15: 1 | O15: 1 | P15: 1 | Q15: 1 | T15: 1 | U15: 1 | V15: 1 | W15: 1 | X15: 1 | AA15: 1 | AB15: 1 | AC15: 1 | AD15: 1 | AE15: 1 | AH15: 1 | AK15: 1 | AL15: *
D16: 丸山 | E16: =SUM(H16:AK16)*F16 -> 180 | F16: 20 | G16: 人数 | J16: 0.5 | M16: 0.5 | N16: 0.5 | O16: 0.5 | P16: 0.5 | Q16: 0.5 | T16: 0.5 | U16: 0.5 | V16: 0.5 | W16: 0.5 | X16: 0.5 | AA16: 0.5 | AB16: 0.5 | AC16: 0.5 | AD16: 0.5 | AE16: 0.5 | AH16: 0.5 | AK16: 0.5 | AL16: *
D17: 三浦 | E17: =SUM(H17:AK17)*F17 -> 210 | F17: 30 | G17: 人数 | AA17: 1 | AB17: 1 | AC17: 1 | AD17: 1 | AE17: 1 | AH17: 1 | AK17: 1 | AL17: *
D18: 目黒 | E18: =SUM(H18:AK18)*F18 -> 270 | F18: 15 | G18: 人数 | J18: 1 | M18: 1 | N18: 1 | O18: 1 | P18: 1 | Q18: 1 | T18: 1 | U18: 1 | V18: 1 | W18: 1 | X18: 1 | AA18: 1 | AB18: 1 | AC18: 1 | AD18: 1 | AE18: 1 | AH18: 1 | AK18: 1 | AL18: *
D19: 池田 | E19: =SUM(H19:AK19)*F19 -> 180 | F19: 10 | G19: 人数 | J19: 1 | M19: 1 | N19: 1 | O19: 1 | P19: 1 | Q19: 1 | T19: 1 | U19: 1 | V19: 1 | W19: 1 | X19: 1 | AA19: 1 | AB19: 1 | AC19: 1 | AD19: 1 | AE19: 1 | AH19: 1 | AK19: 1 | AL19: *
C20: 2次 | D20: 田中 | E20: =SUM(H20:AK20)*F20 -> 369 | F20: 30 | G20: 人数 | J20: 0.3 | M20: 0.5 | N20: 0.5 | O20: 0.5 | P20: 0.5 | Q20: 0.5 | T20: 0.5 | U20: 0.5 | V20: 0.5 | W20: 0.5 | X20: 0.5 | AA20: 1 | AB20: 1 | AC20: 1 | AD20: 1 | AE20: 1 | AH20: 1 | AK20: 1 | AL20: *
D21: 小野 | E21: =SUM(H21:AK21)*F21 -> 492 | F21: 40 | G21: 人数 | J21: 0.5 | M21: 0.5 | N21: 0.5 | O21: 0.5 | P21: 0.5 | Q21: 0.5 | T21: 0.5 | U21: 0.5 | V21: 0.5 | W21: 0.5 | X21: 0.5 | AA21: 1 | AB21: 0.8 | AC21: 1 | AD21: 1 | AE21: 1 | AH21: 1 | AK21: 1 | AL21: *
D22: 大場 | E22: =SUM(H22:AK22)*F22 -> 70 | F22: 20 | G22: 人数 | T22: 0.5 | U22: 0.5 | V22: 0.5 | W22: 0.5 | X22: 0.5 | AH22: 0.5 | AK22: 0.5 | AL22: *
D23: OP | E23: =SUM(H23:AK23)*F23 -> 70 | F23: 20 | G23: 人数 | J23: 0.5 | N23: 0.5 | Q23: 0.5 | U23: 0.5 | X23: 0.5 | AB23: 0.5 | AE23: 0.5 | AL23: *
B24: 扶養 児童 | C24: 申請（合計） | E24: =SUM(H24:AK24) -> 904 | F24: - | G24: 件数 | J24: =151+23 -> 174 | K24: 0 | L24: 0 | M24: 16 | N24: 17 | O24: 50 | P24: 41 | Q24: 58 | R24: 0 | S24: 0 | T24: 25 | U24: 57 | V24: 15 | W24: 40 | X24: 98 | Y24: 0 | Z24: 0 | AA24: 36 | AB24: 17 | AC24: 50 | AD24: 41 | AE24: 58 | AF24: 0 | AG24: 0 | AH24: 25 | AI24: 64 | AJ24: 0 | AK24: 22 | AL24: *
C25: 1次（合計） | E25: =SUM(H25:AK25) -> 487.5 | F25: - | G25: 件数 | J25: =SUM(J31*$F$31,J32*$F$32,J33*$F$33) -> 30 | K25: =SUM(K31*$F$31,K32*$F$32,K33*$F$33) -> 0 | L25: =SUM(L31*$F$31,L32*$F$32,L33*$F$33) -> 0 | M25: =SUM(M31*$F$31,M32*$F$32,M33*$F$33) -> 22.5 | N25: =SUM(N31*$F$31,N32*$F$32,N33*$F$33) -> 22.5 | O25: =SUM(O31*$F$31,O32*$F$32,O33*$F$33) -> 22.5 | P25: =SUM(P31*$F$31,P32*$F$32,P33*$F$33) -> 22.5 | Q25: =SUM(Q31*$F$31,Q32*$F$32,Q33*$F$33) -> 22.5 | ... AK25: =SUM(AK31*$F$31,AK32*$F$32,AK33*$F$33) -> 30 | AL25: *
C26: 1次（累計） | E26: - | F26: - | G26: 件数 | H26: =H25 -> 0 | I26: =H26+I25 -> 0 | J26: =I26+J25 -> 30 | K26: =J26+K25 -> 30 | L26: =K26+L25 -> 30 | M26: =L26+M25 -> 52.5 | N26: =M26+N25 -> 75 | O26: =N26+O25 -> 97.5 | P26: =O26+P25 -> 120 | ... AK26: =AJ26+AK25 -> 487.5
C27: 2次（合計） | E27: =SUM(H27:AK27) -> 264 | F27: - | G27: 件数 | J27: =SUM(J34*$F$34,J35*$F$35,J36*$F$36,J37*$F$37) -> 13 | K27: =SUM(K34*$F$34,K35*$F$35,K36*$F$36,K37*$F$37) -> 0 | L27: =SUM(L34*$F$34,L35*$F$35,L36*$F$36,L37*$F$37) -> 0 | M27: =SUM(M34*$F$34,M35*$F$35,M36*$F$36,M37*$F$37) -> 13 | N27: =SUM(N34*$F$34,N35*$F$35,N36*$F$36,N37*$F$37) -> 13 | O27: =SUM(O34*$F$34,O35*$F$35,O36*$F$36,O37*$F$37) -> 13 | P27: =SUM(P34*$F$34,P35*$F$35,P36*$F$36,P37*$F$37) -> 13 | Q27: =SUM(Q34*$F$34,Q35*$F$35,Q36*$F$36,Q37*$F$37) -> 13 | ... AK27: =SUM(AK34*$F$34,AK35*$F$35,AK36*$F$36,AK37*$F$37) -> 13 | AL27: *
C28: 2次（累計） | E28: - | F28: - | G28: 件数 | H28: =H27 -> 0 | I28: =H28+I27 -> 0 | J28: =I28+J27 -> 13 | K28: =J28+K27 -> 13 | L28: =K28+L27 -> 13 | M28: =L28+M27 -> 26 | N28: =M28+N27 -> 39 | O28: =N28+O27 -> 52 | P28: =O28+P27 -> 65 | ... AK28: =AJ28+AK27 -> 264
C29: 1次残件数 | E29: =E24-E25 -> 416.5 | F29: - | G29: 件数 | J29: =I29+J24-J25 -> 144 | K29: =J29+K24-K25 -> 144 | L29: =K29+L24-L25 -> 144 | M29: =L29+M24-M25 -> 137.5 | N29: =M29+N24-N25 -> 132 | O29: =N29+O24-O25 -> 159.5 | P29: =O29+P24-P25 -> 178 | Q29: =P29+Q24-Q25 -> 213.5 | ... AK29: =AJ29+AK24-AK25 -> 416.5 | AL29: *
C30: 2次残件数 | E30: =E24-E27 -> 640 | F30: - | G30: 件数 | J30: =I30+J24-J27 -> 161 | K30: =J30+K24-K27 -> 161 | L30: =K30+L24-L27 -> 161 | M30: =L30+M24-M27 -> 164 | N30: =M30+N24-N27 -> 168 | O30: =N30+O24-O27 -> 205 | P30: =O30+P24-P27 -> 233 | Q30: =P30+Q24-Q27 -> 278 | ... AK30: =AJ30+AK24-AK27 -> 640 | AL30: *
C31: 1次 | D31: OP | E31: =SUM(H31:AK31)*F31 -> 217.5 | F31: 15 | G31: 人数 | J31: 1 | M31: 0.5 | N31: 0.5 | O31: 0.5 | P31: 0.5 | Q31: 0.5 | T31: 0.5 | U31: 1 | V31: 1 | W31: 1 | X31: 1 | AA31: 0.5 | AB31: 1 | AC31: 1 | AD31: 1 | AE31: 1.5 | AH31: 0.5 | AK31: 1 | AL31: *
D32: 小菅 | E32: =SUM(H32:AK32)*F32 -> 270 | F32: 15 | G32: 人数 | J32: 1 | M32: 1 | N32: 1 | O32: 1 | P32: 1 | Q32: 1 | T32: 1 | U32: 1 | V32: 1 | W32: 1 | X32: 1 | AA32: 1 | AB32: 1 | AC32: 1 | AD32: 1 | AE32: 1 | AH32: 1 | AK32: 1 | AL32: *
G33: 人数 | AL33: *
C34: 2次 | D34: 西村 | E34: =SUM(H34:AK34)*F34 -> 234 | F34: 13 | G34: 人数 | J34: 1 | M34: 1 | N34: 1 | O34: 1 | P34: 1 | Q34: 1 | T34: 1 | U34: 1 | V34: 1 | W34: 1 | X34: 1 | AA34: 1 | AB34: 1 | AC34: 1 | AD34: 1 | AE34: 1 | AH34: 1 | AK34: 1 | AL34: *
D35: 栗城 | E35: =SUM(H35:AK35)*F35 -> 30 | F35: 10 | G35: 人数 | T35: 1 | AA35: 1 | AH35: 1 | AL35: *
D36: 管理 | E36: =SUM(H36:AK36) -> 0 | G36: 人数 | AL36: *
G37: 人数 | AL37: *
B38: 給与 | C38: 申請（合計） | E38: =SUM(H38:AK38) -> 265 | F38: - | G38: 件数 | J38: =44+39 -> 83 | K38: 0 | L38: 0 | M38: 1 | N38: 47 | O38: 0 | P38: 1 | Q38: 6 | R38: 0 | S38: 0 | T38: 15 | U38: 2 | V38: 3 | W38: 8 | X38: 6 | Y38: 0 | Z38: 0 | AA38: 9 | AB38: 47 | AC38: 0 | AD38: 1 | AE38: 6 | AF38: 0 | AG38: 0 | AH38: 15 | AI38: 5 | AJ38: 0 | AK38: 10 | AL38: *
C39: 1次（合計） | E39: =SUM(H39:AK39) -> 201 | F39: - | G39: 件数 | J39: =SUM(J45*$F$45,J46*$F$46,J47*$F$47) -> 0 | K39: =SUM(K45*$F$45,K46*$F$46,K47*$F$47) -> 0 | L39: =SUM(L45*$F$45,L46*$F$46,L47*$F$47) -> 0 | M39: =SUM(M45*$F$45,M46*$F$46,M47*$F$47) -> 0 | N39: =SUM(N45*$F$45,N46*$F$46,N47*$F$47) -> 6 | O39: =SUM(O45*$F$45,O46*$F$46,O47*$F$47) -> 6 | P39: =SUM(P45*$F$45,P46*$F$46,P47*$F$47) -> 6 | Q39: =SUM(Q45*$F$45,Q46*$F$46,Q47*$F$47) -> 6 | ... AK39: =SUM(AK45*$F$45,AK46*$F$46,AK47*$F$47) -> 21 | AL39: *
C40: 1次（累計） | E40: - | F40: - | G40: 件数 | H40: =H39 -> 0 | I40: =H40+I39 -> 0 | J40: =I40+J39 -> 0 | K40: =J40+K39 -> 0 | L40: =K40+L39 -> 0 | M40: =L40+M39 -> 0 | N40: =M40+N39 -> 6 | O40: =N40+O39 -> 12 | P40: =O40+P39 -> 18 | ... AK40: =AJ40+AK39 -> 201
...

Sheet 0401(実績)
J2: 1 | M2: 1 | N2: 1 | O2: 1 | P2: 1 | Q2: 1 | T2: 1 | U2: 1 | V2: 1 | W2: 1 | X2: 1 | AA2: 1 | AB2: 1 | AC2: 1 | AD2: 1 | AE2: 1 | AH2: 1 | AI2: 1 | AK2: 1 | AL2: =SUM(H2:AK2) -> 19
E3: 予測件数 | F3: 件数/人 | H3: 46113 | N3: システム停止日 | T3: システム停止日 | AL3: *
H4: =H3 -> 46113 | I4: =H4+1 -> 46114 | J4: =I4+1 -> 46115 | K4: =J4+1 -> 46116 | L4: =K4+1 -> 46117 | M4: =L4+1 -> 46118 | N4: =M4+1 -> 46119 | O4: =N4+1 -> 46120 | P4: =O4+1 -> 46121 | ... AK4: =AJ4+1 -> 46142 | AL4: *
H5: =H4 -> 46113 | I5: =I4 -> 46114 | J5: =J4 -> 46115 | K5: =K4 -> 46116 | L5: =L4 -> 46117 | M5: =M4 -> 46118 | N5: =N4 -> 46119 | O5: =O4 -> 46120 | ... AK5: =AK4 -> 46142 | AL5: *
B6: 通勤 | C6: 申請（合計） | E6: =SUM(H6:AK6) -> 2876 | F6: - | G6: 件数 | J6: =104+91 -> 195 | M6: 113 | N6: 144 | O6: 122 | P6: 156 | Q6: 139 | T6: 144 | U6: 229 | V6: 126 | W6: 127 | X6: 109 | AA6: 188 | AB6: 86 | AC6: 277 | AD6: 136 | AE6: 124 | AH6: 110 | AI6: 159 | AK6: 192 | AL6: =SUM(H6:AK6) -> 2876
C7: 1次（合計） | E7: =SUM(H7:AK7) -> 1831 | F7: - | G7: 件数 | H7: =SUM(H13:H23) -> 0 | I7: =SUM(I13:I23) -> 0 | J7: =SUM(J13:J23) -> 29 | K7: =SUM(K13:K23) -> 0 | L7: =SUM(L13:L23) -> 0 | M7: =SUM(M13:M23) -> 73 | N7: =SUM(N13:N23) -> 88 | O7: =SUM(O13:O23) -> 78 | ... AK7: =SUM(AK13:AK23) -> 119 | AL7: *
C8: １次（累計） | E8: =AK8 -> 1831 | F8: - | G8: 件数 | H8: =H7 -> 0 | I8: =H8+I7 -> 0 | J8: =I8+J7 -> 29 | K8: =J8+K7 -> 29 | L8: =K8+L7 -> 29 | M8: =L8+M7 -> 102 | N8: =M8+N7 -> 190 | O8: =N8+O7 -> 268 | P8: =O8+P7 -> 340 | ... AK8: =AJ8+AK7 -> 1831 | AL8: *
C9: 2次（合計） | E9: =SUM(H9:AK9) -> 1093 | F9: - | G9: 件数 | H9: =SUM(H24:H28) -> 0 | I9: =SUM(I24:I28) -> 0 | J9: =SUM(J24:J28) -> 24 | K9: =SUM(K24:K28) -> 0 | L9: =SUM(L24:L28) -> 0 | M9: =SUM(M24:M28) -> 17 | N9: =SUM(N24:N28) -> 32 | O9: =SUM(O24:O28) -> 44 | ... AK9: =SUM(AK24:AK28) -> 70 | AL9: *
C10: 2次（累計） | E10: =AK10 -> 1093 | F10: - | G10: 件数 | H10: =H9 -> 0 | I10: =H10+I9 -> 0 | J10: =I10+J9 -> 24 | K10: =J10+K9 -> 24 | L10: =K10+L9 -> 24 | M10: =L10+M9 -> 41 | N10: =M10+N9 -> 73 | O10: =N10+O9 -> 117 | P10: =O10+P9 -> 157 | ... AK10: =AJ10+AK9 -> 1093 | AL10: *
C11: 1次残件数 | E11: =E6-E7 -> 1045 | F11: - | G11: 件数 | H11: =H6-H7 -> 0 | I11: =H11+I6-I7 -> 0 | J11: =I11+J6-J7 -> 166 | K11: =J11+K6-K7 -> 166 | L11: =K11+L6-L7 -> 166 | M11: =L11+M6-M7 -> 206 | N11: =M11+N6-N7 -> 262 | O11: =N11+O6-O7 -> 306 | P11: =O11+P6-P7 -> 390 | ... AK11: =AJ11+AK6-AK7 -> 1045 | AL11: *
C12: 2次残件数 | E12: =E6-E9 -> 1783 | F12: - | G12: 件数 | H12: =SUM($H$6:H6)-SUM($H$9:H9) -> 0 | I12: =H12+I6-I9 -> 0 | J12: =I12+J6-J9 -> 171 | K12: =J12+K6-K9 -> 171 | L12: =K12+L6-L9 -> 171 | M12: =L12+M6-M9 -> 267 | N12: =M12+N6-N9 -> 379 | O12: =N12+O6-O9 -> 457 | P12: =O12+P6-P9 -> 573 | ... AK12: =AJ12+AK6-AK9 -> 1783 | AL12: *
C13: 1次 | D13: 伊藤 | E13: =SUM(H13:AK13) -> 51 | F13: 20 | G13: 件数 | N13: 11 | V13: 13 | AC13: 15 | AE13: 11 | AI13: 1 | AL13: *
D14: 植田 | E14: =SUM(H14:AK14) -> 70 | F14: 20 | G14: 件数 | Q14: 7 | U14: 11 | W14: 13 | AB14: 12 | AD14: 11 | AE14: 11 | AK14: 5 | AL14: *
D15: 兼田 | E15: =SUM(H15:AK15) -> 46 | F15: 20 | G15: 件数 | J15: 5 | N15: 9 | P15: 7 | U15: 6 | AA15: 9 | AH15: 10 | AL15: *
D16: 島 | E16: =SUM(H16:AK16) -> 57 | F16: 20 | G16: 件数 | M16: 12 | O16: 15 | X16: 17 | AI16: 13 | AL16: *
D17: 大場 | E17: =SUM(H17:AK17) -> 137 | F17: 20 | G17: 件数 | J17: 12 | M17: 5 | N17: 10 | O17: 8 | P17: 7 | T17: 11 | U17: 7 | V17: 12 | W17: 11 | X17: 6 | AA17: 5 | AB17: 8 | AC17: 14 | AD17: 6 | AE17: 5 | AH17: 6 | AI17: 4 | AL17: *
D18: 平田 | E18: =SUM(H18:AK18) -> 217 | F18: 20 | G18: 件数 | J18: 5 | M18: 13 | N18: 11 | O18: 14 | P18: 13 | Q18: 10 | T18: 12 | U18: 10 | V18: 11 | W18: 10 | X18: 15 | AA18: 17 | AB18: 14 | AC18: 12 | AD18: 7 | AE18: 9 | AH18: 16 | AI18: 10 | AK18: 8 | AL18: *
D19: 丸山 | E19: =SUM(H19:AK19) -> 191 | F19: 20 | G19: 件数 | J19: 7 | M19: 12 | N19: 15 | O19: 10 | P19: 11 | Q19: 4 | T19: 9 | U19: 7 | W19: 15 | X19: 10 | AA19: 12 | AB19: 12 | AC19: 10 | AD19: 12 | AE19: 7 | AH19: 12 | AI19: 16 | AK19: 10 | AL19: *
D20: 三浦 | E20: =SUM(H20:AK20) -> 352 | F20: 30 | G20: 件数 | U20: 14 | V20: 26 | W20: 29 | X20: 34 | AA20: 33 | AB20: 34 | AC20: 37 | AD20: 33 | AH20: 33 | AI20: 38 | AK20: 41 | AL20: *
D21: 目黒 | E21: =SUM(H21:AK21) -> 294 | F21: 15 | G21: 件数 | M21: 15 | N21: 16 | O21: 16 | P21: 15 | Q21: 16 | U21: 15 | V21: 19 | W21: 15 | X21: 15 | AA21: 14 | AB21: 17 | AC21: 20 | AD21: 17 | AE21: 19 | AH21: 21 | AI21: 18 | AK21: 26 | AL21: *
D22: 池田 | E22: =SUM(H22:AK22) -> 352 | F22: 10 | G22: 件数 | M22: 16 | N22: 16 | O22: 15 | P22: 19 | Q22: 19 | U22: 18 | V22: 21 | W22: 23 | X22: 25 | AA22: 21 | AB22: 19 | AC22: 23 | AD22: 25 | AE22: 19 | AH22: 23 | AI22: 21 | AK22: 29 | AL22: *
D23: 市丸 | E23: - | F23: - | G23: 件数 | V23: 40 | W23: 1 | AB23: 19 | AE23: 4 | AL23: *
C24: 2次 | D24: 田中 | E24: =SUM(H24:AK24) -> 221 | F24: 30 | G24: 件数 | M24: 6 | O24: 2 | P24: 1 | Q24: 8 | T24: 8 | U24: 7 | V24: 18 | W24: 26 | X24: 3 | AA24: 15 | AB24: 18 | AC24: 30 | AD24: 2 | AE24: 6 | AH24: 26 | AI24: 20 | AK24: 25 | AL24: *
D25: 小野 | E25: =SUM(H25:AK25) -> 714 | F25: 40 | G25: 件数 | J25: 24 | N25: 32 | O25: 40 | P25: 39 | Q25: 44 | T25: 45 | U25: 27 | V25: 41 | W25: 46 | X25: 50 | AA25: 41 | AB25: 30 | AC25: 40 | AD25: 41 | AE25: 45 | AH25: 40 | AI25: 44 | AK25: 45 | AL25: *
D26: 大場 | E26: =SUM(H26:AK26) -> 69 | F26: 20 | G26: 件数 | M26: 11 | O26: 2 | V26: 3 | W26: 3 | X26: 7 | AA26: 9 | AB26: 3 | AC26: 5 | AD26: 7 | AE26: 7 | AH26: 10 | AI26: 2 | AL26: *
D27: 市丸 | E27: - | F27: - | G27: 件数 | W27: 40 | AB27: 19 | AE27: 4 | AL27: *
D28: OP | E28: =SUM(H28:AK28) -> 26 | F28: 20 | G28: 件数 | Q28: 4 | X28: 7 | AB28: 7 | AE28: 4 | AI28: 4 | AL28: *
B29: 扶養 児童 | C29: 申請（合計） | E29: =SUM(H29:AK29) -> 803 | F29: - | G29: 件数 | J29: =151+36 -> 187 | M29: 21 | N29: 39 | O29: 28 | P29: 34 | Q29: 49 | T29: 33 | U29: 55 | V29: 33 | W29: 24 | X29: 33 | AA29: 44 | AB29: 36 | AC29: 29 | AD29: 41 | AE29: 31 | AH29: 33 | AI29: 29 | AK29: 24 | AL29: *
C30: 1次（合計） | E30: =SUM(H30:AK30) -> 648 | F30: - | G30: 件数 | J30: =SUM(J36:J41) -> 21 | K30: =SUM(K36:K41) -> 0 | L30: =SUM(L36:L41) -> 0 | M30: =SUM(M36:M41) -> 12 | N30: =SUM(N36:N41) -> 24 | O30: =SUM(O36:O41) -> 24 | P30: =SUM(P36:P41) -> 32 | Q30: =SUM(Q36:Q41) -> 38 | ... AK30: =SUM(AK36:AK41) -> 34 | AL30: *
C31: １次（累計） | E31: =AK31 -> 648 | F31: - | G31: 件数 | J31: =I31+J30 -> 21 | K31: =J31+K30 -> 21 | L31: =K31+L30 -> 21 | M31: =L31+M30 -> 33 | N31: =M31+N30 -> 57 | O31: =N31+O30 -> 81 | P31: =O31+P30 -> 113 | Q31: =P31+Q30 -> 151 | ... AK31: =AJ31+AK30 -> 648 | AL31: *
C32: 2次（合計） | E32: =SUM(H32:AK32) -> 510 | F32: - | G32: 件数 | J32: =SUM(J42:J45) -> 16 | K32: =SUM(K42:K45) -> 0 | L32: =SUM(L42:L45) -> 0 | M32: =SUM(M42:M45) -> 13 | N32: =SUM(N42:N45) -> 20 | O32: =SUM(O42:O45) -> 29 | P32: =SUM(P42:P45) -> 25 | Q32: =SUM(Q42:Q45) -> 19 | ... AK32: =SUM(AK42:AK45) -> 22 | AL32: *
C33: 2次（累計） | E33: =AK33 -> 510 | F33: - | G33: 件数 | J33: =I33+J32 -> 16 | K33: =J33+K32 -> 16 | L33: =K33+L32 -> 16 | M33: =L33+M32 -> 29 | N33: =M33+N32 -> 49 | O33: =N33+O32 -> 78 | P33: =O33+P32 -> 103 | Q33: =P33+Q32 -> 122 | ... AK33: =AJ33+AK32 -> 510 | AL33: *
C34: 1次残件数 | E34: =E29-E30 -> 155 | F34: - | G34: 件数 | J34: =I34+J29-J30 -> 166 | K34: =J34+K29-K30 -> 166 | L34: =K34+L29-L30 -> 166 | M34: =L34+M29-M30 -> 175 | N34: =M34+N29-N30 -> 190 | O34: =N34+O29-O30 -> 194 | P34: =O34+P29-P30 -> 196 | Q34: =P34+Q29-Q30 -> 207 | ... AK34: =AJ34+AK29-AK30 -> 155 | AL34: *
C35: 2次残件数 | E35: =E29-E32 -> 293 | F35: - | G35: 件数 | J35: =I35+J29-J32 -> 171 | K35: =J35+K29-K32 -> 171 | L35: =K35+L29-L32 -> 171 | M35: =L35+M29-M32 -> 179 | N35: =M35+N29-N32 -> 198 | O35: =N35+O29-O32 -> 197 | P35: =O35+P29-P32 -> 206 | Q35: =P35+Q29-Q32 -> 236 | ... AK35: =AJ35+AK29-AK32 -> 293 | AL35: *
C36: 1次 | D36: 伊藤 | E36: =SUM(H36:AK36)*F36 -> 735 | F36: 15 | G36: 人数 | J36: 5 | O36: 8 | U36: 11 | W36: 8 | X36: 6 | AD36: 4 | AE36: 1 | AK36: 6 | AL36: *
D37: 植田 | E37: =SUM(H37:AK37)*F37 -> 1470 | F37: 15 | G37: 人数 | N37: 9 | P37: 13 | T37: 9 | U37: 2 | V37: 11 | X37: 16 | AC37: 15 | AH37: 12 | AI37: 11 | AL37: *
D38: 兼田 | E38: =SUM(H38:AK38)*F38 -> 765 | F38: 15 | G38: 人数 | Q38: 2 | T38: 5 | W38: 6 | AB38: 7 | AD38: 9 | AE38: 9 | AI38: 7 | AK38: 6 | AL38: *
D39: 島 | E39: =SUM(H39:AK39)*F39 -> 1395 | F39: 15 | G39: 人数 | J39: 7 | Q39: 12 | U39: 8 | V39: 16 | AA39: 13 | AC39: 19 | AE39: 7 | AH39: 11 | AL39: *
D40: 小菅 | E40: =SUM(H40:AK40)*F40 -> 5025 | F40: 15 | G40: 人数 | J40: 9 | M40: 12 | N40: 15 | O40: 16 | P40: 19 | Q40: 24 | T40: 20 | U40: 26 | W40: 23 | X40: 25 | AA40: 19 | AB40: 18 | AC40: 27 | AD40: 20 | AE40: 20 | AH40: 19 | AI40: 23 | AL40: *
G41: 人数 | AK41: 22 | AL41: *
...

Sheet 0401(予実)
J2: 1 | M2: 1 | N2: 1 | O2: 1 | P2: 1 | Q2: 1 | T2: 1 | U2: 1 | V2: 1 | W2: 1 | X2: 1 | AA2: 1 | AB2: 1 | AC2: 1 | AD2: 1 | AE2: 1 | AH2: 1 | AI2: 1 | AK2: 1 | AL2: =SUM(H2:AK2) -> 19
E3: 予測件数 | F3: 件数/人 | H3: 46113 | N3: システム停止日 | T3: システム停止日 | AL3: *
H4: =H3 -> 46113 | I4: =H4+1 -> 46114 | J4: =I4+1 -> 46115 | K4: =J4+1 -> 46116 | L4: =K4+1 -> 46117 | M4: =L4+1 -> 46118 | N4: =M4+1 -> 46119 | O4: =N4+1 -> 46120 | P4: =O4+1 -> 46121 | ... AK4: =AJ4+1 -> 46142 | AL4: *
H5: =H4 -> 46113 | I5: =I4 -> 46114 | J5: =J4 -> 46115 | K5: =K4 -> 46116 | L5: =L4 -> 46117 | M5: =M4 -> 46118 | N5: =N4 -> 46119 | O5: =O4 -> 46120 | ... AK5: =AK4 -> 46142 | AL5: *
B6: 通勤 | C6: 申請（合計） | E6: ='0401(予定）'!E6 -> 4525 | F6: ='0401(予定）'!F6 -> - | G6: ='0401(予定）'!G6 -> 件数 | H6: ='0401(予定）'!H6 -> 0 | I6: ='0401(予定）'!I6 -> 0 | J6: ='0401(予定）'!J6 -> 568 | K6: ='0401(予定）'!K6 -> 0 | L6: ='0401(予定）'!L6 -> 0 | ... AK6: ='0401(予定）'!AK6 -> 205 | AL6: =SUM(H6:AK6) -> 4525
C7: 申請（合計） | E7: ='0401(実績)'!E6 -> 2876 | F7: ='0401(実績)'!F6 -> - | G7: ='0401(実績)'!G6 -> 件数 | H7: ='0401(実績)'!H6 -> 0 | I7: ='0401(実績)'!I6 -> 0 | J7: ='0401(実績)'!J6 -> 195 | K7: ='0401(実績)'!K6 -> 0 | L7: ='0401(実績)'!L6 -> 0 | ... AK7: ='0401(実績)'!AK6 -> 192 | AL7: =SUM(H7:AK7) -> 2876
C8: 1次（累計） | E8: ='0401(予定）'!E8 -> - | F8: ='0401(予定）'!F8 -> - | G8: ='0401(予定）'!G8 -> 件数 | H8: ='0401(予定）'!H8 -> 0 | I8: ='0401(予定）'!I8 -> 0 | J8: ='0401(予定）'!J8 -> 85 | K8: ='0401(予定）'!K8 -> 85 | L8: ='0401(予定）'!L8 -> 85 | ... AK8: ='0401(予定）'!AK8 -> 1520 | AL8: *
C9: １次（累計） | E9: ='0401(実績)'!E8 -> 1831 | F9: ='0401(実績)'!F8 -> - | G9: ='0401(実績)'!G8 -> 件数 | H9: ='0401(実績)'!H8 -> 0 | I9: ='0401(実績)'!I8 -> 0 | J9: ='0401(実績)'!J8 -> 29 | K9: ='0401(実績)'!K8 -> 29 | L9: ='0401(実績)'!L8 -> 29 | ... AK9: ='0401(実績)'!AK8 -> 1831 | AL9: *
C10: 2次（累計） | E10: ='0401(予定）'!E10 -> - | F10: ='0401(予定）'!F10 -> - | G10: ='0401(予定）'!G10 -> 件数 | H10: ='0401(予定）'!H10 -> 0 | I10: ='0401(予定）'!I10 -> 0 | J10: ='0401(予定）'!J10 -> 39 | K10: ='0401(予定）'!K10 -> 39 | L10: ='0401(予定）'!L10 -> 39 | ... AK10: ='0401(予定）'!AK10 -> 1001 | AL10: *
C11: 2次（累計） | E11: ='0401(実績)'!E10 -> 1093 | F11: ='0401(実績)'!F10 -> - | G11: ='0401(実績)'!G10 -> 件数 | H11: ='0401(実績)'!H10 -> 0 | I11: ='0401(実績)'!I10 -> 0 | J11: ='0401(実績)'!J10 -> 24 | K11: ='0401(実績)'!K10 -> 24 | L11: ='0401(実績)'!L10 -> 24 | ... AK11: ='0401(実績)'!AK10 -> 1093 | AL11: *
B12: 扶養 児童 | C12: 申請（合計） | E12: ='0401(予定）'!E24 -> 904 | F12: ='0401(予定）'!F24 -> - | G12: ='0401(予定）'!G24 -> 件数 | H12: ='0401(予定）'!H24 -> 0 | I12: ='0401(予定）'!I24 -> 0 | J12: ='0401(予定）'!J24 -> 174 | K12: ='0401(予定）'!K24 -> 0 | L12: ='0401(予定）'!L24 -> 0 | ... AK12: ='0401(予定）'!AK24 -> 22 | AL12: *
C13: 申請（合計） | E13: ='0401(実績)'!E29 -> 803 | F13: ='0401(実績)'!F29 -> - | G13: ='0401(実績)'!G29 -> 件数 | H13: ='0401(実績)'!H29 -> 0 | I13: ='0401(実績)'!I29 -> 0 | J13: ='0401(実績)'!J29 -> 187 | K13: ='0401(実績)'!K29 -> 0 | L13: ='0401(実績)'!L29 -> 0 | ... AK13: ='0401(実績)'!AK29 -> 24 | AL13: *
C14: 1次（累計） | E14: ='0401(予定）'!E14 -> 110 | F14: ='0401(予定）'!F14 -> 20 | G14: ='0401(予定）'!G14 -> 人数 | H14: ='0401(予定）'!H14 -> 0 | I14: ='0401(予定）'!I14 -> 0 | J14: ='0401(予定）'!J14 -> 0.5 | K14: ='0401(予定）'!K14 -> 0 | L14: ='0401(予定）'!L14 -> 0 | ... AK14: ='0401(予定）'!AK14 -> 0 | AL14: *
C15: １次（累計） | E15: ='0401(実績)'!E14 -> 70 | F15: ='0401(実績)'!F14 -> 20 | G15: ='0401(実績)'!G14 -> 件数 | H15: ='0401(実績)'!H14 -> 0 | I15: ='0401(実績)'!I14 -> 0 | J15: ='0401(実績)'!J14 -> 0 | K15: ='0401(実績)'!K14 -> 0 | L15: ='0401(実績)'!L14 -> 0 | ... AK15: ='0401(実績)'!AK14 -> 5 | AL15: *
C16: 2次（累計） | E16: ='0401(予定）'!E16 -> 180 | F16: ='0401(予定）'!F16 -> 20 | G16: ='0401(予定）'!G16 -> 人数 | H16: ='0401(予定）'!H16 -> 0 | I16: ='0401(予定）'!I16 -> 0 | J16: ='0401(予定）'!J16 -> 0.5 | K16: ='0401(予定）'!K16 -> 0 | L16: ='0401(予定）'!L16 -> 0 | ... AK16: ='0401(予定）'!AK16 -> 0.5 | AL16: *
C17: 2次（累計） | E17: ='0401(実績)'!E16 -> 57 | F17: ='0401(実績)'!F16 -> 20 | G17: ='0401(実績)'!G16 -> 件数 | H17: ='0401(実績)'!H16 -> 0 | I17: ='0401(実績)'!I16 -> 0 | J17: ='0401(実績)'!J16 -> 0 | K17: ='0401(実績)'!K16 -> 0 | L17: ='0401(実績)'!L16 -> 0 | ... AK17: ='0401(実績)'!AK16 -> 0 | AL17: *
B18: 給与 | C18: 申請（合計） | E18: ='0401(予定）'!E38 -> 265 | F18: ='0401(予定）'!F38 -> - | G18: ='0401(予定）'!G38 -> 件数 | H18: ='0401(予定）'!H38 -> 0 | I18: ='0401(予定）'!I38 -> 0 | J18: ='0401(予定）'!J38 -> 83 | K18: ='0401(予定）'!K38 -> 0 | L18: ='0401(予定）'!L38 -> 0 | ... AK18: ='0401(予定）'!AK38 -> 10 | AL18: *
C19: 申請（合計） | E19: ='0401(実績)'!E46 -> 254 | F19: ='0401(実績)'!F46 -> - | G19: ='0401(実績)'!G46 -> 件数 | H19: ='0401(実績)'!H46 -> 0 | I19: ='0401(実績)'!I46 -> 0 | J19: ='0401(実績)'!J46 -> 48 | K19: ='0401(実績)'!K46 -> 0 | L19: ='0401(実績)'!L46 -> 0 | ... AK19: ='0401(実績)'!AK46 -> 4 | AL19: *
C20: 1次（累計） | E20: ='0401(予定）'!E40 -> - | F20: ='0401(予定）'!F40 -> - | G20: ='0401(予定）'!G40 -> 件数 | H20: ='0401(予定）'!H40 -> 0 | I20: ='0401(予定）'!I40 -> 0 | J20: ='0401(予定）'!J40 -> 0 | K20: ='0401(予定）'!K40 -> 0 | L20: ='0401(予定）'!L40 -> 0 | ... AK20: ='0401(予定）'!AK40 -> 201 | AL20: *
C21: １次（累計） | E21: ='0401(実績)'!E48 -> 195 | F21: ='0401(実績)'!F48 -> - | G21: ='0401(実績)'!G48 -> 件数 | H21: ='0401(実績)'!H48 -> 0 | I21: ='0401(実績)'!I48 -> 0 | J21: ='0401(実績)'!J48 -> 13 | K21: ='0401(実績)'!K48 -> 13 | L21: ='0401(実績)'!L48 -> 13 | ... AK21: ='0401(実績)'!AK48 -> 195 | AL21: *
C22: 2次（累計） | E22: ='0401(予定）'!E42 -> - | F22: ='0401(予定）'!F42 -> - | G22: ='0401(予定）'!G42 -> 件数 | H22: ='0401(予定）'!H42 -> 0 | I22: ='0401(予定）'!I42 -> 0 | J22: ='0401(予定）'!J42 -> 8.5 | K22: ='0401(予定）'!K42 -> 8.5 | L22: ='0401(予定）'!L42 -> 8.5 | ... AK22: ='0401(予定）'!AK42 -> 173 | AL22: *
C23: 2次（累計） | E23: ='0401(実績)'!E50 -> 200 | F23: ='0401(実績)'!F50 -> - | G23: ='0401(実績)'!G50 -> 件数 | H23: ='0401(実績)'!H50 -> 0 | I23: ='0401(実績)'!I50 -> 0 | J23: ='0401(実績)'!J50 -> 3 | K23: ='0401(実績)'!K50 -> 3 | L23: ='0401(実績)'!L50 -> 3 | ... AK23: ='0401(実績)'!AK50 -> 200 | AL23: *
B24: 住居 | C24: 申請（合計） | E24: ='0401(予定）'!E52 -> 356 | F24: ='0401(予定）'!F52 -> - | G24: ='0401(予定）'!G52 -> 件数 | H24: ='0401(予定）'!H52 -> 0 | I24: ='0401(予定）'!I52 -> 0 | J24: ='0401(予定）'!J52 -> 143 | K24: ='0401(予定）'!K52 -> 0 | L24: ='0401(予定）'!L52 -> 0 | ... AK24: ='0401(予定）'!AK52 -> 10 | AL24: *
C25: 申請（合計） | E25: ='0401(実績)'!E63 -> 324 | F25: ='0401(実績)'!F63 -> - | G25: ='0401(実績)'!G63 -> 件数 | H25: ='0401(実績)'!H63 -> 0 | I25: ='0401(実績)'!I63 -> 0 | J25: ='0401(実績)'!J63 -> 139 | K25: ='0401(実績)'!K63 -> 0 | L25: ='0401(実績)'!L63 -> 0 | ... AK25: ='0401(実績)'!AK63 -> 15 | AL25: *
C26: 1次（累計） | E26: ='0401(予定）'!E54 -> - | F26: ='0401(予定）'!F54 -> - | G26: ='0401(予定）'!G54 -> 件数 | H26: ='0401(予定）'!H54 -> 0 | I26: ='0401(予定）'!I54 -> 0 | J26: ='0401(予定）'!J54 -> 0 | K26: ='0401(予定）'!K54 -> 0 | L26: ='0401(予定）'!L54 -> 0 | ... AK26: ='0401(予定）'!AK54 -> 208
C27: １次（累計） | E27: ='0401(実績)'!E65 -> 213 | F27: ='0401(実績)'!F65 -> - | G27: ='0401(実績)'!G65 -> 件数 | H27: ='0401(実績)'!H65 -> 0 | I27: ='0401(実績)'!I65 -> 0 | J27: ='0401(実績)'!J65 -> 6 | K27: ='0401(実績)'!K65 -> 6 | L27: ='0401(実績)'!L65 -> 6 | ... AK27: ='0401(実績)'!AK65 -> 213 | AL27: *
C28: 2次（累計） | E28: ='0401(予定）'!E56 -> - | F28: ='0401(予定）'!F56 -> - | G28: ='0401(予定）'!G56 -> 件数 | H28: ='0401(予定）'!H56 -> 0 | I28: ='0401(予定）'!I56 -> 0 | J28: ='0401(予定）'!J56 -> 11.7 | K28: ='0401(予定）'!K56 -> 11.7 | L28: ='0401(予定）'!L56 -> 11.7 | ... AK28: ='0401(予定）'!AK56 -> 210.6
C29: 2次（累計） | E29: ='0401(実績)'!E67 -> 255 | F29: ='0401(実績)'!F67 -> - | G29: ='0401(実績)'!G67 -> 件数 | H29: ='0401(実績)'!H67 -> 0 | I29: ='0401(実績)'!I67 -> 0 | J29: ='0401(実績)'!J67 -> 22 | K29: ='0401(実績)'!K67 -> 22 | L29: ='0401(実績)'!L67 -> 22 | ... AK29: ='0401(実績)'!AK67 -> 255 | AL29: *

Sheet 0501(予定)
H2: 1 | N2: 1 | O2: 1 | R2: 1 | S2: 1 | T2: 1 | U2: 1 | V2: 1 | Y2: 1 | Z2: 1 | AA2: 1 | AB2: 1 | AC2: 1 | AF2: 1 | AG2: 1 | AH2: 1 | AI2: 1 | AJ2: 1 | AM2: =SUM(H2:AL2) -> 18
E3: 予測件数 | F3: 件数/人 | H3: 46143 | N3: システム停止日 | AM3: *
H4: =H3 -> 46143 | I4: =H4+1 -> 46144 | J4: =I4+1 -> 46145 | K4: =J4+1 -> 46146 | L4: =K4+1 -> 46147 | M4: =L4+1 -> 46148 | N4: =M4+1 -> 46149 | O4: =N4+1 -> 46150 | P4: =O4+1 -> 46151 | ... AL4: =AK4+1 -> 46173 | AM4: *
H5: =H4 -> 46143 | I5: =I4 -> 46144 | J5: =J4 -> 46145 | K5: =K4 -> 46146 | L5: =L4 -> 46147 | M5: =M4 -> 46148 | N5: =N4 -> 46149 | O5: =O4 -> 46150 | ... AL5: =AL4 -> 46173 | AM5: *
B6: 通勤 | C6: 申請（合計） | E6: =SUM(H6:AL6)+'0401(予定）'!E6 -> 5720 | F6: - | G6: 件数 | H6: 96 | I6: 0 | J6: 0 | K6: 0 | L6: 0 | M6: 0 | N6: 0 | O6: 102 | P6: 0 | Q6: 0 | R6: 75 | S6: 213 | T6: 153 | U6: 98 | V6: 147 | W6: 0 | X6: 0 | Y6: 100 | Z6: 76 | AA6: 41 | AB6: 11 | AC6: 17 | AD6: 0 | AE6: 0 | AF6: 14 | AG6: 13 | AH6: 13 | AI6: 13 | AJ6: 13 | AK6: 0 | AL6: 0 | AM6: =SUM(H6:AL6) -> 1195
C7: 1次（合計） | E7: =SUM(H7:AL7)+'0401(予定）'!E7 -> 3305 | F7: - | G7: 件数 | H7: =SUM(H13*$F$13,H14*$F$14,H15*$F$15,$F$16*H16,$F$17*H17,$F$18*H18,$F$19*H19) -> 115 | I7: =SUM(I13*$F$13,I14*$F$14,I15*$F$15,$F$16*I16,$F$17*I17,$F$18*I18,$F$19*I19) -> 0 | J7: =SUM(J13*$F$13,J14*$F$14,J15*$F$15,$F$16*J16,$F$17*J17,$F$18*J18,$F$19*J19) -> 0 | K7: =SUM(K13*$F$13,K14*$F$14,K15*$F$15,$F$16*K16,$F$17*K17,$F$18*K18,$F$19*K19) -> 0 | L7: =SUM(L13*$F$13,L14*$F$14,L15*$F$15,$F$16*L16,$F$17*L17,$F$18*L18,$F$19*L19) -> 0 | M7: =SUM(M13*$F$13,M14*$F$14,M15*$F$15,$F$16*M16,$F$17*M17,$F$18*M18,$F$19*M19) -> 0 | N7: =SUM(N13*$F$13,N14*$F$14,N15*$F$15,$F$16*N16,$F$17*N17,$F$18*N18,$F$19*N19) -> 105 | O7: =SUM(O13*$F$13,O14*$F$14,O15*$F$15,$F$16*O16,$F$17*O17,$F$18*O18,$F$19*O19) -> 115 | ... AL7: =SUM(AL13*$F$13,AL14*$F$14,AL15*$F$15,$F$16*AL16,$F$17*AL17,$F$18*AL18,$F$19*AL19) -> 0 | AM7: *
C8: 1次（累計） | E8: - | F8: - | G8: 件数 | H8: ='0401(予定）'!AK8+H7 -> 1635 | I8: =H8+I7 -> 1635 | J8: =I8+J7 -> 1635 | K8: =J8+K7 -> 1635 | L8: =K8+L7 -> 1635 | M8: =L8+M7 -> 1635 | N8: =M8+N7 -> 1740 | O8: =N8+O7 -> 1855 | P8: =O8+P7 -> 1855 | ... AL8: =AK8+AL7 -> 3305 | AM8: *
C9: 2次（合計） | E9: =SUM(H9:AL9)+'0401(予定）'!E9 -> 2277 | F9: - | G9: 件数 | H9: =SUM(H20*$F$20,H21*$F$21,H22*$F$22,H23*$F$23) -> 80 | I9: =SUM(I20*$F$20,I21*$F$21,I22*$F$22,I23*$F$23) -> 0 | J9: =SUM(J20*$F$20,J21*$F$21,J22*$F$22,J23*$F$23) -> 0 | K9: =SUM(K20*$F$20,K21*$F$21,K22*$F$22,K23*$F$23) -> 0 | L9: =SUM(L20*$F$20,L21*$F$21,L22*$F$22,L23*$F$23) -> 0 | M9: =SUM(M20*$F$20,M21*$F$21,M22*$F$22,M23*$F$23) -> 0 | N9: =SUM(N20*$F$20,N21*$F$21,N22*$F$22,N23*$F$23) -> 70 | O9: =SUM(O20*$F$20,O21*$F$21,O22*$F$22,O23*$F$23) -> 80 | ... AL9: =SUM(AL20*$F$20,AL21*$F$21,AL22*$F$22,AL23*$F$23) -> 0 | AM9: *
C10: 2次（累計） | E10: - | F10: - | G10: 件数 | H10: ='0401(予定）'!AK10+H9 -> 1081 | I10: =H10+I9 -> 1081 | J10: =I10+J9 -> 1081 | K10: =J10+K9 -> 1081 | L10: =K10+L9 -> 1081 | M10: =L10+M9 -> 1081 | N10: =M10+N9 -> 1151 | O10: =N10+O9 -> 1231 | P10: =O10+P9 -> 1231 | ... AK10: =AJ10+AK9 -> 2277 | AM10: *
C11: 1次残件数 | E11: =E6-E7 -> 2415 | F11: - | G11: 件数 | H11: ='0401(予定）'!AK11+H6-H7 -> 2986 | I11: =H11+I6-I7 -> 2986 | J11: =I11+J6-J7 -> 2986 | K11: =J11+K6-K7 -> 2986 | L11: =K11+L6-L7 -> 2986 | M11: =L11+M6-M7 -> 2986 | N11: =M11+N6-N7 -> 2881 | O11: =N11+O6-O7 -> 2868 | P11: =O11+P6-P7 -> 2868 | ... AL11: =AK11+AL6-AL7 -> 2415 | AM11: *
C12: 2次残件数 | E12: =E6-E9 -> 3443 | F12: - | G12: 件数 | H12: ='0401(予定）'!AK12+H6-H9 -> 3540 | I12: =H12+I6-I9 -> 3540 | J12: =I12+J6-J9 -> 3540 | K12: =J12+K6-K9 -> 3540 | L12: =K12+L6-L9 -> 3540 | M12: =L12+M6-M9 -> 3540 | N12: =M12+N6-N9 -> 3470 | O12: =N12+O6-O9 -> 3492 | P12: =O12+P6-P9 -> 3492 | ... AL12: =AK12+AL6-AL9 -> 3443 | AM12: *
C13: 1次 | D13: OP | E13: =SUM(H13:AK13)*F13 -> 210 | F13: 20 | G13: 人数 | H13: 1 | N13: 0.5 | O13: 1 | R13: 0.5 | S13: 0.5 | T13: 0.5 | U13: 0.5 | V13: 1 | Y13: 0.5 | Z13: 0.5 | AA13: 0.5 | AB13: 0.5 | AC13: 1 | AF13: 0.5 | AG13: 0.5 | AH13: 0.5 | AI13: 0.5 | AM13: *
D14: 大場 | E14: =SUM(H14:AK14)*F14 -> 130 | F14: 20 | G14: 人数 | H14: 0.5 | N14: 0.5 | O14: 0.5 | R14: 0.5 | S14: 0.5 | T14: 0.5 | U14: 0.5 | V14: 0.5 | Y14: 0.5 | Z14: 0.5 | AA14: 0.5 | AB14: 0.5 | AC14: 0.5 | AM14: *
D15: 平田 | E15: =SUM(H15:AK15)*F15 -> 340 | F15: 20 | G15: 人数 | H15: 1 | N15: 1 | O15: 1 | R15: 1 | S15: 1 | T15: 1 | U15: 1 | V15: 1 | Y15: 1 | Z15: 1 | AA15: 1 | AB15: 1 | AC15: 1 | AF15: 1 | AG15: 1 | AH15: 1 | AI15: 1 | AM15: *
D16: 丸山 | E16: =SUM(H16:AK16)*F16 -> 170 | F16: 20 | G16: 人数 | H16: 0.5 | N16: 0.5 | O16: 0.5 | R16: 0.5 | S16: 0.5 | T16: 0.5 | U16: 0.5 | V16: 0.5 | Y16: 0.5 | Z16: 0.5 | AA16: 0.5 | AB16: 0.5 | AC16: 0.5 | AF16: 0.5 | AG16: 0.5 | AH16: 0.5 | AI16: 0.5 | AM16: *
D17: 三浦 | E17: =SUM(H17:AK17)*F17 -> 510 | F17: 30 | G17: 人数 | H17: 1 | N17: 1 | O17: 1 | R17: 1 | S17: 1 | T17: 1 | U17: 1 | V17: 1 | Y17: 1 | Z17: 1 | AA17: 1 | AB17: 1 | AC17: 1 | AF17: 1 | AG17: 1 | AH17: 1 | AI17: 1 | AM17: *
D18: 目黒 | E18: =SUM(H18:AK18)*F18 -> 255 | F18: 15 | G18: 人数 | H18: 1 | N18: 1 | O18: 1 | R18: 1 | S18: 1 | T18: 1 | U18: 1 | V18: 1 | Y18: 1 | Z18: 1 | AA18: 1 | AB18: 1 | AC18: 1 | AF18: 1 | AG18: 1 | AH18: 1 | AI18: 1 | AM18: *
D19: 池田 | E19: =SUM(H19:AK19)*F19 -> 170 | F19: 10 | G19: 人数 | H19: 1 | N19: 1 | O19: 1 | R19: 1 | S19: 1 | T19: 1 | U19: 1 | V19: 1 | Y19: 1 | Z19: 1 | AA19: 1 | AB19: 1 | AC19: 1 | AF19: 1 | AG19: 1 | AH19: 1 | AI19: 1 | AM19: *
C20: 2次 | D20: 田中 | E20: =SUM(H20:AK20)*F20 -> 510 | F20: 30 | G20: 人数 | H20: 1 | N20: 1 | O20: 1 | R20: 1 | S20: 1 | T20: 1 | U20: 1 | V20: 1 | Y20: 1 | Z20: 1 | AA20: 1 | AB20: 1 | AC20: 1 | AF20: 1 | AG20: 1 | AH20: 1 | AI20: 1 | AM20: *
D21: 小野 | E21: =SUM(H21:AK21)*F21 -> 656 | F21: 40 | G21: 人数 | H21: 1 | N21: 1 | O21: 1 | R21: 1 | S21: 0.8 | T21: 1 | U21: 1 | V21: 1 | Y21: 1 | Z21: 0.8 | AA21: 1 | AB21: 1 | AC21: 1 | AF21: 1 | AG21: 0.8 | AH21: 1 | AI21: 1 | AM21: *
D22: 大場 | E22: =SUM(H22:AK22)*F22 -> 40 | F22: 20 | G22: 人数 | AF22: 0.5 | AG22: 0.5 | AH22: 0.5 | AI22: 0.5 | AM22: *
D23: OP | E23: =SUM(H23:AK23)*F23 -> 70 | F23: 20 | G23: 人数 | H23: 0.5 | O23: 0.5 | S23: 0.5 | V23: 0.5 | Z23: 0.5 | AC23: 0.5 | AG23: 0.5 | AM23: *
B24: 扶養 児童 | C24: 申請（合計） | E24: =SUM(H24:AL24)+'0401(予定）'!E24 -> 1362 | F24: - | G24: 件数 | H24: 29 | I24: 0 | J24: 0 | K24: 0 | L24: 0 | M24: 0 | N24: 47 | O24: 16 | P24: 0 | Q24: 0 | R24: 23 | S24: 28 | T24: 12 | U24: 29 | V24: 26 | W24: 0 | X24: 0 | Y24: 69 | Z24: 23 | AA24: 31 | AB24: 11 | AC24: 23 | AD24: 0 | AE24: 0 | AF24: 13 | AG24: 19 | AH24: 8 | AI24: 19 | AJ24: 32 | AK24: 0 | AL24: 0 | AM24: *
C25: 1次（合計） | E25: =SUM(H25:AL25)+'0401(予定）'!E25 -> 1031.5 | F25: - | G25: 件数 | H25: =SUM(H29*$F$29,H30*$F$30,H31*$F$31) -> 32 | I25: =SUM(I29*$F$29,I30*$F$30,I31*$F$31) -> 0 | J25: =SUM(J29*$F$29,J30*$F$30,J31*$F$31) -> 0 | K25: =SUM(K29*$F$29,K30*$F$30,K31*$F$31) -> 0 | L25: =SUM(L29*$F$29,L30*$F$30,L31*$F$31) -> 0 | M25: =SUM(M29*$F$29,M30*$F$30,M31*$F$31) -> 0 | N25: =SUM(N29*$F$29,N30*$F$30,N31*$F$31) -> 32 | O25: =SUM(O29*$F$29,O30*$F$30,O31*$F$31) -> 32 | ... AL25: =SUM(AL29*$F$29,AL30*$F$30,AL31*$F$31) -> 0 | AM25: *
C26: 2次（合計） | E26: =SUM(H26:AL26)+'0401(予定）'!E27 -> 517 | F26: - | G26: 件数 | H26: =SUM(H32*$F$32,H33*$F$33,H34*$F$34,H35*$F$35) -> 13 | I26: =SUM(I32*$F$32,I33*$F$33,I34*$F$34,I35*$F$35) -> 0 | J26: =SUM(J32*$F$32,J33*$F$33,J34*$F$34,J35*$F$35) -> 0 | K26: =SUM(K32*$F$32,K33*$F$33,K34*$F$34,K35*$F$35) -> 0 | L26: =SUM(L32*$F$32,L33*$F$33,L34*$F$34,L35*$F$35) -> 0 | M26: =SUM(M32*$F$32,M33*$F$33,M34*$F$34,M35*$F$35) -> 0 | N26: =SUM(N32*$F$32,N33*$F$33,N34*$F$34,N35*$F$35) -> 21 | O26: =SUM(O32*$F$32,O33*$F$33,O34*$F$34,O35*$F$35) -> 13 | ... AL26: =SUM(AL32*$F$32,AL33*$F$33,AL34*$F$34,AL35*$F$35) -> 0 | AM26: *
C27: 1次残件数 | E27: =E24-E25 -> 330.5 | F27: - | G27: 件数 | H27: ='0401(予定）'!AK29+H24-H25 -> 413.5 | I27: =H27+I24-I25 -> 413.5 | J27: =I27+J24-J25 -> 413.5 | K27: =J27+K24-K25 -> 413.5 | L27: =K27+L24-L25 -> 413.5 | M27: =L27+M24-M25 -> 413.5 | N27: =M27+N24-N25 -> 428.5 | O27: =N27+O24-O25 -> 412.5 | P27: =O27+P24-P25 -> 412.5 | ... AL27: =AK27+AL24-AL25 -> 330.5 | AM27: *
C28: 2次残件数 | E28: =E24-E26 -> 845 | F28: - | G28: 件数 | H28: ='0401(予定）'!AK30+H24-H26 -> 656 | I28: =H28+I24-I26 -> 656 | J28: =I28+J24-J26 -> 656 | K28: =J28+K24-K26 -> 656 | L28: =K28+L24-L26 -> 656 | M28: =L28+M24-M26 -> 656 | N28: =M28+N24-N26 -> 682 | O28: =N28+O24-O26 -> 685 | P28: =O28+P24-P26 -> 685 | ... AL28: =AK28+AL24-AL26 -> 845 | AM28: *
C29: 1次 | D29: OP | E29: =SUM(H29:AL29)*F29 -> 255 | F29: 15 | G29: 人数 | H29: 1 | N29: 1 | O29: 1 | R29: 1 | S29: 1 | T29: 1 | U29: 1 | V29: 1 | Y29: 1 | Z29: 1 | AA29: 1 | AB29: 1 | AC29: 1 | AF29: 1 | AG29: 1 | AH29: 1 | AI29: 1 | AM29: *
D30: 小菅 | E30: =SUM(H30:AL30)*F30 -> 289 | F30: 17 | G30: 人数 | H30: 1 | N30: 1 | O30: 1 | R30: 1 | S30: 1 | T30: 1 | U30: 1 | V30: 1 | Y30: 1 | Z30: 1 | AA30: 1 | AB30: 1 | AC30: 1 | AF30: 1 | AG30: 1 | AH30: 1 | AI30: 1 | AM30: *
E31: =SUM(H31:AL31) -> 0 | G31: 人数 | AM31: *
C32: 2次 | D32: 西村 | E32: =SUM(H32:AL32)*F32 -> 221 | F32: 13 | G32: 人数 | H32: 1 | N32: 1 | O32: 1 | R32: 1 | S32: 1 | T32: 1 | U32: 1 | V32: 1 | Y32: 1 | Z32: 1 | AA32: 1 | AB32: 1 | AC32: 1 | AF32: 1 | AG32: 1 | AH32: 1 | AI32: 1 | AM32: *
D33: 栗城 | E33: =SUM(H33:AL33)*F33 -> 32 | F33: 10 | G33: 人数 | N33: 0.8 | S33: 0.8 | Z33: 0.8 | AG33: 0.8 | AM33: *
D34: 管理 | E34: =SUM(H34:AL34) -> 0 | F34: 10 | G34: 人数 | AM34: *
E35: =SUM(H35:AL35) -> 0 | G35: 人数 | AM35: *
B36: 給与 | C36: 申請（合計） | E36: =SUM(H36:AL36)+'0401(予定）'!E38 -> 495 | F36: - | G36: 件数 | H36: 1 | I36: 0 | J36: 0 | K36: 0 | L36: 0 | M36: 0 | N36: 11 | O36: 10 | P36: 0 | Q36: 0 | R36: 15 | S36: 13 | T36: 19 | U36: 14 | V36: 3 | W36: 0 | X36: 0 | Y36: 1 | Z36: 27 | AA36: 17 | AB36: 11 | AC36: 10 | AD36: 0 | AE36: 0 | AF36: 15 | AG36: 17 | AH36: 16 | AI36: 3 | AJ36: 27 | AK36: 0 | AL36: 0 | AM36: *
C37: 1次（合計） | E37: =SUM(H37:AL37)+'0401(予定）'!E39 -> 420 | F37: - | G37: 件数 | H37: =SUM(H41*$F$41,H42*$F$42,H43*$F$43) -> 17 | I37: =SUM(I41*$F$41,I42*$F$42,I43*$F$43) -> 0 | J37: =SUM(J41*$F$41,J42*$F$42,J43*$F$43) -> 0 | K37: =SUM(K41*$F$41,K42*$F$42,K43*$F$43) -> 0 | L37: =SUM(L41*$F$41,L42*$F$42,L43*$F$43) -> 0 | M37: =SUM(M41*$F$41,M42*$F$42,M43*$F$43) -> 0 | N37: =SUM(N41*$F$41,N42*$F$42,N43*$F$43) -> 7 | O37: =SUM(O41*$F$41,O42*$F$42,O43*$F$43) -> 17 | ... AL37: =SUM(AL41*$F$41,AL42*$F$42,AL43*$F$43) -> 0 | AM37: *
C38: 2次（合計） | E38: =SUM(H38:AL38)+'0401(予定）'!E41 -> 399 | F38: - | G38: 件数 | H38: =SUM(H44*$F$44,H45*$F$45,H46*$F$46,H47*$F$47) -> 17 | I38: =SUM(I44*$F$44,I45*$F$45,I46*$F$46,I47*$F$47) -> 0 | J38: =SUM(J44*$F$44,J45*$F$45,J46*$F$46,J47*$F$47) -> 0 | K38: =SUM(K44*$F$44,K45*$F$45,K46*$F$46,K47*$F$47) -> 0 | L38: =SUM(L44*$F$44,L45*$F$45,L46*$F$46,L47*$F$47) -> 0 | M38: =SUM(M44*$F$44,M45*$F$45,M46*$F$46,M47*$F$47) -> 0 | N38: =SUM(N44*$F$44,N45*$F$45,N46*$F$46,N47*$F$47) -> 7 | O38: =SUM(O44*$F$44,O45*$F$45,O46*$F$46,O47*$F$47) -> 17 | ... AL38: =SUM(AL44*$F$44,AL45*$F$45,AL46*$F$46,AL47*$F$47) -> 0 | AM38: *
C39: 1次残件数 | E39: =E36-E37 -> 75 | F39: - | G39: 件数 | H39: 556 | I39: =H39+I36-I37 -> 556 | J39: =I39+J36-J37 -> 556 | K39: =J39+K36-K37 -> 556 | L39: =K39+L36-L37 -> 556 | M39: =L39+M36-M37 -> 556 | N39: =M39+N36-N37 -> 560 | O39: =N39+O36-O37 -> 553 | P39: =O39+P36-P37 -> 553 | ... AL39: =AK39+AL36-AL37 -> 583 | AM39: *
C40: 2次残件数 | E40: =E36-E38 -> 96 | F40: - | G40: 件数 | H40: 720 | I40: =H40+I36-I38 -> 720 | J40: =I40+J36-J38 -> 720 | K40: =J40+K36-K38 -> 720 | L40: =K40+L36-L38 -> 720 | M40: =L40+M36-M38 -> 720 | N40: =M40+N36-N38 -> 724 | O40: =N40+O36-O38 -> 717 | P40: =O40+P36-P38 -> 717 | ... AE40: =AD40+AE36-AE38 -> 727 | AJ40: =AI40+AJ36-AJ38 -> 10 | AK40: =AJ40+AK36-AK38 -> 10 | AL40: =AK40+AL36-AL38 -> 10 | AM40: *
C41: 1次 | D41: OP | E41: =SUM(H41:AL41)*F41 -> 0 | F41: 40 | G41: 人数 | AM41: *
...

Sheet 0501(実績)
H2: 1 | N2: 1 | O2: 1 | R2: 1 | S2: 1 | T2: 1 | U2: 1 | V2: 1 | Y2: 1 | Z2: 1 | AA2: 1 | AB2: 1 | AC2: 1 | AF2: 1 | AG2: 1 | AH2: 1 | AI2: 1 | AJ2: 1 | AL2: =SUM(H2:AK2) -> 18
E3: 予測件数 | F3: 件数/人 | H3: 46143 | N3: システム停止日 | T3: システム停止日 | AL3: *
H4: =H3 -> 46143 | I4: =H4+1 -> 46144 | J4: =I4+1 -> 46145 | K4: =J4+1 -> 46146 | L4: =K4+1 -> 46147 | M4: =L4+1 -> 46148 | N4: =M4+1 -> 46149 | O4: =N4+1 -> 46150 | P4: =O4+1 -> 46151 | ... AK4: =AJ4+1 -> 46172 | AL4: *
H5: =H4 -> 46143 | I5: =I4 -> 46144 | J5: =J4 -> 46145 | K5: =K4 -> 46146 | L5: =L4 -> 46147 | M5: =M4 -> 46148 | N5: =N4 -> 46149 | O5: =O4 -> 46150 | ... AK5: =AK4 -> 46172 | AL5: *
B6: 通勤 | C6: 申請（合計） | E6: =SUM(H6:AK6) -> 1441 | F6: - | G6: 件数 | H6: 102 | N6: 119 | O6: 213 | R6: 172 | S6: 201 | T6: 160 | U6: 132 | V6: 114 | Y6: 72 | Z6: 9 | AA6: 56 | AB6: 25 | AC6: 12 | AF6: 8 | AG6: 9 | AH6: 5 | AI6: 18 | AJ6: 14 | AL6: =SUM(H6:AK6) -> 1441
C7: 1次（合計） | E7: =SUM(H7:AK7) -> 1806 | F7: - | G7: 件数 | H7: =SUM(H13:H23) -> 128 | I7: =SUM(I13:I23) -> 0 | J7: =SUM(J13:J23) -> 0 | K7: =SUM(K13:K23) -> 0 | L7: =SUM(L13:L23) -> 0 | M7: =SUM(M13:M23) -> 0 | N7: =SUM(N13:N23) -> 129 | O7: =SUM(O13:O23) -> 140 | ... AK7: =SUM(AK13:AK23) -> 0 | AL7: *
C8: １次（累計） | E8: =AK8 -> 3637 | F8: - | G8: 件数 | H8: ='0401(実績)'!AK8+H7 -> 1959 | I8: =H8+I7 -> 1959 | J8: =I8+J7 -> 1959 | K8: =J8+K7 -> 1959 | L8: =K8+L7 -> 1959 | M8: =L8+M7 -> 1959 | N8: =M8+N7 -> 2088 | O8: =N8+O7 -> 2228 | P8: =O8+P7 -> 2228 | ... AK8: =AJ8+AK7 -> 3637 | AL8: *
C9: 2次（合計） | E9: =SUM(H9:AK9) -> 1368 | F9: - | G9: 件数 | H9: =SUM(H24:H31) -> 68 | I9: =SUM(I24:I31) -> 0 | J9: =SUM(J24:J31) -> 0 | K9: =SUM(K24:K31) -> 0 | L9: =SUM(L24:L31) -> 0 | M9: =SUM(M24:M31) -> 0 | N9: =SUM(N24:N31) -> 59 | O9: =SUM(O24:O31) -> 52 | ... AK9: =SUM(AK24:AK31) -> 0 | AL9: *
C10: 2次（累計） | E10: =AK10 -> 2461 | F10: - | G10: 件数 | H10: ='0401(実績)'!AK10+H9 -> 1161 | I10: =H10+I9 -> 1161 | J10: =I10+J9 -> 1161 | K10: =J10+K9 -> 1161 | L10: =K10+L9 -> 1161 | M10: =L10+M9 -> 1161 | N10: =M10+N9 -> 1220 | O10: =N10+O9 -> 1272 | P10: =O10+P9 -> 1272 | ... AK10: =AJ10+AK9 -> 2461 | AL10: *
C11: 1次残件数 | E11: =E6-E7 -> -365 | F11: - | G11: 件数 | H11: ='0401(実績)'!AK11+H6-H7 -> 1019 | I11: =H11+I6-I7 -> 1019 | J11: =I11+J6-J7 -> 1019 | K11: =J11+K6-K7 -> 1019 | L11: =K11+L6-L7 -> 1019 | M11: =L11+M6-M7 -> 1019 | N11: =M11+N6-N7 -> 1009 | O11: =N11+O6-O7 -> 1082 | P11: =O11+P6-P7 -> 1082 | ... AK11: =AJ11+AK6-AK7 -> 680 | AL11: *
C12: 2次残件数 | E12: =E6-E9 -> 73 | F12: - | G12: 件数 | H12: ='0401(実績)'!AK12+SUM($H$6:H6)-SUM($H$9:H9) -> 1817 | I12: =H12+I6-I9 -> 1817 | J12: =I12+J6-J9 -> 1817 | K12: =J12+K6-K9 -> 1817 | L12: =K12+L6-L9 -> 1817 | M12: =L12+M6-M9 -> 1817 | N12: =M12+N6-N9 -> 1877 | O12: =N12+O6-O9 -> 2038 | P12: =O12+P6-P9 -> 2038 | ... AK12: =AJ12+AK6-AK9 -> 1856 | AL12: *
C13: 1次 | D13: 伊藤 | E13: =SUM(H13:AK13) -> 46 | F13: 20 | G13: 件数 | N13: 14 | S13: 14 | V13: 15 | Y13: 2 | AI13: 1 | AL13: *
D14: 植田 | E14: =SUM(H14:AK14) -> 9 | F14: 20 | G14: 件数 | U14: 9 | AL14: *
D15: 兼田 | E15: =SUM(H15:AK15) -> 28 | F15: 20 | G15: 件数 | H15: 2 | O15: 11 | V15: 14 | AI15: 1 | AL15: *
D16: 島 | E16: =SUM(H16:AK16) -> 35 | F16: 20 | G16: 件数 | H16: 11 | O16: 12 | T16: 12 | AL16: *
D17: 大場 | E17: =SUM(H17:AK17) -> 142 | F17: 20 | G17: 件数 | N17: 3 | O17: 5 | R17: 4 | S17: 10 | T17: 1 | U17: 11 | V17: 13 | Y17: 6 | Z17: 7 | AA17: 11 | AB17: 18 | AC17: 10 | AF17: 11 | AG17: 16 | AH17: 8 | AI17: 1 | AJ17: 7 | AL17: *
D18: 平田 | E18: =SUM(H18:AK18) -> 133 | F18: 20 | G18: 件数 | H18: 10 | N18: 9 | O18: 8 | R18: 6 | S18: 8 | T18: 10 | U18: 6 | V18: 8 | Y18: 7 | Z18: 7 | AA18: 7 | AB18: 8 | AC18: 7 | AF18: 7 | AG18: 9 | AH18: 6 | AI18: 10 | AL18: *
D19: 丸山 | E19: =SUM(H19:AK19) -> 180 | F19: 20 | G19: 件数 | H19: 11 | N19: 12 | O19: 12 | T19: 9 | U19: 11 | V19: 12 | Y19: 9 | Z19: 13 | AA19: 11 | AB19: 12 | AC19: 11 | AF19: 12 | AG19: 8 | AH19: 11 | AI19: 14 | AJ19: 12 | AL19: *
D20: 三浦 | E20: =SUM(H20:AK20) -> 582 | F20: 30 | G20: 件数 | H20: 39 | N20: 42 | O20: 40 | R20: 40 | S20: 44 | T20: 44 | U20: 41 | V20: 43 | Y20: 28 | Z20: 28 | AA20: 24 | AB20: 21 | AC20: 18 | AF20: 21 | AG20: 15 | AH20: 31 | AI20: 29 | AJ20: 34 | AL20: *
D21: 目黒 | E21: =SUM(H21:AK21) -> 302 | F21: 15 | G21: 件数 | H21: 26 | N21: 25 | O21: 24 | R21: 24 | S21: 25 | T21: 26 | U21: 23 | V21: 16 | Y21: 21 | Z21: 13 | AA21: 15 | AB21: 12 | AF21: 1 | AG21: 13 | AH21: 11 | AI21: 13 | AJ21: 14 | AL21: *
D22: 池田 | E22: =SUM(H22:AK22) -> 347 | F22: 10 | G22: 件数 | H22: 29 | N22: 24 | O22: 28 | R22: 26 | S22: 28 | T22: 27 | U22: 26 | V22: 27 | Y22: 26 | Z22: 17 | AA22: 19 | AB22: 9 | AC22: 1 | AF22: 1 | AG22: 17 | AH22: 12 | AI22: 15 | AJ22: 15 | AL22: *
D23: 市丸 | E23: - | F23: - | G23: 件数 | V23: 2 | AL23: *
C24: 2次 | D24: 田中 | E24: =SUM(H24:AK24) -> 227 | F24: 30 | G24: 件数 | H24: 28 | N24: 3 | O24: 2 | R24: 28 | S24: 27 | T24: 29 | U24: 12 | V24: 18 | Y24: 6 | Z24: 2 | AA24: 7 | AB24: 4 | AC24: 10 | AF24: 15 | AG24: 7 | AH24: 5 | AI24: 13 | AJ24: 11 | AL24: *
D25: 小野 | E25: =SUM(H25:AK25) -> 648 | F25: 40 | G25: 件数 | H25: 40 | N25: 39 | O25: 42 | R25: 8 | S25: 44 | T25: 47 | U25: 42 | V25: 42 | Y25: 44 | Z25: 25 | AA25: 33 | AB25: 18 | AC25: 23 | AF25: 38 | AG25: 46 | AH25: 40 | AI25: 43 | AJ25: 34 | AL25: *
D26: 大場 | E26: =SUM(H26:AK26) -> 124 | F26: 20 | G26: 件数 | N26: 17 | O26: 7 | S26: 1 | T26: 16 | U26: 1 | V26: 1 | Y26: 17 | Z26: 2 | AH26: 18 | AI26: 30 | AJ26: 14 | AL26: *
D27: 伊藤 | E27: =SUM(H27:AK27) -> 47 | F27: 20 | G27: 件数 | V27: 2 | Z27: 10 | AA27: 19 | AB27: 1 | AG27: 15
D28: 植田 | E28: =SUM(H28:AK28) -> 163 | F28: 20 | G28: 件数 | Y28: 14 | Z28: 26 | AB28: 2 | AC28: 28 | AG28: 26 | AH28: 28 | AI28: 9 | AJ28: 30
D29: 兼田 | E29: =SUM(H29:AK29) -> 92 | F29: 20 | G29: 件数 | AB29: 14 | AC29: 14 | AF29: 20 | AI29: 25 | AJ29: 19
D30: 島 | E30: - | F30: 20 | G30: 件数 | O30: 1 | Y30: 17 | AF30: 14 | AJ30: 18 | AL30: *
D31: 市丸 | E31: - | F31: - | G31: 件数 | V31: 2 | AF31: 9 | AG31: 6 | AL31: *
B32: 扶養 児童 | C32: 申請（合計） | E32: =SUM(H32:AK32) -> 446 | F32: - | G32: 件数 | H32: 21 | N32: 29 | O32: 33 | R32: 31 | S32: 28 | T32: 26 | U32: 24 | V32: 27 | Y32: 21 | Z32: 11 | AA32: 30 | AB32: 26 | AC32: 23 | AF32: 33 | AG32: 28 | AH32: 11 | AI32: 14 | AJ32: 30 | AL32: *
C33: 1次（合計） | E33: =SUM(H33:AK33) -> 520 | F33: - | G33: 件数 | H33: =SUM(H39:H44) -> 34 | I33: =SUM(I39:I44) -> 0 | J33: =SUM(J39:J44) -> 0 | K33: =SUM(K39:K44) -> 0 | L33: =SUM(L39:L44) -> 0 | M33: =SUM(M39:M44) -> 0 | N33: =SUM(N39:N44) -> 26 | O33: =SUM(O39:O44) -> 27 | ... AK33: =SUM(AK39:AK44) -> 0 | AL33: *
C34: １次（累計） | E34: =AK34 -> 1168 | F34: - | G34: 件数 | H34: ='0401(実績)'!AK31+'0501(実績)'!H33 -> 682 | I34: =H34+I33 -> 682 | J34: =I34+J33 -> 682 | K34: =J34+K33 -> 682 | L34: =K34+L33 -> 682 | M34: =L34+M33 -> 682 | N34: =M34+N33 -> 708 | O34: =N34+O33 -> 735 | P34: =O34+P33 -> 735 | ... AK34: =AJ34+AK33 -> 1168 | AL34: *
C35: 2次（合計） | E35: =SUM(H35:AK35) -> 470 | F35: - | G35: 件数 | H35: =SUM(H45:H48) -> 17 | I35: =SUM(I45:I48) -> 0 | J35: =SUM(J45:J48) -> 0 | K35: =SUM(K45:K48) -> 0 | L35: =SUM(L45:L48) -> 0 | M35: =SUM(M45:M48) -> 0 | N35: =SUM(N45:N48) -> 14 | O35: =SUM(O45:O48) -> 31 | ... AK35: =SUM(AK45:AK48) -> 0 | AL35: *
C36: 2次（累計） | E36: =AK36 -> 980 | F36: - | G36: 件数 | H36: ='0401(実績)'!AK33+'0501(実績)'!H35 -> 527 | I36: =H36+I35 -> 527 | J36: =I36+J35 -> 527 | K36: =J36+K35 -> 527 | L36: =K36+L35 -> 527 | M36: =L36+M35 -> 527 | N36: =M36+N35 -> 541 | O36: =N36+O35 -> 572 | P36: =O36+P35 -> 572 | ... AK36: =AJ36+AK35 -> 980 | AL36: *
C37: 1次残件数 | E37: =E32-E33 -> -74 | F37: - | G37: 件数 | H37: ='0401(実績)'!AK34+'0501(実績)'!H32-H33 -> 142 | I37: =H37+I32-I33 -> 142 | J37: =I37+J32-J33 -> 142 | K37: =J37+K32-K33 -> 142 | L37: =K37+L32-L33 -> 142 | M37: =L37+M32-M33 -> 142 | N37: =M37+N32-N33 -> 145 | O37: =N37+O32-O33 -> 151 | P37: =O37+P32-P33 -> 151 | ... AK37: =AJ37+AK32-AK33 -> 81 | AL37: *
C38: 2次残件数 | E38: =E32-E35 -> -24 | F38: - | G38: 件数 | H38: ='0401(実績)'!AK35+'0501(実績)'!H32-'0501(実績)'!H35 -> 297 | I38: =H38+I32-I35 -> 297 | J38: =I38+J32-J35 -> 297 | K38: =J38+K32-K35 -> 297 | L38: =K38+L32-L35 -> 297 | M38: =L38+M32-M35 -> 297 | N38: =M38+N32-N35 -> 312 | O38: =N38+O32-O35 -> 314 | P38: =O38+P32-P35 -> 314 | ... AK38: =AJ38+AK32-AK35 -> 269 | AL38: *
C39: 1次 | D39: 伊藤 | E39: =SUM(H39:AK39)*F39 -> 615 | F39: 15 | G39: 件数 | H39: 6 | O39: 6 | U39: 8 | AB39: 6 | AI39: 7 | AJ39: 8 | AL39: *
D40: 植田 | E40: =SUM(H40:AK40)*F40 -> 1095 | F40: 15 | G40: 件数 | H40: 10 | S40: 4 | T40: 16 | V40: 12 | AA40: 12 | AB40: 8 | AI40: 11 | AL40: *
D41: 兼田 | E41: =SUM(H41:AK41)*F41 -> 540 | F41: 15 | G41: 件数 | N41: 5 | R41: 7 | S41: 2 | U41: 4 | Y41: 7 | Z41: 6 | AG41: 5 | AL41: *
...

Sheet 0501(予実) 
E1: =348-480 -> -132
H2: 1 | N2: 1 | O2: 1 | R2: 1 | S2: 1 | T2: 1 | U2: 1 | V2: 1 | Y2: 1 | Z2: 1 | AA2: 1 | AB2: 1 | AC2: 1 | AF2: 1 | AG2: 1 | AH2: 1 | AI2: 1 | AJ2: 1
E3: 予測件数 | F3: 件数/人 | H3: 46143 | N3: システム停止日 | AL3: *
H4: =H3 -> 46143 | I4: =H4+1 -> 46144 | J4: =I4+1 -> 46145 | K4: =J4+1 -> 46146 | L4: =K4+1 -> 46147 | M4: =L4+1 -> 46148 | N4: =M4+1 -> 46149 | O4: =N4+1 -> 46150 | P4: =O4+1 -> 46151 | ... AK4: =AJ4+1 -> 46172 | AL4: *
H5: =H4 -> 46143 | I5: =I4 -> 46144 | J5: =J4 -> 46145 | K5: =K4 -> 46146 | L5: =L4 -> 46147 | M5: =M4 -> 46148 | N5: =N4 -> 46149 | O5: =O4 -> 46150 | ... AK5: =AK4 -> 46172 | AL5: *
B6: 通勤 | C6: 申請（合計） | E6: ='0501(予定)'!E6 -> 5720 | F6: ='0501(予定)'!F6 -> - | G6: ='0501(予定)'!G6 -> 件数 | H6: ='0501(予定)'!H6 -> 96 | I6: ='0501(予定)'!I6 -> 0 | J6: ='0501(予定)'!J6 -> 0 | K6: ='0501(予定)'!K6 -> 0 | L6: ='0501(予定)'!L6 -> 0 | ... AK6: ='0501(予定)'!AK6 -> 0 | AL6: =SUM(H6:AK6) -> 1195
C7: 申請（合計） | E7: ='0501(実績)'!E6 -> 1441 | F7: ='0501(実績)'!F6 -> - | G7: ='0501(実績)'!G6 -> 件数 | H7: ='0501(実績)'!H6 -> 102 | I7: ='0501(実績)'!I6 -> 0 | J7: ='0501(実績)'!J6 -> 0 | K7: ='0501(実績)'!K6 -> 0 | L7: ='0501(実績)'!L6 -> 0 | ... AK7: ='0501(実績)'!AK6 -> 0 | AL7: =SUM(H7:AK7) -> 1441
C8: 1次（累計） | E8: ='0501(予定)'!E8 -> - | F8: ='0501(予定)'!F8 -> - | G8: ='0501(予定)'!G8 -> 件数 | H8: ='0501(予定)'!H8 -> 1635 | I8: ='0501(予定)'!I8 -> 1635 | J8: ='0501(予定)'!J8 -> 1635 | K8: ='0501(予定)'!K8 -> 1635 | L8: ='0501(予定)'!L8 -> 1635 | ... AK8: ='0501(予定)'!AK8 -> 3305 | AL8: *
C9: １次（累計） | E9: ='0501(実績)'!E8 -> 3637 | F9: ='0501(実績)'!F8 -> - | G9: ='0501(実績)'!G8 -> 件数 | H9: ='0501(実績)'!H8 -> 1959 | I9: ='0501(実績)'!I8 -> 1959 | J9: ='0501(実績)'!J8 -> 1959 | K9: ='0501(実績)'!K8 -> 1959 | L9: ='0501(実績)'!L8 -> 1959 | ... AK9: ='0501(実績)'!AK8 -> 3637 | AL9: *
C10: 2次（累計） | E10: ='0501(予定)'!E10 -> - | F10: ='0501(予定)'!F10 -> - | G10: ='0501(予定)'!G10 -> 件数 | H10: ='0501(予定)'!H10 -> 1081 | I10: ='0501(予定)'!I10 -> 1081 | J10: ='0501(予定)'!J10 -> 1081 | K10: ='0501(予定)'!K10 -> 1081 | L10: ='0501(予定)'!L10 -> 1081 | ... AK10: ='0501(予定)'!AK10 -> 2277 | AL10: *
C11: 2次（累計） | E11: ='0501(実績)'!E10 -> 2461 | F11: ='0501(実績)'!F10 -> - | G11: ='0501(実績)'!G10 -> 件数 | H11: ='0501(実績)'!H10 -> 1161 | I11: ='0501(実績)'!I10 -> 1161 | J11: ='0501(実績)'!J10 -> 1161 | K11: ='0501(実績)'!K10 -> 1161 | L11: ='0501(実績)'!L10 -> 1161 | ... AK11: ='0501(実績)'!AK10 -> 2461 | AL11: *
B12: 扶養 児童 | C12: 申請（合計） | E12: ='0501(予定)'!E24 -> 1362 | F12: ='0501(予定)'!F24 -> - | G12: ='0501(予定)'!G24 -> 件数 | H12: ='0501(予定)'!H24 -> 29 | I12: ='0501(予定)'!I24 -> 0 | J12: ='0501(予定)'!J24 -> 0 | K12: ='0501(予定)'!K24 -> 0 | L12: ='0501(予定)'!L24 -> 0 | ... AK12: ='0501(予定)'!AK24 -> 0 | AL12: *
C13: 申請（合計） | E13: ='0501(実績)'!E29 -> 92 | F13: ='0501(実績)'!F29 -> 20 | G13: ='0501(実績)'!G29 -> 件数 | H13: ='0501(実績)'!H29 -> 0 | I13: ='0501(実績)'!I29 -> 0 | J13: ='0501(実績)'!J29 -> 0 | K13: ='0501(実績)'!K29 -> 0 | L13: ='0501(実績)'!L29 -> 0 | ... AK13: ='0501(実績)'!AK29 -> 0 | AL13: *
C14: 1次（累計） | E14: ='0501(予定)'!E14 -> 130 | F14: ='0501(予定)'!F14 -> 20 | G14: ='0501(予定)'!G14 -> 人数 | H14: ='0501(予定)'!H14 -> 0.5 | I14: ='0501(予定)'!I14 -> 0 | J14: ='0501(予定)'!J14 -> 0 | K14: ='0501(予定)'!K14 -> 0 | L14: ='0501(予定)'!L14 -> 0 | ... AK14: ='0501(予定)'!AK14 -> 0 | AL14: *
C15: １次（累計） | E15: ='0501(実績)'!E14 -> 9 | F15: ='0501(実績)'!F14 -> 20 | G15: ='0501(実績)'!G14 -> 件数 | H15: ='0501(実績)'!H14 -> 0 | I15: ='0501(実績)'!I14 -> 0 | J15: ='0501(実績)'!J14 -> 0 | K15: ='0501(実績)'!K14 -> 0 | L15: ='0501(実績)'!L14 -> 0 | ... AK15: ='0501(実績)'!AK14 -> 0 | AL15: *
C16: 2次（累計） | E16: ='0501(予定)'!E16 -> 170 | F16: ='0501(予定)'!F16 -> 20 | G16: ='0501(予定)'!G16 -> 人数 | H16: ='0501(予定)'!H16 -> 0.5 | I16: ='0501(予定)'!I16 -> 0 | J16: ='0501(予定)'!J16 -> 0 | K16: ='0501(予定)'!K16 -> 0 | L16: ='0501(予定)'!L16 -> 0 | ... AK16: ='0501(予定)'!AK16 -> 0 | AL16: *
C17: 2次（累計） | E17: ='0501(実績)'!E16 -> 35 | F17: ='0501(実績)'!F16 -> 20 | G17: ='0501(実績)'!G16 -> 件数 | H17: ='0501(実績)'!H16 -> 11 | I17: ='0501(実績)'!I16 -> 0 | J17: ='0501(実績)'!J16 -> 0 | K17: ='0501(実績)'!K16 -> 0 | L17: ='0501(実績)'!L16 -> 0 | ... AK17: ='0501(実績)'!AK16 -> 0 | AL17: *
B18: 給与 | C18: 申請（合計） | E18: ='0501(予定)'!E38 -> 399 | F18: ='0501(予定)'!F38 -> - | G18: ='0501(予定)'!G38 -> 件数 | H18: ='0501(予定)'!H38 -> 17 | I18: ='0501(予定)'!I38 -> 0 | J18: ='0501(予定)'!J38 -> 0 | K18: ='0501(予定)'!K38 -> 0 | L18: ='0501(予定)'!L38 -> 0 | ... AK18: ='0501(予定)'!AK38 -> 0 | AL18: *
C19: 申請（合計） | E19: ='0501(実績)'!E46 -> 1370 | F19: ='0501(実績)'!F46 -> 10 | G19: ='0501(実績)'!G46 -> 件数 | H19: ='0501(実績)'!H46 -> 0 | I19: ='0501(実績)'!I46 -> 0 | J19: ='0501(実績)'!J46 -> 0 | K19: ='0501(実績)'!K46 -> 0 | L19: ='0501(実績)'!L46 -> 0 | ... AK19: ='0501(実績)'!AK46 -> 0 | AL19: *
C20: 1次（累計） | E20: ='0501(予定)'!E40 -> 96 | F20: ='0501(予定)'!F40 -> - | G20: ='0501(予定)'!G40 -> 件数 | H20: ='0501(予定)'!H40 -> 720 | I20: ='0501(予定)'!I40 -> 720 | J20: ='0501(予定)'!J40 -> 720 | K20: ='0501(予定)'!K40 -> 720 | L20: ='0501(予定)'!L40 -> 720 | ... AK20: ='0501(予定)'!AK40 -> 10 | AL20: *
C21: １次（累計） | E21: ='0501(実績)'!E48 -> 0 | F21: ='0501(実績)'!F48 -> 0 | G21: ='0501(実績)'!G48 -> 件数 | H21: ='0501(実績)'!H48 -> 0 | I21: ='0501(実績)'!I48 -> 0 | J21: ='0501(実績)'!J48 -> 0 | K21: ='0501(実績)'!K48 -> 0 | L21: ='0501(実績)'!L48 -> 0 | ... AK21: ='0501(実績)'!AK48 -> 0 | AL21: *
C22: 2次（累計） | E22: ='0501(予定)'!E42 -> 119 | F22: ='0501(予定)'!F42 -> 35 | G22: ='0501(予定)'!G42 -> 人数 | H22: ='0501(予定)'!H42 -> 0.2 | I22: ='0501(予定)'!I42 -> 0 | J22: ='0501(予定)'!J42 -> 0 | K22: ='0501(予定)'!K42 -> 0 | L22: ='0501(予定)'!L42 -> 0 | ... AK22: ='0501(予定)'!AK42 -> 0 | AL22: *
C23: 2次（累計） | E23: ='0501(実績)'!E50 -> 216 | F23: ='0501(実績)'!F50 -> - | G23: ='0501(実績)'!G50 -> 件数 | H23: ='0501(実績)'!H50 -> 14 | I23: ='0501(実績)'!I50 -> 0 | J23: ='0501(実績)'!J50 -> 0 | K23: ='0501(実績)'!K50 -> 0 | L23: ='0501(実績)'!L50 -> 0 | ... AK23: ='0501(実績)'!AK50 -> 0 | AL23: *
B24: 住居 | C24: 申請（合計） | E24: ='0501(予定)'!E52 -> 176.2 | F24: ='0501(予定)'!F52 -> - | G24: ='0501(予定)'!G52 -> 件数 | H24: ='0501(予定)'!H52 -> 77.6 | I24: ='0501(予定)'!I52 -> 77.6 | J24: ='0501(予定)'!J52 -> 77.6 | K24: ='0501(予定)'!K52 -> 77.6 | L24: ='0501(予定)'!L52 -> 77.6 | ... AK24: ='0501(予定)'!AK52 -> 113.8 | AL24: *
C25: 申請（合計） | E25: ='0501(実績)'!E63 -> 4200 | F25: ='0501(実績)'!F63 -> 35 | G25: ='0501(実績)'!G63 -> 件数 | H25: ='0501(実績)'!H63 -> 7 | I25: ='0501(実績)'!I63 -> 0 | J25: ='0501(実績)'!J63 -> 0 | K25: ='0501(実績)'!K63 -> 0 | L25: ='0501(実績)'!L63 -> 0 | ... AK25: ='0501(実績)'!AK63 -> 0 | AL25: *
C26: 1次（累計） | E26: ='0501(予定)'!E54 -> 138 | F26: ='0501(予定)'!F54 -> 10 | G26: ='0501(予定)'!G54 -> 人数 | H26: ='0501(予定)'!H54 -> 0.8 | I26: ='0501(予定)'!I54 -> 0 | J26: ='0501(予定)'!J54 -> 0 | K26: ='0501(予定)'!K54 -> 0 | L26: ='0501(予定)'!L54 -> 0 | ... AK26: ='0501(予定)'!AK54 -> 0
C27: １次（累計） | E27: ='0501(実績)'!E65 -> 0 | F27: ='0501(実績)'!F65 -> 0 | G27: ='0501(実績)'!G65 -> 件数 | H27: ='0501(実績)'!H65 -> 0 | I27: ='0501(実績)'!I65 -> 0 | J27: ='0501(実績)'!J65 -> 0 | K27: ='0501(実績)'!K65 -> 0 | L27: ='0501(実績)'!L65 -> 0 | ... AK27: ='0501(実績)'!AK65 -> 0 | AL27: *
C28: 2次（累計） | E28: ='0501(予定)'!E56 -> 0 | F28: ='0501(予定)'!F56 -> 16 | G28: ='0501(予定)'!G56 -> 人数 | H28: ='0501(予定)'!H56 -> 0 | I28: ='0501(予定)'!I56 -> 0 | J28: ='0501(予定)'!J56 -> 0 | K28: ='0501(予定)'!K56 -> 0 | L28: ='0501(予定)'!L56 -> 0 | ... AK28: ='0501(予定)'!AK56 -> 0
C29: 2次（累計） | E29: ='0501(実績)'!E67 -> 202 | F29: ='0501(実績)'!F67 -> - | G29: ='0501(実績)'!G67 -> 件数 | H29: ='0501(実績)'!H67 -> 11 | I29: ='0501(実績)'!I67 -> 0 | J29: ='0501(実績)'!J67 -> 0 | K29: ='0501(実績)'!K67 -> 0 | L29: ='0501(実績)'!L67 -> 0 | ... AK29: ='0501(実績)'!AK67 -> 0 | AL29: *

Sheet 0601(予定)
H2: 1 | I2: 1 | J2: 1 | K2: 1 | L2: 1 | O2: 1 | P2: 1 | Q2: 1 | R2: 1 | S2: 1 | V2: 1 | W2: 1 | X2: 1 | Y2: 1 | Z2: 1 | AC2: 1 | AD2: 1 | AE2: 1 | AF2: 1 | AG2: 1 | AJ2: 1 | AK2: 1 | AL2: =SUM(H2:AK2) -> 22
E3: 予測件数 | F3: 件数/人 | H3: 46174 | L3: システム停止日 | AE3: 全体集会 | AL3: *
H4: =H3 -> 46174 | I4: =H4+1 -> 46175 | J4: =I4+1 -> 46176 | K4: =J4+1 -> 46177 | L4: =K4+1 -> 46178 | M4: =L4+1 -> 46179 | N4: =M4+1 -> 46180 | O4: =N4+1 -> 46181 | P4: =O4+1 -> 46182 | ... AK4: =AJ4+1 -> 46203 | AL4: *
H5: =H4 -> 46174 | I5: =I4 -> 46175 | J5: =J4 -> 46176 | K5: =K4 -> 46177 | L5: =L4 -> 46178 | M5: =M4 -> 46179 | N5: =N4 -> 46180 | O5: =O4 -> 46181 | ... AK5: =AK4 -> 46203 | AL5: *
B6: 通勤 | C6: 申請（合計） | E6: =SUM(H6:AK6)+'0501(予定)'!E6 -> 5720 | F6: - | G6: 件数 | AL6: =SUM(H6:AK6) -> 0
C7: 1次（合計） | E7: =SUM(H7:AK7)+'0501(予定)'!E7 -> 4515 | F7: - | G7: 件数 | H7: =SUM(H13*$F$13,H14*$F$14,H15*$F$15) -> 60 | I7: =SUM(I13*$F$13,I14*$F$14,I15*$F$15) -> 60 | J7: =SUM(J13*$F$13,J14*$F$14,J15*$F$15) -> 60 | K7: =SUM(K13*$F$13,K14*$F$14,K15*$F$15) -> 60 | L7: =SUM(L13*$F$13,L14*$F$14,L15*$F$15) -> 70 | M7: =SUM(M13*$F$13,M14*$F$14,M15*$F$15) -> 0 | N7: =SUM(N13*$F$13,N14*$F$14,N15*$F$15) -> 0 | O7: =SUM(O13*$F$13,O14*$F$14,O15*$F$15) -> 60 | ... AK7: =SUM(AK13*$F$13,AK14*$F$14,AK15*$F$15) -> 0 | AL7: *
C8: 1次（累計） | E8: - | F8: - | G8: 件数 | H8: ='0501(予定)'!AK8+H7 -> 3365 | I8: =H8+I7 -> 3425 | J8: =I8+J7 -> 3485 | K8: =J8+K7 -> 3545 | L8: =K8+L7 -> 3615 | M8: =L8+M7 -> 3615 | N8: =M8+N7 -> 3615 | O8: =N8+O7 -> 3675 | P8: =O8+P7 -> 3735 | ... AK8: =AJ8+AK7 -> 4515
C9: 2次（合計） | E9: =SUM(H9:AK9)+'0501(予定)'!E9 -> 3857 | F9: - | G9: 件数 | H9: =SUM(H16*$F$16,H17*$F$17,H18*$F$18,H19*$F$19) -> 70 | I9: =SUM(I16*$F$16,I17*$F$17,I18*$F$18,I19*$F$19) -> 72 | J9: =SUM(J16*$F$16,J17*$F$17,J18*$F$18,J19*$F$19) -> 70 | K9: =SUM(K16*$F$16,K17*$F$17,K18*$F$18,K19*$F$19) -> 70 | L9: =SUM(L16*$F$16,L17*$F$17,L18*$F$18,L19*$F$19) -> 80 | M9: =SUM(M16*$F$16,M17*$F$17,M18*$F$18,M19*$F$19) -> 0 | N9: =SUM(N16*$F$16,N17*$F$17,N18*$F$18,N19*$F$19) -> 0 | O9: =SUM(O16*$F$16,O17*$F$17,O18*$F$18,O19*$F$19) -> 70 | ... AK9: =SUM(AK16*$F$16,AK17*$F$17,AK18*$F$18,AK19*$F$19) -> 0 | AL9: *
C10: 2次（累計） | E10: - | F10: - | G10: 件数 | H10: ='0501(予定)'!AK10+H9 -> 2347 | I10: =H10+I9 -> 2419 | J10: =I10+J9 -> 2489 | K10: =J10+K9 -> 2559 | L10: =K10+L9 -> 2639 | M10: =L10+M9 -> 2639 | N10: =M10+N9 -> 2639 | O10: =N10+O9 -> 2709 | P10: =O10+P9 -> 2781 | ... AK10: =AJ10+AK9 -> 3857
C11: 1次残件数 | E11: =E6-E7 -> 1205 | F11: - | G11: 件数 | H11: ='0501(予定)'!AK11+H6-H7 -> 2355 | I11: =H11+I6-I7 -> 2295 | J11: =I11+J6-J7 -> 2235 | K11: =J11+K6-K7 -> 2175 | L11: =K11+L6-L7 -> 2105 | M11: =L11+M6-M7 -> 2105 | N11: =M11+N6-N7 -> 2105 | O11: =N11+O6-O7 -> 2045 | P11: =O11+P6-P7 -> 1985 | ... AK11: =AJ11+AK6-AK7 -> 1205 | AL11: *
C12: 2次残件数 | E12: =E6-E9 -> 1863 | F12: - | G12: 件数 | H12: ='0501(予定)'!AK12+H6-H9 -> 3373 | I12: =H12+I6-I9 -> 3301 | J12: =I12+J6-J9 -> 3231 | K12: =J12+K6-K9 -> 3161 | L12: =K12+L6-L9 -> 3081 | M12: =L12+M6-M9 -> 3081 | N12: =M12+N6-N9 -> 3081 | O12: =N12+O6-O9 -> 3011 | P12: =O12+P6-P9 -> 2939 | ... AK12: =AJ12+AK6-AK9 -> 1863 | AL12: *
C13: 1次 | D13: OP | E13: =SUM(H13:AK13)*F13 -> 246 | F13: 20 | G13: 人数 | H13: 0.5 | I13: 0.5 | J13: 0.5 | K13: 0.5 | L13: 1 | O13: 0.5 | P13: 0.5 | Q13: 0.5 | R13: 0.5 | S13: 1 | V13: 0.5 | W13: 0.5 | X13: 0.5 | Y13: 0.5 | Z13: 1 | AC13: 0.5 | AD13: 0.5 | AE13: 0.3 | AF13: 0.5 | AG13: 1 | AJ13: 0.5 | AL13: *
D14: 大場 | E14: =SUM(H14:AK14)*F14 -> 340 | F14: 20 | G14: 人数 | H14: 1 | I14: 1 | J14: 1 | K14: 1 | L14: 1 | O14: 1 | P14: 1 | Q14: 1 | R14: 1 | S14: 1 | V14: 1 | W14: 1 | X14: 1 | Y14: 1 | Z14: 1 | AC14: 1 | AJ14: 1 | AL14: *
D15: 三浦 | E15: =SUM(H15:AK15)*F15 -> 624 | F15: 30 | G15: 人数 | H15: 1 | I15: 1 | J15: 1 | K15: 1 | L15: 1 | O15: 1 | P15: 1 | Q15: 1 | R15: 1 | S15: 1 | V15: 1 | W15: 1 | X15: 1 | Y15: 1 | Z15: 1 | AC15: 1 | AD15: 1 | AE15: 0.8 | AF15: 1 | AG15: 1 | AJ15: 1 | AL15: *
C16: 2次 | D16: 田中 | E16: =SUM(H16:AK16)*F16 -> 624 | F16: 30 | G16: 人数 | H16: 1 | I16: 1 | J16: 1 | K16: 1 | L16: 1 | O16: 1 | P16: 1 | Q16: 1 | R16: 1 | S16: 1 | V16: 1 | W16: 1 | X16: 1 | Y16: 1 | Z16: 1 | AC16: 1 | AD16: 1 | AE16: 0.8 | AF16: 1 | AG16: 1 | AJ16: 1 | AL16: *
D17: 小野 | E17: =SUM(H17:AK17)*F17 -> 800 | F17: 40 | G17: 人数 | H17: 1 | I17: 0.8 | J17: 1 | K17: 1 | L17: 1 | O17: 1 | P17: 0.8 | Q17: 1 | R17: 1 | S17: 1 | V17: 1 | W17: 0.8 | X17: 1 | Y17: 1 | Z17: 1 | AC17: 1 | AD17: 0.8 | AE17: 0.8 | AF17: 1 | AG17: 1 | AJ17: 1 | AL17: *
D18: 大場 | E18: =SUM(H18:AK18)*F18 -> 76 | F18: 20 | G18: 人数 | AD18: 1 | AE18: 0.8 | AF18: 1 | AG18: 1 | AL18: *
